Workbook

Sheet Matriz de Avaliação
E1: FORMULÁRIO - FO | J1: Código | K1: FO.SUP.014 - 1.0
J2: Data | K2: 45757
E3: Título: | J3: Área | K3: SUP
E4: Matriz de Avaliação Técnica e Qualidade | J4: Páginas | K4: 44593
B5: Matriz de Avaliação Técnica e Qualidade
B6: ESCOPO DA CONTRATAÇÃO: | F6: Prestaçao de Serviços Solução Nginx Plus no Aeroporto de Guarulhos.
F8: NTT DATA | G8: Agility | H8: Fornecedor03 | I8: Fornecedor04 | J8: Fornecedor05 | K8: Fornecedor06 | L8: Nome Fornecedor 7 | M8: Nome Fornecedor 8 | N8: Nome Fornecedor 9 | O8: Nome Fornecedor 10 | P8: Fornecedor07 | R8: Peso Total
B9: Item | C9: Requisito Avaliado | D9: Área Avaliadora | E9: Peso | R9: =SUM(E10:E27) -> 47 | S9: 1 | T9: 2 | U9: 3 | V9: 4 | W9: 5 | X9: 6 | Y9: 7 | Z9: 8 | AA9: 9 | AB9: 10
B10: 1 | C10: A proposta contempla licenciamento do NGINX Plus em cluster com validade de 60 meses? | D10: Área tecnica | E10: 2 | F10: Atende | G10: Atende | R10: =E10/$R$9 -> 0.042553191 | S10: =IF(F10="Atende",5,IF(F10="Atende Parcialmente",3,0)) -> 5 | T10: =IF(G10="Atende",5,IF(G10="Atende Parcialmente",3,0)) -> 5 | U10: =IF(H10="Atende",5,IF(H10="Atende Parcialmente",3,0)) -> 0 | V10: =IF(I10="Atende",5,IF(I10="Atende Parcialmente",3,0)) -> 0 | W10: =IF(J10="Atende",5,IF(J10="Atende Parcialmente",3,0)) -> 0 | X10: =IF(K10="Atende",5,IF(K10="Atende Parcialmente",3,0)) -> 0 | Y10: =IF(P10="Atende",5,IF(P10="Atende Parcialmente",3,0)) -> 0 | Z10: =IF(M10="Atende",5,IF(M10="Atende Parcialmente",3,0)) -> 0 | AA10: =IF(N10="Atende",5,IF(N10="Atende Parcialmente",3,0)) -> 0 | AB10: =IF(O10="Atende",5,IF(O10="Atende Parcialmente",3,0)) -> 0
B11: 2 | C11: O fornecedor possui parceria oficial com a F5 e experiência comprovada na oferta de suporte técnico para o NGINX Plus? | D11: Área tecnica | E11: 3 | F11: Não atende | G11: Atende parcialmente | R11: =E11/$R$9 -> 0.063829787 | S11: =IF(F11="Atende",5,IF(F11="Atende Parcialmente",3,0)) -> 0 | T11: =IF(G11="Atende",5,IF(G11="Atende Parcialmente",3,0)) -> 3 | U11: =IF(H11="Atende",5,IF(H11="Atende Parcialmente",3,0)) -> 0 | V11: =IF(I11="Atende",5,IF(I11="Atende Parcialmente",3,0)) -> 0 | W11: =IF(J11="Atende",5,IF(J11="Atende Parcialmente",3,0)) -> 0 | X11: =IF(K11="Atende",5,IF(K11="Atende Parcialmente",3,0)) -> 0 | Y11: =IF(P11="Atende",5,IF(P11="Atende Parcialmente",3,0)) -> 0 | Z11: =IF(M11="Atende",5,IF(M11="Atende Parcialmente",3,0)) -> 0 | AA11: =IF(N11="Atende",5,IF(N11="Atende Parcialmente",3,0)) -> 0 | AB11: =IF(O11="Atende",5,IF(O11="Atende Parcialmente",3,0)) -> 0
B12: 3 | C12: O suporte técnico oferecido é 24x7, com acesso direto ao fabricante e com garantia de atualizações e correções de segurança? | D12: Área tecnica | E12: 3 | F12: Atende parcialmente | G12: Atende | R12: =E12/$R$9 -> 0.063829787 | S12: =IF(F12="Atende",5,IF(F12="Atende Parcialmente",3,0)) -> 3 | T12: =IF(G12="Atende",5,IF(G12="Atende Parcialmente",3,0)) -> 5 | U12: =IF(H12="Atende",5,IF(H12="Atende Parcialmente",3,0)) -> 0 | V12: =IF(I12="Atende",5,IF(I12="Atende Parcialmente",3,0)) -> 0 | W12: =IF(J12="Atende",5,IF(J12="Atende Parcialmente",3,0)) -> 0 | X12: =IF(K12="Atende",5,IF(K12="Atende Parcialmente",3,0)) -> 0 | Y12: =IF(P12="Atende",5,IF(P12="Atende Parcialmente",3,0)) -> 0 | Z12: =IF(M12="Atende",5,IF(M12="Atende Parcialmente",3,0)) -> 0 | AA12: =IF(N12="Atende",5,IF(N12="Atende Parcialmente",3,0)) -> 0 | AB12: =IF(O12="Atende",5,IF(O12="Atende Parcialmente",3,0)) -> 0
B13: 4 | C13: O suporte técnico será prestado em quais idiomas? Existe opção de atendimento em português? | D13: Área tecnica | E13: 3 | F13: Não atende | G13: Atende parcialmente | R13: =E13/$R$9 -> 0.063829787 | S13: =IF(F13="Atende",5,IF(F13="Atende Parcialmente",3,0)) -> 0 | T13: =IF(G13="Atende",5,IF(G13="Atende Parcialmente",3,0)) -> 3 | U13: =IF(H13="Atende",5,IF(H13="Atende Parcialmente",3,0)) -> 0 | V13: =IF(I13="Atende",5,IF(I13="Atende Parcialmente",3,0)) -> 0 | W13: =IF(J13="Atende",5,IF(J13="Atende Parcialmente",3,0)) -> 0 | X13: =IF(K13="Atende",5,IF(K13="Atende Parcialmente",3,0)) -> 0 | Y13: =IF(P13="Atende",5,IF(P13="Atende Parcialmente",3,0)) -> 0 | Z13: =IF(M13="Atende",5,IF(M13="Atende Parcialmente",3,0)) -> 0 | AA13: =IF(N13="Atende",5,IF(N13="Atende Parcialmente",3,0)) -> 0 | AB13: =IF(O13="Atende",5,IF(O13="Atende Parcialmente",3,0)) -> 0
B14: 5 | C14: O licenciamento contempla a entrega de duas ou mais instâncias em alta disponibilidade (HA)? | D14: Área tecnica | E14: 3 | F14: Atende | G14: Atende | R14: =E14/$R$9 -> 0.063829787 | S14: =IF(F14="Atende",5,IF(F14="Atende Parcialmente",3,0)) -> 5 | T14: =IF(G14="Atende",5,IF(G14="Atende Parcialmente",3,0)) -> 5 | U14: =IF(H14="Atende",5,IF(H14="Atende Parcialmente",3,0)) -> 0 | V14: =IF(I14="Atende",5,IF(I14="Atende Parcialmente",3,0)) -> 0 | W14: =IF(J14="Atende",5,IF(J14="Atende Parcialmente",3,0)) -> 0 | X14: =IF(K14="Atende",5,IF(K14="Atende Parcialmente",3,0)) -> 0 | Y14: =IF(P14="Atende",5,IF(P14="Atende Parcialmente",3,0)) -> 0 | Z14: =IF(M14="Atende",5,IF(M14="Atende Parcialmente",3,0)) -> 0 | AA14: =IF(N14="Atende",5,IF(N14="Atende Parcialmente",3,0)) -> 0 | AB14: =IF(O14="Atende",5,IF(O14="Atende Parcialmente",3,0)) -> 0
B15: 6 | C15: Quais documentos técnicos comprovam a aptidão técnica para prestação dos serviços descritos neste TR? | D15: Área tecnica | E15: 3 | F15: Não atende | G15: Atende parcialmente | R15: =E15/$R$9 -> 0.063829787 | S15: =IF(F15="Atende",5,IF(F15="Atende Parcialmente",3,0)) -> 0 | T15: =IF(G15="Atende",5,IF(G15="Atende Parcialmente",3,0)) -> 3 | U15: =IF(H15="Atende",5,IF(H15="Atende Parcialmente",3,0)) -> 0 | V15: =IF(I15="Atende",5,IF(I15="Atende Parcialmente",3,0)) -> 0 | W15: =IF(J15="Atende",5,IF(J15="Atende Parcialmente",3,0)) -> 0 | X15: =IF(K15="Atende",5,IF(K15="Atende Parcialmente",3,0)) -> 0 | Y15: =IF(P15="Atende",5,IF(P15="Atende Parcialmente",3,0)) -> 0 | Z15: =IF(M15="Atende",5,IF(M15="Atende Parcialmente",3,0)) -> 0 | AA15: =IF(N15="Atende",5,IF(N15="Atende Parcialmente",3,0)) -> 0 | AB15: =IF(O15="Atende",5,IF(O15="Atende Parcialmente",3,0)) -> 0
B16: 7 | C16: A proposta apresenta referências de clientes anteriores com casos semelhantes? | D16: Área tecnica | E16: 3 | F16: Não atende | G16: Não atende | R16: =E16/$R$9 -> 0.063829787 | S16: =IF(F16="Atende",5,IF(F16="Atende Parcialmente",3,0)) -> 0 | T16: =IF(G16="Atende",5,IF(G16="Atende Parcialmente",3,0)) -> 0 | U16: =IF(H16="Atende",5,IF(H16="Atende Parcialmente",3,0)) -> 0 | V16: =IF(I16="Atende",5,IF(I16="Atende Parcialmente",3,0)) -> 0 | W16: =IF(J16="Atende",5,IF(J16="Atende Parcialmente",3,0)) -> 0 | X16: =IF(K16="Atende",5,IF(K16="Atende Parcialmente",3,0)) -> 0 | Y16: =IF(P16="Atende",5,IF(P16="Atende Parcialmente",3,0)) -> 0 | Z16: =IF(M16="Atende",5,IF(M16="Atende Parcialmente",3,0)) -> 0 | AA16: =IF(N16="Atende",5,IF(N16="Atende Parcialmente",3,0)) -> 0 | AB16: =IF(O16="Atende",5,IF(O16="Atende Parcialmente",3,0)) -> 0
B17: 8 | C17: Haverá alguma limitação quanto ao canal de atendimento com o fabricante (F5)? | D17: Área tecnica | E17: 2 | F17: Atende parcialmente | G17: Atende parcialmente | R17: =E17/$R$9 -> 0.042553191 | S17: =IF(F17="Atende",5,IF(F17="Atende Parcialmente",3,0)) -> 3 | T17: =IF(G17="Atende",5,IF(G17="Atende Parcialmente",3,0)) -> 3 | U17: =IF(H17="Atende",5,IF(H17="Atende Parcialmente",3,0)) -> 0 | V17: =IF(I17="Atende",5,IF(I17="Atende Parcialmente",3,0)) -> 0 | W17: =IF(J17="Atende",5,IF(J17="Atende Parcialmente",3,0)) -> 0 | X17: =IF(K17="Atende",5,IF(K17="Atende Parcialmente",3,0)) -> 0 | Y17: =IF(P17="Atende",5,IF(P17="Atende Parcialmente",3,0)) -> 0 | Z17: =IF(M17="Atende",5,IF(M17="Atende Parcialmente",3,0)) -> 0 | AA17: =IF(N17="Atende",5,IF(N17="Atende Parcialmente",3,0)) -> 0 | AB17: =IF(O17="Atende",5,IF(O17="Atende Parcialmente",3,0)) -> 0
B18: 9 | C18: A empresa consegue atender 100% do escopo com equipe própria, ou haverá subcontratação? | D18: Área tecnica | E18: 2 | F18: Não atende | G18: Atende | R18: =E18/$R$9 -> 0.042553191 | S18: =IF(F18="Atende",5,IF(F18="Atende Parcialmente",3,0)) -> 0 | T18: =IF(G18="Atende",5,IF(G18="Atende Parcialmente",3,0)) -> 5 | U18: =IF(H18="Atende",5,IF(H18="Atende Parcialmente",3,0)) -> 0 | V18: =IF(I18="Atende",5,IF(I18="Atende Parcialmente",3,0)) -> 0 | W18: =IF(J18="Atende",5,IF(J18="Atende Parcialmente",3,0)) -> 0 | X18: =IF(K18="Atende",5,IF(K18="Atende Parcialmente",3,0)) -> 0 | Y18: =IF(P18="Atende",5,IF(P18="Atende Parcialmente",3,0)) -> 0 | Z18: =IF(M18="Atende",5,IF(M18="Atende Parcialmente",3,0)) -> 0 | AA18: =IF(N18="Atende",5,IF(N18="Atende Parcialmente",3,0)) -> 0 | AB18: =IF(O18="Atende",5,IF(O18="Atende Parcialmente",3,0)) -> 0
B19: 10 | C19: Existe garantia formal de acesso aos patches e atualizações de segurança durante toda a vigência do contrato? | D19: Área tecnica | E19: 3 | F19: Atende | G19: Atende | R19: =E19/$R$9 -> 0.063829787 | S19: =IF(F19="Atende",5,IF(F19="Atende Parcialmente",3,0)) -> 5 | T19: =IF(G19="Atende",5,IF(G19="Atende Parcialmente",3,0)) -> 5 | U19: =IF(H19="Atende",5,IF(H19="Atende Parcialmente",3,0)) -> 0 | V19: =IF(I19="Atende",5,IF(I19="Atende Parcialmente",3,0)) -> 0 | W19: =IF(J19="Atende",5,IF(J19="Atende Parcialmente",3,0)) -> 0 | X19: =IF(K19="Atende",5,IF(K19="Atende Parcialmente",3,0)) -> 0 | Y19: =IF(P19="Atende",5,IF(P19="Atende Parcialmente",3,0)) -> 0 | Z19: =IF(M19="Atende",5,IF(M19="Atende Parcialmente",3,0)) -> 0 | AA19: =IF(N19="Atende",5,IF(N19="Atende Parcialmente",3,0)) -> 0 | AB19: =IF(O19="Atende",5,IF(O19="Atende Parcialmente",3,0)) -> 0
B20: 11 | C20: O contrato proposto está alinhado ao modelo de OPEX com vigência contínua, conforme definido no TR? | D20: Área tecnica | E20: 3 | F20: Atende | G20: Atende | R20: =E20/$R$9 -> 0.063829787 | S20: =IF(F20="Atende",5,IF(F20="Atende Parcialmente",3,0)) -> 5 | T20: =IF(G20="Atende",5,IF(G20="Atende Parcialmente",3,0)) -> 5 | U20: =IF(H20="Atende",5,IF(H20="Atende Parcialmente",3,0)) -> 0 | V20: =IF(I20="Atende",5,IF(I20="Atende Parcialmente",3,0)) -> 0 | W20: =IF(J20="Atende",5,IF(J20="Atende Parcialmente",3,0)) -> 0 | X20: =IF(K20="Atende",5,IF(K20="Atende Parcialmente",3,0)) -> 0 | Y20: =IF(P20="Atende",5,IF(P20="Atende Parcialmente",3,0)) -> 0 | Z20: =IF(M20="Atende",5,IF(M20="Atende Parcialmente",3,0)) -> 0 | AA20: =IF(N20="Atende",5,IF(N20="Atende Parcialmente",3,0)) -> 0 | AB20: =IF(O20="Atende",5,IF(O20="Atende Parcialmente",3,0)) -> 0
B21: 12 | C21: Existe cronograma proposto de ativação e entrega das licenças? | D21: Área tecnica | E21: 2 | F21: Não atende | G21: Atende parcialmente | R21: =E21/$R$9 -> 0.042553191 | S21: =IF(F21="Atende",5,IF(F21="Atende Parcialmente",3,0)) -> 0 | T21: =IF(G21="Atende",5,IF(G21="Atende Parcialmente",3,0)) -> 3 | U21: =IF(H21="Atende",5,IF(H21="Atende Parcialmente",3,0)) -> 0 | V21: =IF(I21="Atende",5,IF(I21="Atende Parcialmente",3,0)) -> 0 | W21: =IF(J21="Atende",5,IF(J21="Atende Parcialmente",3,0)) -> 0 | X21: =IF(K21="Atende",5,IF(K21="Atende Parcialmente",3,0)) -> 0 | Y21: =IF(P21="Atende",5,IF(P21="Atende Parcialmente",3,0)) -> 0 | Z21: =IF(M21="Atende",5,IF(M21="Atende Parcialmente",3,0)) -> 0 | AA21: =IF(N21="Atende",5,IF(N21="Atende Parcialmente",3,0)) -> 0 | AB21: =IF(O21="Atende",5,IF(O21="Atende Parcialmente",3,0)) -> 0
... B27: 18 | C27: O fornecedor possui capacidade de atuação conforme regras de segurança, mesmo sendo serviço remoto? | D27: Área tecnica | E27: 3 | F27: Atende parcialmente | G27: Atende parcialmente | R27: =E27/$R$9 -> 0.063829787 | S27: =IF(F27="Atende",5,IF(F27="Atende Parcialmente",3,0)) -> 3 | T27: =IF(G27="Atende",5,IF(G27="Atende Parcialmente",3,0)) -> 3 | U27: =IF(H27="Atende",5,IF(H27="Atende Parcialmente",3,0)) -> 0 | V27: =IF(I27="Atende",5,IF(I27="Atende Parcialmente",3,0)) -> 0 | W27: =IF(J27="Atende",5,IF(J27="Atende Parcialmente",3,0)) -> 0 | X27: =IF(K27="Atende",5,IF(K27="Atende Parcialmente",3,0)) -> 0 | Y27: =IF(P27="Atende",5,IF(P27="Atende Parcialmente",3,0)) -> 0 | Z27: =IF(M27="Atende",5,IF(M27="Atende Parcialmente",3,0)) -> 0 | AA27: =IF(N27="Atende",5,IF(N27="Atende Parcialmente",3,0)) -> 0 | AB27: =IF(O27="Atende",5,IF(O27="Atende Parcialmente",3,0)) -> 0
B29: NOTA E RESULTADO FINAL | F29: =IF(F8="","",S29) -> 1.8085106 | G29: =IF(G8="","",T29) -> 3.787234 | H29: =IF(H8="","",U29) -> 0 | I29: =IF(I8="","",V29) -> 0 | J29: =IF(J8="","",W29) -> 0 | K29: =IF(K8="","",X29) -> 0 | L29: =IF(L8="","",Y29) -> 0 | M29: =IF(M8="","",Z29) -> 0 | ... O29: =IF(O8="","",AB29) -> 0 | P29: =IF(P8="","",Y29) -> 0 | S29: =IF(S28>0,0,SUMPRODUCT($R$10:$R$27,S10:S27)) -> 1.8085106 | T29: =IF(T28>0,0,SUMPRODUCT($R$10:$R$27,T10:T27)) -> 3.787234 | U29: =IF(U28>0,0,SUMPRODUCT($R$10:$R$27,U10:U27)) -> 0 | V29: =IF(V28>0,0,SUMPRODUCT($R$10:$R$27,V10:V27)) -> 0 | W29: =IF(W28>0,0,SUMPRODUCT($R$10:$R$27,W10:W27)) -> 0 | X29: =IF(X28>0,0,SUMPRODUCT($R$10:$R$27,X10:X27)) -> 0 | Y29: =IF(Y28>0,0,SUMPRODUCT($R$10:$R$27,Y10:Y27)) -> 0 | Z29: =IF(Z28>0,0,SUMPRODUCT($R$10:$R$27,Z10:Z27)) -> 0 | ... AB29: =IF(AB28>0,0,SUMPRODUCT($R$10:$R$27,AB10:AB27)) -> 0
F30: =IF(F8="","",IF(F29>=$F$34,"APROVADO","REPROVADO")) -> REPROVADO | G30: =IF(G8="","",IF(G29>=$F$34,"APROVADO","REPROVADO")) -> APROVADO | H30: =IF(H8="","",IF(H29>=$F$34,"APROVADO","REPROVADO")) -> REPROVADO | I30: =IF(I8="","",IF(I29>=$F$34,"APROVADO","REPROVADO")) -> REPROVADO | J30: =IF(J8="","",IF(J29>=$F$34,"APROVADO","REPROVADO")) -> REPROVADO | K30: =IF(K8="","",IF(K29>=$F$34,"APROVADO","REPROVADO")) -> REPROVADO | L30: =IF(L8="","",IF(L29>=$F$34,"APROVADO","REPROVADO")) -> REPROVADO | M30: =IF(M8="","",IF(M29>=$F$34,"APROVADO","REPROVADO")) -> REPROVADO | ... P30: =IF(P8="","",IF(P29>=$F$34,"APROVADO","REPROVADO")) -> REPROVADO
B31: * Itens avaliados como "Atende Parcialmente" ou "Não Atende" devem ser detalhados na folha justificativas.
B33: Legenda Pesos | F33: Nota de Corte
B34: Peso 1 | C34: Desejável | F34: 3.7
B35: Peso 2 | C35: Relevante
B36: Peso 3 | C36: Mandatório
E38: Responsáveis: | H38: Nome: | J38: Data:
E40: Responsável pela avaliação (Área Técnica): | H40: Evandro Pereira Santiago | J40: 45757
E42: Responsável pela avaliação (Qualidade):
E44: Responsável pela avaliação (Farmacêutico):

Sheet Justificativas
E1: FORMULÁRIO - FO | Q1: Código | R1: FO.SUP.014 - 1.0
Q2: Data | R2: 45757
E3: Título: | Q3: Área | R3: SUP
E4: ='Matriz de Avaliação'!E4 -> Matriz de Avaliação Técnica e Qualidade | Q4: Páginas | R4: 44594
B5: ='Matriz de Avaliação'!B5:J5 -> Matriz de Avaliação Técnica e Qualidade
B6: ESCOPO DA CONTRATAÇÃO: | F6: Prestaçao de Serviços XXXXXXXXXXX no Aeroporto de Guarulhos.
B7: ='Matriz de Avaliação'!F8 -> NTT DATA
B8: Item | C8: Requisito Avaliado | D8: Área Avaliadora | E8: Justificativa:
B9: 1 | C9: ='Matriz de Avaliação'!C10 -> A proposta contempla licenciamento do NGINX Plus em cluster com validade de 60 meses? | D9: ='Matriz de Avaliação'!D10 -> Área tecnica | E9: Licenciamento de cluster está previsto, com foco em subscrição.
B10: 2 | C10: ='Matriz de Avaliação'!C11 -> O fornecedor possui parceria oficial com a F5 e experiência comprovada na oferta de suporte técnico para o NGINX Plus? | D10: ='Matriz de Avaliação'!D11 -> Área tecnica | E10: Proposta não menciona vínculo formal com a F5 nem experiência comprovada.
B11: 3 | C11: ='Matriz de Avaliação'!C12 -> O suporte técnico oferecido é 24x7, com acesso direto ao fabricante e com garantia de atualizações e correções de segurança? | D11: ='Matriz de Avaliação'!D12 -> Área tecnica | E11: Oferece suporte via F5 24x7, mas sem detalhar intermediação ou garantias locais.
B12: 4 | C12: ='Matriz de Avaliação'!C13 -> O suporte técnico será prestado em quais idiomas? Existe opção de atendimento em português? | D12: ='Matriz de Avaliação'!D13 -> Área tecnica | E12: Suporte apenas em inglês, via canal F5.
B13: 5 | C13: ='Matriz de Avaliação'!C14 -> O licenciamento contempla a entrega de duas ou mais instâncias em alta disponibilidade (HA)? | D13: ='Matriz de Avaliação'!D14 -> Área tecnica | E13: Cluster com alta disponibilidade é citado.
B14: 6 | C14: ='Matriz de Avaliação'!C15 -> Quais documentos técnicos comprovam a aptidão técnica para prestação dos serviços descritos neste TR? | D14: ='Matriz de Avaliação'!D15 -> Área tecnica | E14: Não apresenta documentação técnica ou comprovação de aptidão.
B15: 7 | C15: ='Matriz de Avaliação'!C16 -> A proposta apresenta referências de clientes anteriores com casos semelhantes? | D15: ='Matriz de Avaliação'!D16 -> Área tecnica | E15: Não há menção a clientes ou histórico semelhante.
B16: 8 | C16: ='Matriz de Avaliação'!C17 -> Haverá alguma limitação quanto ao canal de atendimento com o fabricante (F5)? | D16: ='Matriz de Avaliação'!D17 -> Área tecnica | E16: F5 é o canal direto, mas parceiro não acompanha ou intermedia.
B17: 9 | C17: ='Matriz de Avaliação'!C18 -> A empresa consegue atender 100% do escopo com equipe própria, ou haverá subcontratação? | D17: ='Matriz de Avaliação'!D18 -> Área tecnica | E17: Não demonstra equipe própria para execução ou suporte técnico.
B18: 10 | C18: ='Matriz de Avaliação'!C19 -> Existe garantia formal de acesso aos patches e atualizações de segurança durante toda a vigência do contrato? | D18: ='Matriz de Avaliação'!D19 -> Área tecnica | E18: Atualizações são cobertas pela subscrição da F5.
B19: 11 | C19: ='Matriz de Avaliação'!C20 -> O contrato proposto está alinhado ao modelo de OPEX com vigência contínua, conforme definido no TR? | D19: ='Matriz de Avaliação'!D20 -> Área tecnica | E19: Contrato segue modelo OPEX com prazo definido de 60 meses.
B20: 12 | C20: ='Matriz de Avaliação'!C21 -> Existe cronograma proposto de ativação e entrega das licenças? | D20: ='Matriz de Avaliação'!D21 -> Área tecnica | E20: Não apresenta cronograma ou datas de entrega técnica.
... B26: 18 | C26: ='Matriz de Avaliação'!C27 -> O fornecedor possui capacidade de atuação conforme regras de segurança, mesmo sendo serviço remoto? | D26: ='Matriz de Avaliação'!D27 -> Área tecnica | E26: Serviço é remoto, mas sem detalhamento de conformidade com normas locais.
B28: ='Matriz de Avaliação'!G8 -> Agility
B29: Item | C29: Requisito Avaliado | D29: Área Avaliadora | E29: Justificativa:
B30: 1 | C30: ='Matriz de Avaliação'!C10 -> A proposta contempla licenciamento do NGINX Plus em cluster com validade de 60 meses? | D30: ='Matriz de Avaliação'!D10 -> Área tecnica | E30: Inclui licenciamento de cluster NGINX Plus com prazo de 60 meses.
B31: 2 | C31: ='Matriz de Avaliação'!C11 -> O fornecedor possui parceria oficial com a F5 e experiência comprovada na oferta de suporte técnico para o NGINX Plus? | D31: ='Matriz de Avaliação'!D11 -> Área tecnica | E31: Se declara parceira e implementadora, mas sem prova de certificação máxima.
B32: 3 | C32: ='Matriz de Avaliação'!C12 -> O suporte técnico oferecido é 24x7, com acesso direto ao fabricante e com garantia de atualizações e correções de segurança? | D32: ='Matriz de Avaliação'!D12 -> Área tecnica | E32: Oferece suporte F5 24x7 (Premium) e equipe própria N1/N2.
B33: 4 | C33: ='Matriz de Avaliação'!C13 -> O suporte técnico será prestado em quais idiomas? Existe opção de atendimento em português? | D33: ='Matriz de Avaliação'!D13 -> Área tecnica | E33: Atendimento da F5 em inglês, com suporte local parcial em português.
B34: 5 | C34: ='Matriz de Avaliação'!C14 -> O licenciamento contempla a entrega de duas ou mais instâncias em alta disponibilidade (HA)? | D34: ='Matriz de Avaliação'!D14 -> Área tecnica | E34: Entrega prevê duas instâncias em HA.
B35: 6 | C35: ='Matriz de Avaliação'!C15 -> Quais documentos técnicos comprovam a aptidão técnica para prestação dos serviços descritos neste TR? | D35: ='Matriz de Avaliação'!D15 -> Área tecnica | E35: Cita escopo técnico e equipe, mas não anexa documentação formal.
B36: 7 | C36: ='Matriz de Avaliação'!C16 -> A proposta apresenta referências de clientes anteriores com casos semelhantes? | D36: ='Matriz de Avaliação'!D16 -> Área tecnica | E36: Proposta não apresenta histórico de clientes.
B37: 8 | C37: ='Matriz de Avaliação'!C17 -> Haverá alguma limitação quanto ao canal de atendimento com o fabricante (F5)? | D37: ='Matriz de Avaliação'!D17 -> Área tecnica | E37: Canal com F5 existe, mas limitações dependem da F5.
B38: 9 | C38: ='Matriz de Avaliação'!C18 -> A empresa consegue atender 100% do escopo com equipe própria, ou haverá subcontratação? | D38: ='Matriz de Avaliação'!D18 -> Área tecnica | E38: Realiza com equipe própria sem terceirização informada.
B39: 10 | C39: ='Matriz de Avaliação'!C19 -> Existe garantia formal de acesso aos patches e atualizações de segurança durante toda a vigência do contrato? | D39: ='Matriz de Avaliação'!D19 -> Área tecnica | E39: Inclui atualizações contínuas conforme política da F5.
B40: 11 | C40: ='Matriz de Avaliação'!C20 -> O contrato proposto está alinhado ao modelo de OPEX com vigência contínua, conforme definido no TR? | D40: ='Matriz de Avaliação'!D20 -> Área tecnica | E40: Modelo OPEX com vigência de 60 meses está atendido.
B41: 12 | C41: ='Matriz de Avaliação'!C21 -> Existe cronograma proposto de ativação e entrega das licenças? | D41: ='Matriz de Avaliação'!D21 -> Área tecnica | E41: Descreve escopo técnico e atividades, mas não detalha prazos fixos.
... B47: 18 | C47: ='Matriz de Avaliação'!C27 -> O fornecedor possui capacidade de atuação conforme regras de segurança, mesmo sendo serviço remoto? | D47: ='Matriz de Avaliação'!D27 -> Área tecnica | E47: Cita conformidade geral, mas não detalha aderência a regras de segurança locais.
B49: ='Matriz de Avaliação'!H8 -> Fornecedor03
B50: Item | C50: Requisito Avaliado | D50: Área Avaliadora | E50: Justificativa:
B51: 1 | C51: ='Matriz de Avaliação'!C10 -> A proposta contempla licenciamento do NGINX Plus em cluster com validade de 60 meses? | D51: ='Matriz de Avaliação'!D10 -> Área tecnica
B52: 2 | C52: ='Matriz de Avaliação'!C11 -> O fornecedor possui parceria oficial com a F5 e experiência comprovada na oferta de suporte técnico para o NGINX Plus? | D52: ='Matriz de Avaliação'!D11 -> Área tecnica
...
