Workbook

Sheet DASHBOARD_01_205
B2: Inventário Servidores Dezembro 2024
B4: Linux Virtual | E4: Linux Fisicos | H4: Windows Virtual | K4: Windows Fisicos
B5: Total Virtuais | C5: =COUNTIFS(INVENTÁRIO_01_2025!C:C,"Linux",INVENTÁRIO_01_2025!E:E,"Virtual") -> 100 | E5: Total Fisicos | F5: =COUNTIFS(INVENTÁRIO_01_2025!C:C,"Linux",INVENTÁRIO_01_2025!E:E,"Fisico") -> 49 | H5: Total Virtuais | I5: =COUNTIFS(INVENTÁRIO_01_2025!C:C,"Windows",INVENTÁRIO_01_2025!E:E,"Virtual") -> 272 | K5: Total Fisicos | L5: =COUNTIFS(INVENTÁRIO_01_2025!C:C,"Windows",INVENTÁRIO_01_2025!E:E,"Fisico") -> 29
B6: Desligadas | C6: =COUNTIFS(INVENTÁRIO_01_2025!B:B,"poweredOff",INVENTÁRIO_01_2025!C:C,"Linux",INVENTÁRIO_01_2025!E:E,"Virtual") -> 10 | E6: Desligadas | F6: =COUNTIFS(INVENTÁRIO_01_2025!B:B,"poweredOff",INVENTÁRIO_01_2025!C:C,"Linux",INVENTÁRIO_01_2025!E:E,"Fisico") -> 4 | H6: Desligadas | I6: =COUNTIFS(INVENTÁRIO_01_2025!B:B,"poweredOff",INVENTÁRIO_01_2025!C:C,"Windows",INVENTÁRIO_01_2025!E:E,"Virtual") -> 19 | K6: Desligadas | L6: =COUNTIFS(INVENTÁRIO_01_2025!B:B,"poweredOff",INVENTÁRIO_01_2025!C:C,"Windows",INVENTÁRIO_01_2025!E:E,"Fisico") -> 7
B7: Ligadas | C7: =COUNTIFS(INVENTÁRIO_01_2025!B:B,"poweredOn",INVENTÁRIO_01_2025!C:C,"Linux",INVENTÁRIO_01_2025!E:E,"Virtual") -> 90 | E7: Ligadas | F7: =COUNTIFS(INVENTÁRIO_01_2025!B:B,"poweredOn",INVENTÁRIO_01_2025!C:C,"Linux",INVENTÁRIO_01_2025!E:E,"Fisico") -> 45 | H7: Ligadas | I7: =COUNTIFS(INVENTÁRIO_01_2025!B:B,"poweredOn",INVENTÁRIO_01_2025!C:C,"Windows",INVENTÁRIO_01_2025!E:E,"Virtual") -> 253 | K7: Ligadas | L7: =COUNTIFS(INVENTÁRIO_01_2025!B:B,"poweredOn",INVENTÁRIO_01_2025!C:C,"Windows",INVENTÁRIO_01_2025!E:E,"Fisico") -> 22
B9: Total RedHat 9 | C9: =COUNTIFS(INVENTÁRIO_01_2025!C:C,"Linux",INVENTÁRIO_01_2025!D:D,"*RedHat 9*",INVENTÁRIO_01_2025!E:E,"Virtual") -> 5 | E9: Total RedHat 9 | F9: =COUNTIFS(INVENTÁRIO_01_2025!C:C,"Linux",INVENTÁRIO_01_2025!D:D,"*RedHat 9*",INVENTÁRIO_01_2025!E:E,"Fisico") -> 0 | H9: Windows 2022 | I9: =COUNTIFS(INVENTÁRIO_01_2025!C:C,"Windows",INVENTÁRIO_01_2025!D:D,"*2022*",INVENTÁRIO_01_2025!E:E,"Virtual") -> 7 | K9: Windows 2022 | L9: =COUNTIFS(INVENTÁRIO_01_2025!C:C,"Windows",INVENTÁRIO_01_2025!D:D,"*2022*",INVENTÁRIO_01_2025!E:E,"Fisico") -> 1
B10: Total RedHat 8 | C10: =COUNTIFS(INVENTÁRIO_01_2025!C:C,"Linux",INVENTÁRIO_01_2025!D:D,"*RedHat 8*",INVENTÁRIO_01_2025!E:E,"Virtual") -> 8 | E10: Total RedHat 8 | F10: =COUNTIFS(INVENTÁRIO_01_2025!C:C,"Linux",INVENTÁRIO_01_2025!D:D,"*RedHat 8*",INVENTÁRIO_01_2025!E:E,"Fisico") -> 2 | H10: Windows 2019 | I10: =COUNTIFS(INVENTÁRIO_01_2025!C:C,"Windows",INVENTÁRIO_01_2025!D:D,"*2019*",INVENTÁRIO_01_2025!E:E,"Virtual") -> 56 | K10: Windows 2019 | L10: =COUNTIFS(INVENTÁRIO_01_2025!C:C,"Windows",INVENTÁRIO_01_2025!D:D,"*2019*",INVENTÁRIO_01_2025!E:E,"Fisico") -> 15
B11: Total RedHat 7 | C11: =COUNTIFS(INVENTÁRIO_01_2025!C:C,"Linux",INVENTÁRIO_01_2025!D:D,"*RedHat 7*",INVENTÁRIO_01_2025!E:E,"Virtual") -> 8 | E11: Total RedHat 7 | F11: =COUNTIFS(INVENTÁRIO_01_2025!C:C,"Linux",INVENTÁRIO_01_2025!D:D,"*RedHat 7*",INVENTÁRIO_01_2025!E:E,"Fisico") -> 1 | H11: Windows 2016 | I11: =COUNTIFS(INVENTÁRIO_01_2025!C:C,"Windows",INVENTÁRIO_01_2025!D:D,"*2016*",INVENTÁRIO_01_2025!E:E,"Virtual") -> 78 | K11: Windows 2016 | L11: =COUNTIFS(INVENTÁRIO_01_2025!C:C,"Windows",INVENTÁRIO_01_2025!D:D,"*2016*",INVENTÁRIO_01_2025!E:E,"Fisico") -> 0
B12: Total RedHat 6 | C12: =COUNTIFS(INVENTÁRIO_01_2025!C:C,"Linux",INVENTÁRIO_01_2025!D:D,"*RedHat 6*",INVENTÁRIO_01_2025!E:E,"Virtual") -> 10 | E12: Total RedHat 6 | F12: =COUNTIFS(INVENTÁRIO_01_2025!C:C,"Linux",INVENTÁRIO_01_2025!D:D,"*RedHat 6*",INVENTÁRIO_01_2025!E:E,"Fisico") -> 23 | H12: Windows 2012 | I12: =COUNTIFS(INVENTÁRIO_01_2025!C:C,"Windows",INVENTÁRIO_01_2025!D:D,"*2012*",INVENTÁRIO_01_2025!E:E,"Virtual") -> 51 | K12: Windows 2012 | L12: =COUNTIFS(INVENTÁRIO_01_2025!C:C,"Windows",INVENTÁRIO_01_2025!D:D,"*2012*",INVENTÁRIO_01_2025!E:E,"Fisico") -> 7
B13: Total RedHat 5 | C13: =COUNTIFS(INVENTÁRIO_01_2025!C:C,"Linux",INVENTÁRIO_01_2025!D:D,"*RedHat 5*",INVENTÁRIO_01_2025!E:E,"Virtual") -> 1 | E13: Total RedHat 5 | F13: =COUNTIFS(INVENTÁRIO_01_2025!C:C,"Linux",INVENTÁRIO_01_2025!D:D,"*RedHat 5*",INVENTÁRIO_01_2025!E:E,"Fisico") -> 1 | H13: Windows 2008 | I13: =COUNTIFS(INVENTÁRIO_01_2025!C:C,"Windows",INVENTÁRIO_01_2025!D:D,"*2008*",INVENTÁRIO_01_2025!E:E,"Virtual") -> 72 | K13: Windows 2008 | L13: =COUNTIFS(INVENTÁRIO_01_2025!C:C,"Windows",INVENTÁRIO_01_2025!D:D,"*2008*",INVENTÁRIO_01_2025!E:E,"Fisico") -> 6
B14: Total Ubuntu | C14: =COUNTIFS(INVENTÁRIO_01_2025!C:C,"Linux",INVENTÁRIO_01_2025!D:D,"*Ubuntu*",INVENTÁRIO_01_2025!E:E,"Virtual") -> 32 | E14: Total Ubuntu | F14: =COUNTIFS(INVENTÁRIO_01_2025!C:C,"Linux",INVENTÁRIO_01_2025!D:D,"*Ubuntu*",INVENTÁRIO_01_2025!E:E,"Fisico") -> 1 | H14: Windows 10 | I14: =COUNTIFS(INVENTÁRIO_01_2025!C:C,"Windows",INVENTÁRIO_01_2025!D:D,"*10*",INVENTÁRIO_01_2025!E:E,"Virtual") -> 3 | K14: Windows 10 | L14: =COUNTIFS(INVENTÁRIO_01_2025!C:C,"Windows",INVENTÁRIO_01_2025!D:D,"*10*",INVENTÁRIO_01_2025!E:E,"Fisico") -> 0
B15: Total Centos | C15: =COUNTIFS(INVENTÁRIO_01_2025!C:C,"Linux",INVENTÁRIO_01_2025!D:D,"*Centos*",INVENTÁRIO_01_2025!E:E,"Virtual") -> 9 | E15: Total Centos | F15: =COUNTIFS(INVENTÁRIO_01_2025!C:C,"Linux",INVENTÁRIO_01_2025!D:D,"*Centos*",INVENTÁRIO_01_2025!E:E,"Fisico") -> 0 | H15: Windows 8 | I15: =COUNTIFS(INVENTÁRIO_01_2025!C:C,"Windows",INVENTÁRIO_01_2025!D:D,"*Windows 8*",INVENTÁRIO_01_2025!E:E,"Virtual") -> 1 | K15: Windows 8 | L15: =COUNTIFS(INVENTÁRIO_01_2025!C:C,"Windows",INVENTÁRIO_01_2025!D:D,"*Windows 8*",INVENTÁRIO_01_2025!E:E,"Fisico") -> 0
B16: Total Debian | C16: =COUNTIFS(INVENTÁRIO_01_2025!C:C,"Linux",INVENTÁRIO_01_2025!D:D,"*Debian*",INVENTÁRIO_01_2025!E:E,"Virtual") -> 6 | E16: Total Debian | F16: =COUNTIFS(INVENTÁRIO_01_2025!C:C,"Linux",INVENTÁRIO_01_2025!D:D,"*Debian*",INVENTÁRIO_01_2025!E:E,"Fisico") -> 0 | H16: Windows 7 | I16: =COUNTIFS(INVENTÁRIO_01_2025!C:C,"Windows",INVENTÁRIO_01_2025!D:D,"*7*",INVENTÁRIO_01_2025!E:E,"Virtual") -> 4 | K16: Windows 7 | L16: =COUNTIFS(INVENTÁRIO_01_2025!C:C,"Windows",INVENTÁRIO_01_2025!D:D,"*7*",INVENTÁRIO_01_2025!E:E,"Fisico") -> 0
B17: Total Suse | C17: =COUNTIFS(INVENTÁRIO_01_2025!C:C,"Linux",INVENTÁRIO_01_2025!D:D,"*Suse*",INVENTÁRIO_01_2025!E:E,"Virtual") -> 8 | E17: Total Suse | F17: =COUNTIFS(INVENTÁRIO_01_2025!C:C,"Linux",INVENTÁRIO_01_2025!D:D,"*Suse*",INVENTÁRIO_01_2025!E:E,"Fisico") -> 0
B18: Total SOs | C18: =SUM(C9:C17) -> 87 | E18: Total SOs | F18: =SUM(F9:F17) -> 28
B19: Outros SOs | C19: =C5-C18 -> 13 | E19: Outros SOs | F19: =F5-F18 -> 21
B22: TOP 10 SO | E22: Servidores Criados | H22: Servidores Excluidos | K22: TOTAIS
B23: Windows 2019 | C23: =I10+L10 -> 71 | K23: Total Servidores | L23: =L25+L24 -> 450
B24: Windows 2016 | C24: =I11 -> 78 | K24: Total Linux | L24: =C5+F5 -> 149
B25: Windows 2008 | C25: =I13+L13 -> 78 | K25: Total Windows | L25: =L5+I5 -> 301
B26: Windows 2012 | C26: =I12+L12 -> 58 | K26: Total Fisicos | L26: =F5+L5 -> 78
B27: RedHat | C27: =C9+C10+C11+C12+C13+F9+F10+F11+F12+F13 -> 59 | K27: Total Virtuais | L27: =C5+I5 -> 372
B28: Ubuntu | C28: =C14+F14 -> 33 | K28: Total Ligadas | L28: =C7+F7+I7+L7 -> 410
B29: Centos | C29: =C15+F15 -> 9 | K29: Total Desligadas | L29: =C6+F6+I6+L6 -> 40
B30: Suse | C30: =C17+F17 -> 8
B31: Debian | C31: =C16+F16 -> 6
B32: Outros (Win7, 8, 22, App Linux) | C32: =C19+F19+I14+I15+I16+I9+L9 -> 50

Sheet INVENTÁRIO_01_2025
A1: Servidor | B1: Status | C1: Tipo SO | D1: Versão SO | E1: Fisico/Virtual | F1: Local
A2: SLOT-01 | B2: poweredOff | C2: Linux | D2: - | E2: Fisico | F2: ENCLOSURE3-JR6LBY1
A3: SPRDAPTRGRU01 | B3: poweredOff | C3: Linux | D3: - | E3: Fisico | F3: ENCLOSURE5-GQWPZ12
A4: SPRDAPBWGRU01 | B4: poweredOff | C4: Linux | D4: - | E4: Fisico | F4: ENCLOSURE6-DM8QZ12
A5: SPRDAPBWGRU02 | B5: poweredOff | C5: Linux | D5: - | E5: Fisico | F5: ENCLOSURE6-DM8QZ12
A6: SPRDVMGRU01 | B6: poweredOn | C6: Linux | D6: Appliance Vmware | E6: Fisico | F6: ENCLOSURE1-HY381Y1
A7: SPRDVMGRU02 | B7: poweredOn | C7: Linux | D7: Appliance Vmware | E7: Fisico | F7: ENCLOSURE1-HY381Y1
A8: SPRDVMGRU05 | B8: poweredOn | C8: Linux | D8: Appliance Vmware | E8: Fisico | F8: ENCLOSURE1-HY381Y1
A9: SPRDVMGRU03 | B9: poweredOn | C9: Linux | D9: Appliance Vmware | E9: Fisico | F9: ENCLOSURE2-BY381Y1
A10: SPRDVMGRU04 | B10: poweredOn | C10: Linux | D10: Appliance Vmware | E10: Fisico | F10: ENCLOSURE2-BY381Y1
A11: SPRDVMGRU06 | B11: poweredOn | C11: Linux | D11: Appliance Vmware | E11: Fisico | F11: ENCLOSURE2-BY381Y1
A12: SPRDVMSAPGRU01 | B12: poweredOn | C12: Linux | D12: Appliance Vmware | E12: Fisico | F12: ENCLOSURE5-GQWPZ12
... A451: Unknown 41 | B451: poweredOff | C451: Linux | D451: RedHat 7 | E451: Virtual | F451: Vmware 6.5

Sheet DASHBOARD_03_205
B2: Inventário Servidores Fevereiro 2025
B4: Linux Virtual | E4: Linux Fisicos | H4: Windows Virtual | K4: Windows Fisicos
B5: Total Virtuais | C5: =COUNTIFS(INVENTÁRIO_03_2025!C:C,"Linux",INVENTÁRIO_03_2025!E:E,"Virtual") -> 103 | E5: Total Fisicos | F5: =COUNTIFS(INVENTÁRIO_03_2025!C:C,"Linux",INVENTÁRIO_03_2025!E:E,"Fisico") -> 50 | H5: Total Virtuais | I5: =COUNTIFS(INVENTÁRIO_03_2025!C:C,"Windows",INVENTÁRIO_03_2025!E:E,"Virtual") -> 285 | K5: Total Fisicos | L5: =COUNTIFS(INVENTÁRIO_03_2025!C:C,"Windows",INVENTÁRIO_03_2025!E:E,"Fisico") -> 49
B6: Desligadas | C6: =COUNTIFS(INVENTÁRIO_03_2025!B:B,"poweredOff",INVENTÁRIO_03_2025!C:C,"Linux",INVENTÁRIO_03_2025!E:E,"Virtual") -> 14 | E6: Desligadas | F6: =COUNTIFS(INVENTÁRIO_03_2025!B:B,"poweredOff",INVENTÁRIO_03_2025!C:C,"Linux",INVENTÁRIO_03_2025!E:E,"Fisico") -> 4 | H6: Desligadas | I6: =COUNTIFS(INVENTÁRIO_03_2025!B:B,"poweredOff",INVENTÁRIO_03_2025!C:C,"Windows",INVENTÁRIO_03_2025!E:E,"Virtual") -> 25 | K6: Desligadas | L6: =COUNTIFS(INVENTÁRIO_03_2025!B:B,"poweredOff",INVENTÁRIO_03_2025!C:C,"Windows",INVENTÁRIO_03_2025!E:E,"Fisico") -> 28
B7: Ligadas | C7: =COUNTIFS(INVENTÁRIO_03_2025!B:B,"poweredOn",INVENTÁRIO_03_2025!C:C,"Linux",INVENTÁRIO_03_2025!E:E,"Virtual") -> 89 | E7: Ligadas | F7: =COUNTIFS(INVENTÁRIO_03_2025!B:B,"poweredOn",INVENTÁRIO_03_2025!C:C,"Linux",INVENTÁRIO_03_2025!E:E,"Fisico") -> 46 | H7: Ligadas | I7: =COUNTIFS(INVENTÁRIO_03_2025!B:B,"poweredOn",INVENTÁRIO_03_2025!C:C,"Windows",INVENTÁRIO_03_2025!E:E,"Virtual") -> 260 | K7: Ligadas | L7: =COUNTIFS(INVENTÁRIO_03_2025!B:B,"poweredOn",INVENTÁRIO_03_2025!C:C,"Windows",INVENTÁRIO_03_2025!E:E,"Fisico") -> 21
B9: Total RedHat 9 | C9: =COUNTIFS(INVENTÁRIO_03_2025!C:C,"Linux",INVENTÁRIO_03_2025!D:D,"*RedHat 9*",INVENTÁRIO_03_2025!E:E,"Virtual") -> 7 | E9: Total RedHat 9 | F9: =COUNTIFS(INVENTÁRIO_03_2025!C:C,"Linux",INVENTÁRIO_03_2025!D:D,"*RedHat 9*",INVENTÁRIO_03_2025!E:E,"Fisico") -> 0 | H9: Windows 2022 | I9: =COUNTIFS(INVENTÁRIO_03_2025!C:C,"Windows",INVENTÁRIO_03_2025!D:D,"*2022*",INVENTÁRIO_03_2025!E:E,"Virtual") -> 16 | K9: Windows 2022 | L9: =COUNTIFS(INVENTÁRIO_03_2025!C:C,"Windows",INVENTÁRIO_03_2025!D:D,"*2022*",INVENTÁRIO_03_2025!E:E,"Fisico") -> 22
B10: Total RedHat 8 | C10: =COUNTIFS(INVENTÁRIO_03_2025!C:C,"Linux",INVENTÁRIO_03_2025!D:D,"*RedHat 8*",INVENTÁRIO_03_2025!E:E,"Virtual") -> 10 | E10: Total RedHat 8 | F10: =COUNTIFS(INVENTÁRIO_03_2025!C:C,"Linux",INVENTÁRIO_03_2025!D:D,"*RedHat 8*",INVENTÁRIO_03_2025!E:E,"Fisico") -> 2 | H10: Windows 2019 | I10: =COUNTIFS(INVENTÁRIO_03_2025!C:C,"Windows",INVENTÁRIO_03_2025!D:D,"*2019*",INVENTÁRIO_03_2025!E:E,"Virtual") -> 56 | K10: Windows 2019 | L10: =COUNTIFS(INVENTÁRIO_03_2025!C:C,"Windows",INVENTÁRIO_03_2025!D:D,"*2019*",INVENTÁRIO_03_2025!E:E,"Fisico") -> 14
B11: Total RedHat 7 | C11: =COUNTIFS(INVENTÁRIO_03_2025!C:C,"Linux",INVENTÁRIO_03_2025!D:D,"*RedHat 7*",INVENTÁRIO_03_2025!E:E,"Virtual") -> 9 | E11: Total RedHat 7 | F11: =COUNTIFS(INVENTÁRIO_03_2025!C:C,"Linux",INVENTÁRIO_03_2025!D:D,"*RedHat 7*",INVENTÁRIO_03_2025!E:E,"Fisico") -> 1 | H11: Windows 2016 | I11: =COUNTIFS(INVENTÁRIO_03_2025!C:C,"Windows",INVENTÁRIO_03_2025!D:D,"*2016*",INVENTÁRIO_03_2025!E:E,"Virtual") -> 81 | K11: Windows 2016 | L11: =COUNTIFS(INVENTÁRIO_03_2025!C:C,"Windows",INVENTÁRIO_03_2025!D:D,"*2016*",INVENTÁRIO_03_2025!E:E,"Fisico") -> 0
B12: Total RedHat 6 | C12: =COUNTIFS(INVENTÁRIO_03_2025!C:C,"Linux",INVENTÁRIO_03_2025!D:D,"*RedHat 6*",INVENTÁRIO_03_2025!E:E,"Virtual") -> 10 | E12: Total RedHat 6 | F12: =COUNTIFS(INVENTÁRIO_03_2025!C:C,"Linux",INVENTÁRIO_03_2025!D:D,"*RedHat 6*",INVENTÁRIO_03_2025!E:E,"Fisico") -> 23 | H12: Windows 2012 | I12: =COUNTIFS(INVENTÁRIO_03_2025!C:C,"Windows",INVENTÁRIO_03_2025!D:D,"*2012*",INVENTÁRIO_03_2025!E:E,"Virtual") -> 52 | K12: Windows 2012 | L12: =COUNTIFS(INVENTÁRIO_03_2025!C:C,"Windows",INVENTÁRIO_03_2025!D:D,"*2012*",INVENTÁRIO_03_2025!E:E,"Fisico") -> 7
B13: Total RedHat 5 | C13: =COUNTIFS(INVENTÁRIO_03_2025!C:C,"Linux",INVENTÁRIO_03_2025!D:D,"*RedHat 5*",INVENTÁRIO_03_2025!E:E,"Virtual") -> 1 | E13: Total RedHat 5 | F13: =COUNTIFS(INVENTÁRIO_03_2025!C:C,"Linux",INVENTÁRIO_03_2025!D:D,"*RedHat 5*",INVENTÁRIO_03_2025!E:E,"Fisico") -> 1 | H13: Windows 2008 | I13: =COUNTIFS(INVENTÁRIO_03_2025!C:C,"Windows",INVENTÁRIO_03_2025!D:D,"*2008*",INVENTÁRIO_03_2025!E:E,"Virtual") -> 72 | K13: Windows 2008 | L13: =COUNTIFS(INVENTÁRIO_03_2025!C:C,"Windows",INVENTÁRIO_03_2025!D:D,"*2008*",INVENTÁRIO_03_2025!E:E,"Fisico") -> 6
B14: Total Ubuntu | C14: =COUNTIFS(INVENTÁRIO_03_2025!C:C,"Linux",INVENTÁRIO_03_2025!D:D,"*Ubuntu*",INVENTÁRIO_03_2025!E:E,"Virtual") -> 33 | E14: Total Ubuntu | F14: =COUNTIFS(INVENTÁRIO_03_2025!C:C,"Linux",INVENTÁRIO_03_2025!D:D,"*Ubuntu*",INVENTÁRIO_03_2025!E:E,"Fisico") -> 1 | H14: Windows 10 | I14: =COUNTIFS(INVENTÁRIO_03_2025!C:C,"Windows",INVENTÁRIO_03_2025!D:D,"*10*",INVENTÁRIO_03_2025!E:E,"Virtual") -> 3 | K14: Windows 10 | L14: =COUNTIFS(INVENTÁRIO_03_2025!C:C,"Windows",INVENTÁRIO_03_2025!D:D,"*10*",INVENTÁRIO_03_2025!E:E,"Fisico") -> 0
B15: Total Centos | C15: =COUNTIFS(INVENTÁRIO_03_2025!C:C,"Linux",INVENTÁRIO_03_2025!D:D,"*Centos*",INVENTÁRIO_03_2025!E:E,"Virtual") -> 6 | E15: Total Centos | F15: =COUNTIFS(INVENTÁRIO_03_2025!C:C,"Linux",INVENTÁRIO_03_2025!D:D,"*Centos*",INVENTÁRIO_03_2025!E:E,"Fisico") -> 0 | H15: Windows 8 | I15: =COUNTIFS(INVENTÁRIO_03_2025!C:C,"Windows",INVENTÁRIO_03_2025!D:D,"*Windows 8*",INVENTÁRIO_03_2025!E:E,"Virtual") -> 1 | K15: Windows 8 | L15: =COUNTIFS(INVENTÁRIO_03_2025!C:C,"Windows",INVENTÁRIO_03_2025!D:D,"*Windows 8*",INVENTÁRIO_03_2025!E:E,"Fisico") -> 0
B16: Total Debian | C16: =COUNTIFS(INVENTÁRIO_03_2025!C:C,"Linux",INVENTÁRIO_03_2025!D:D,"*Debian*",INVENTÁRIO_03_2025!E:E,"Virtual") -> 6 | E16: Total Debian | F16: =COUNTIFS(INVENTÁRIO_03_2025!C:C,"Linux",INVENTÁRIO_03_2025!D:D,"*Debian*",INVENTÁRIO_03_2025!E:E,"Fisico") -> 0 | H16: Windows 7 | I16: =COUNTIFS(INVENTÁRIO_03_2025!C:C,"Windows",INVENTÁRIO_03_2025!D:D,"*7*",INVENTÁRIO_03_2025!E:E,"Virtual") -> 4 | K16: Windows 7 | L16: =COUNTIFS(INVENTÁRIO_03_2025!C:C,"Windows",INVENTÁRIO_03_2025!D:D,"*7*",INVENTÁRIO_03_2025!E:E,"Fisico") -> 0
B17: Total Suse | C17: =COUNTIFS(INVENTÁRIO_03_2025!C:C,"Linux",INVENTÁRIO_03_2025!D:D,"*Suse*",INVENTÁRIO_03_2025!E:E,"Virtual") -> 8 | E17: Total Suse | F17: =COUNTIFS(INVENTÁRIO_03_2025!C:C,"Linux",INVENTÁRIO_03_2025!D:D,"*Suse*",INVENTÁRIO_03_2025!E:E,"Fisico") -> 0
B18: Total SOs | C18: =SUM(C9:C17) -> 90 | E18: Total SOs | F18: =SUM(F9:F17) -> 28
B19: Outros SOs | C19: =C5-C18 -> 13 | E19: Outros SOs | F19: =F5-F18 -> 22
B22: TOP 10 SO | E22: Servidores Criados | H22: Servidores Excluidos | K22: TOTAIS
B23: Windows 2019 | C23: =I10+L10 -> 70 | K23: Total Servidores | L23: =L25+L24 -> 487
B24: Windows 2016 | C24: =I11 -> 81 | K24: Total Linux | L24: =C5+F5 -> 153
B25: Windows 2008 | C25: =I13+L13 -> 78 | K25: Total Windows | L25: =L5+I5 -> 334
B26: Windows 2012 | C26: =I12+L12 -> 59 | K26: Total Fisicos | L26: =F5+L5 -> 99
B27: RedHat | C27: =C9+C10+C11+C12+C13+F9+F10+F11+F12+F13 -> 64 | K27: Total Virtuais | L27: =C5+I5 -> 388
B28: Ubuntu | C28: =C14+F14 -> 34 | K28: Total Ligadas | L28: =C7+F7+I7+L7 -> 416
B29: Centos | C29: =C15+F15 -> 6 | K29: Total Desligadas | L29: =C6+F6+I6+L6 -> 71
B30: Suse | C30: =C17+F17 -> 8
B31: Debian | C31: =C16+F16 -> 6
B32: Outros (Win7, 8, 22, App Linux) | C32: =C19+F19+I14+I15+I16+I9+L9 -> 81

Sheet INVENTÁRIO_03_2025
A1: Servidor | B1: Status | C1: Tipo SO | D1: Versão SO | E1: Fisico/Virtual | F1: Local
A2: SPRDVMGRU01 | B2: poweredOn | C2: Linux | D2: Appliance Vmware | E2: Fisico | F2: ENCLOSURE1-HY381Y1
A3: SPRDVMGRU02 | B3: poweredOn | C3: Linux | D3: Appliance Vmware | E3: Fisico | F3: ENCLOSURE1-HY381Y1
A4: SPRDVMGRU05 | B4: poweredOn | C4: Linux | D4: Appliance Vmware | E4: Fisico | F4: ENCLOSURE1-HY381Y1
A5: SPRDBDORAGRU03 | B5: poweredOn | C5: Linux | D5: RedHat 5 | E5: Fisico | F5: ENCLOSURE1-HY381Y1
A6: SHOMBDORAGRU01 | B6: poweredOn | C6: Linux | D6: RedHat 6 | E6: Fisico | F6: ENCLOSURE1-HY381Y1
A7: SPRDAPCMSGRU02 | B7: poweredOn | C7: Linux | D7: RedHat 6 | E7: Fisico | F7: ENCLOSURE1-HY381Y1
A8: SPRDBDORAGRU04 | B8: poweredOn | C8: Linux | D8: RedHat 6 | E8: Fisico | F8: ENCLOSURE1-HY381Y1
A9: SPRDAPCMSGRU07 | B9: poweredOn | C9: Linux | D9: RedHat 6 | E9: Fisico | F9: ENCLOSURE1-HY381Y1
A10: SPRDSQLGRU10 | B10: poweredOn | C10: Windows | D10: Windows Server 2012 R2 Datacenter | E10: Fisico | F10: ENCLOSURE1-HY381Y1
A11: SPRDAPDMZGRU01 | B11: poweredOff | C11: Windows | D11: Windows Server 2019 Datacenter | E11: Fisico | F11: ENCLOSURE1-HY381Y1
A12: SPRDVMGRU03 | B12: poweredOn | C12: Linux | D12: Appliance Vmware | E12: Fisico | F12: ENCLOSURE2-BY381Y1
... A488: GRUSPRDCFTV220 | B488: poweredOff | C488: Windows | D488: Windows Server 2022 Standard | E488: Fisico | F488: TPS3

Sheet DASHBOARD_04_2025
B2: Inventário Servidores Abril 2025
B4: Linux Virtual | E4: Linux Fisicos | H4: Windows Virtual | K4: Windows Fisicos
B5: Total Virtuais | C5: =COUNTIFS(INVENTÁRIO_04_2025!C:C,"Linux",INVENTÁRIO_04_2025!E:E,"Virtual") -> 104 | E5: Total Fisicos | F5: =COUNTIFS(INVENTÁRIO_04_2025!C:C,"Linux",INVENTÁRIO_04_2025!E:E,"Fisico") -> 50 | H5: Total Virtuais | I5: =COUNTIFS(INVENTÁRIO_04_2025!C:C,"Windows",INVENTÁRIO_04_2025!E:E,"Virtual") -> 284 | K5: Total Fisicos | L5: =COUNTIFS(INVENTÁRIO_04_2025!C:C,"Windows",INVENTÁRIO_04_2025!E:E,"Fisico") -> 49
B6: Desligadas | C6: =COUNTIFS(INVENTÁRIO_04_2025!B:B,"poweredOff",INVENTÁRIO_04_2025!C:C,"Linux",INVENTÁRIO_04_2025!E:E,"Virtual") -> 7 | E6: Desligadas | F6: =COUNTIFS(INVENTÁRIO_04_2025!B:B,"poweredOff",INVENTÁRIO_04_2025!C:C,"Linux",INVENTÁRIO_04_2025!E:E,"Fisico") -> 4 | H6: Desligadas | I6: =COUNTIFS(INVENTÁRIO_04_2025!B:B,"poweredOff",INVENTÁRIO_04_2025!C:C,"Windows",INVENTÁRIO_04_2025!E:E,"Virtual") -> 17 | K6: Desligadas | L6: =COUNTIFS(INVENTÁRIO_04_2025!B:B,"poweredOff",INVENTÁRIO_04_2025!C:C,"Windows",INVENTÁRIO_04_2025!E:E,"Fisico") -> 28
B7: Ligadas | C7: =COUNTIFS(INVENTÁRIO_04_2025!B:B,"poweredOn",INVENTÁRIO_04_2025!C:C,"Linux",INVENTÁRIO_04_2025!E:E,"Virtual") -> 97 | E7: Ligadas | F7: =COUNTIFS(INVENTÁRIO_04_2025!B:B,"poweredOn",INVENTÁRIO_04_2025!C:C,"Linux",INVENTÁRIO_04_2025!E:E,"Fisico") -> 46 | H7: Ligadas | I7: =COUNTIFS(INVENTÁRIO_04_2025!B:B,"poweredOn",INVENTÁRIO_04_2025!C:C,"Windows",INVENTÁRIO_04_2025!E:E,"Virtual") -> 267 | K7: Ligadas | L7: =COUNTIFS(INVENTÁRIO_04_2025!B:B,"poweredOn",INVENTÁRIO_04_2025!C:C,"Windows",INVENTÁRIO_04_2025!E:E,"Fisico") -> 21
B9: Total RedHat 9 | C9: =COUNTIFS(INVENTÁRIO_04_2025!C:C,"Linux",INVENTÁRIO_04_2025!D:D,"*RedHat 9*",INVENTÁRIO_04_2025!E:E,"Virtual") -> 15 | E9: Total RedHat 9 | F9: =COUNTIFS(INVENTÁRIO_04_2025!C:C,"Linux",INVENTÁRIO_04_2025!D:D,"*RedHat 9*",INVENTÁRIO_04_2025!E:E,"Fisico") -> 0 | H9: Windows 2022 | I9: =COUNTIFS(INVENTÁRIO_04_2025!C:C,"Windows",INVENTÁRIO_04_2025!D:D,"*2022*",INVENTÁRIO_04_2025!E:E,"Virtual") -> 25 | K9: Windows 2022 | L9: =COUNTIFS(INVENTÁRIO_04_2025!C:C,"Windows",INVENTÁRIO_04_2025!D:D,"*2022*",INVENTÁRIO_04_2025!E:E,"Fisico") -> 22
B10: Total RedHat 8 | C10: =COUNTIFS(INVENTÁRIO_04_2025!C:C,"Linux",INVENTÁRIO_04_2025!D:D,"*RedHat 8*",INVENTÁRIO_04_2025!E:E,"Virtual") -> 8 | E10: Total RedHat 8 | F10: =COUNTIFS(INVENTÁRIO_04_2025!C:C,"Linux",INVENTÁRIO_04_2025!D:D,"*RedHat 8*",INVENTÁRIO_04_2025!E:E,"Fisico") -> 2 | H10: Windows 2019 | I10: =COUNTIFS(INVENTÁRIO_04_2025!C:C,"Windows",INVENTÁRIO_04_2025!D:D,"*2019*",INVENTÁRIO_04_2025!E:E,"Virtual") -> 52 | K10: Windows 2019 | L10: =COUNTIFS(INVENTÁRIO_04_2025!C:C,"Windows",INVENTÁRIO_04_2025!D:D,"*2019*",INVENTÁRIO_04_2025!E:E,"Fisico") -> 14
B11: Total RedHat 7 | C11: =COUNTIFS(INVENTÁRIO_04_2025!C:C,"Linux",INVENTÁRIO_04_2025!D:D,"*RedHat 7*",INVENTÁRIO_04_2025!E:E,"Virtual") -> 10 | E11: Total RedHat 7 | F11: =COUNTIFS(INVENTÁRIO_04_2025!C:C,"Linux",INVENTÁRIO_04_2025!D:D,"*RedHat 7*",INVENTÁRIO_04_2025!E:E,"Fisico") -> 1 | H11: Windows 2016 | I11: =COUNTIFS(INVENTÁRIO_04_2025!C:C,"Windows",INVENTÁRIO_04_2025!D:D,"*2016*",INVENTÁRIO_04_2025!E:E,"Virtual") -> 76 | K11: Windows 2016 | L11: =COUNTIFS(INVENTÁRIO_04_2025!C:C,"Windows",INVENTÁRIO_04_2025!D:D,"*2016*",INVENTÁRIO_04_2025!E:E,"Fisico") -> 0
B12: Total RedHat 6 | C12: =COUNTIFS(INVENTÁRIO_04_2025!C:C,"Linux",INVENTÁRIO_04_2025!D:D,"*RedHat 6*",INVENTÁRIO_04_2025!E:E,"Virtual") -> 10 | E12: Total RedHat 6 | F12: =COUNTIFS(INVENTÁRIO_04_2025!C:C,"Linux",INVENTÁRIO_04_2025!D:D,"*RedHat 6*",INVENTÁRIO_04_2025!E:E,"Fisico") -> 23 | H12: Windows 2012 | I12: =COUNTIFS(INVENTÁRIO_04_2025!C:C,"Windows",INVENTÁRIO_04_2025!D:D,"*2012*",INVENTÁRIO_04_2025!E:E,"Virtual") -> 51 | K12: Windows 2012 | L12: =COUNTIFS(INVENTÁRIO_04_2025!C:C,"Windows",INVENTÁRIO_04_2025!D:D,"*2012*",INVENTÁRIO_04_2025!E:E,"Fisico") -> 7
B13: Total RedHat 5 | C13: =COUNTIFS(INVENTÁRIO_04_2025!C:C,"Linux",INVENTÁRIO_04_2025!D:D,"*RedHat 5*",INVENTÁRIO_04_2025!E:E,"Virtual") -> 0 | E13: Total RedHat 5 | F13: =COUNTIFS(INVENTÁRIO_04_2025!C:C,"Linux",INVENTÁRIO_04_2025!D:D,"*RedHat 5*",INVENTÁRIO_04_2025!E:E,"Fisico") -> 1 | H13: Windows 2008 | I13: =COUNTIFS(INVENTÁRIO_04_2025!C:C,"Windows",INVENTÁRIO_04_2025!D:D,"*2008*",INVENTÁRIO_04_2025!E:E,"Virtual") -> 72 | K13: Windows 2008 | L13: =COUNTIFS(INVENTÁRIO_04_2025!C:C,"Windows",INVENTÁRIO_04_2025!D:D,"*2008*",INVENTÁRIO_04_2025!E:E,"Fisico") -> 6
B14: Total Ubuntu | C14: =COUNTIFS(INVENTÁRIO_04_2025!C:C,"Linux",INVENTÁRIO_04_2025!D:D,"*Ubuntu*",INVENTÁRIO_04_2025!E:E,"Virtual") -> 30 | E14: Total Ubuntu | F14: =COUNTIFS(INVENTÁRIO_04_2025!C:C,"Linux",INVENTÁRIO_04_2025!D:D,"*Ubuntu*",INVENTÁRIO_04_2025!E:E,"Fisico") -> 1 | H14: Windows 10 | I14: =COUNTIFS(INVENTÁRIO_04_2025!C:C,"Windows",INVENTÁRIO_04_2025!D:D,"*10*",INVENTÁRIO_04_2025!E:E,"Virtual") -> 3 | K14: Windows 10 | L14: =COUNTIFS(INVENTÁRIO_04_2025!C:C,"Windows",INVENTÁRIO_04_2025!D:D,"*10*",INVENTÁRIO_04_2025!E:E,"Fisico") -> 0
B15: Total Centos | C15: =COUNTIFS(INVENTÁRIO_04_2025!C:C,"Linux",INVENTÁRIO_04_2025!D:D,"*Centos*",INVENTÁRIO_04_2025!E:E,"Virtual") -> 6 | E15: Total Centos | F15: =COUNTIFS(INVENTÁRIO_04_2025!C:C,"Linux",INVENTÁRIO_04_2025!D:D,"*Centos*",INVENTÁRIO_04_2025!E:E,"Fisico") -> 0 | H15: Windows 8 | I15: =COUNTIFS(INVENTÁRIO_04_2025!C:C,"Windows",INVENTÁRIO_04_2025!D:D,"*Windows 8*",INVENTÁRIO_04_2025!E:E,"Virtual") -> 1 | K15: Windows 8 | L15: =COUNTIFS(INVENTÁRIO_04_2025!C:C,"Windows",INVENTÁRIO_04_2025!D:D,"*Windows 8*",INVENTÁRIO_04_2025!E:E,"Fisico") -> 0
B16: Total Debian | C16: =COUNTIFS(INVENTÁRIO_04_2025!C:C,"Linux",INVENTÁRIO_04_2025!D:D,"*Debian*",INVENTÁRIO_04_2025!E:E,"Virtual") -> 6 | E16: Total Debian | F16: =COUNTIFS(INVENTÁRIO_04_2025!C:C,"Linux",INVENTÁRIO_04_2025!D:D,"*Debian*",INVENTÁRIO_04_2025!E:E,"Fisico") -> 0 | H16: Windows 7 | I16: =COUNTIFS(INVENTÁRIO_04_2025!C:C,"Windows",INVENTÁRIO_04_2025!D:D,"*7*",INVENTÁRIO_04_2025!E:E,"Virtual") -> 4 | K16: Windows 7 | L16: =COUNTIFS(INVENTÁRIO_04_2025!C:C,"Windows",INVENTÁRIO_04_2025!D:D,"*7*",INVENTÁRIO_04_2025!E:E,"Fisico") -> 0
B17: Total Suse | C17: =COUNTIFS(INVENTÁRIO_04_2025!C:C,"Linux",INVENTÁRIO_04_2025!D:D,"*Suse*",INVENTÁRIO_04_2025!E:E,"Virtual") -> 8 | E17: Total Suse | F17: =COUNTIFS(INVENTÁRIO_04_2025!C:C,"Linux",INVENTÁRIO_04_2025!D:D,"*Suse*",INVENTÁRIO_04_2025!E:E,"Fisico") -> 0
B18: Total SOs | C18: =SUM(C9:C17) -> 93 | E18: Total SOs | F18: =SUM(F9:F17) -> 28
B19: Outros SOs | C19: =C5-C18 -> 11 | E19: Outros SOs | F19: =F5-F18 -> 22
B22: TOP 10 SO | E22: Servidores Criados | H22: Servidores Excluidos | K22: Totais
B23: Windows 2022 | C23: =I9+L9 -> 47 | E23: SHOMAPLGGRU01_REMOV... | H23: SHOMFSQUA01 | K23: Total Servidores | L23: =L25+L24 -> 487
B24: Windows 2019 | C24: =I10+L10 -> 66 | E24: SHOMAPBCBPGRU02 | H24: SPRDAPCSPGRU01 | K24: Total Linux | L24: =C5+F5 -> 154
B25: Windows 2016 | C25: =I11 -> 76 | E25: SHOMAPLGGRU03_REMOV... | H25: SPRDAPCCGRU03_RESTORE | K25: Total Windows | L25: =L5+I5 -> 333
B26: Windows 2008 | C26: =I13+L13 -> 78 | E26: SPRDFSQUA01 | H26: SPRDAPCCPRGRU01_RESTORE | K26: Total Fisicos | L26: =F5+L5 -> 99
B27: Windows 2012 | C27: =I12+L12 -> 58 | E27: SHOMAPCUPSGRU01 | H27: SPRDAPCCPRGRU02_RESTORE | K27: Total Virtuais | L27: =C5+I5 -> 388
B28: RedHat | C28: =C9+C10+C11+C12+C13+F9+F10+F11+F12+F13 -> 70 | E28: SHOMAPGPROGRU01 | H28: SPRDAPCUPSGRU03_RESTORE | K28: Total Ligadas | L28: =C7+F7+I7+L7 -> 431
B29: Ubuntu | C29: =C14+F14 -> 31 | E29: SHOMAPPHPIGRU01 | H29: SPRDAPCUPSGRU04_RESTORE | K29: Total Desligadas | L29: =C6+F6+I6+L6 -> 56
B30: Centos | C30: =C15+F15 -> 6 | E30: SPRDAPZABGRU02_RESTORE | H30: SPRDAPDHCPGRU02_RESTORE | K30: Total Criados | L30: 22
B31: Suse | C31: =C17+F17 -> 8 | E31: TP_REDHAT9.4_16102024 | H31: SPRDAPHSEGRU01_RESTORE | K31: Total Excluidos | L31: 22
B32: Debian | C32: =C16+F16 -> 6 | E32: TP_UBUNTU_24 | H32: SPRDAPHSEGRU02_RESTORE
B33: Outros (Win7, 8, App Linux) | C33: =C19+F19+I14+I15+I16 -> 41 | E33: SPRDAPCMSM01 | H33: SPRDAPLGGRU01_RESTORE
E34: SPRDAPCMSP01 | H34: SPRDAPLGGRU03_RESTORE
E35: SPRDAPCMSP02 | H35: SPRDAPRPGRU03
E36: SPRDAPCMSP03 | H36: SPRDAPRPGRU04
E37: SPRDAPCMSW01 | H37: SPRDAPRPGRU10_RESTORE
E38: SPRDAPCMSW02 | H38: SPRDSKDAUGRU02_RESTORE
E39: SPRDAPBCBPGRU02 | H39: SPRDSKESBGRU01_RESTORE
E40: SPRDAPRIMAGRU01 | H40: SPRDSQLLGGRU02_RESTORE
E41: SPRDBDHSQLGRU12 | H41: SPRDVCHSEGRU03_RESTORE
E42: SPRDBDHSQLGRU13 | H42: SPRDVCSCGGRU01
E43: SPRDBDHSQLGRU14 | H43: SPRDVCWKIGRU01
E44: SPRDBDHSQLGRU14_CLONE | H44: SPRDBDOTRSGRU02

Sheet INVENTÁRIO_04_2025
A1: Servidor | B1: Status | C1: Tipo SO | D1: Versão SO | E1: Fisico/Virtual | F1: Local | G1: Comparação
A2: SLOT-01 | B2: poweredOff | C2: Linux | D2: - | E2: Fisico | F2: ENCLOSURE3-JR6LBY1 | G2: =VLOOKUP(A:A,INVENTÁRIO_05_2025!A:A,1,0) -> SLOT-01
A3: SPRDAPTRGRU01 | B3: poweredOff | C3: Linux | D3: - | E3: Fisico | F3: ENCLOSURE5-GQWPZ12 | G3: =VLOOKUP(A:A,INVENTÁRIO_05_2025!A:A,1,0) -> SPRDAPTRGRU01
A4: SPRDAPBWGRU01 | B4: poweredOff | C4: Linux | D4: - | E4: Fisico | F4: ENCLOSURE6-DM8QZ12 | G4: =VLOOKUP(A:A,INVENTÁRIO_05_2025!A:A,1,0) -> SPRDAPBWGRU01
A5: SPRDAPBWGRU02 | B5: poweredOff | C5: Linux | D5: - | E5: Fisico | F5: ENCLOSURE6-DM8QZ12 | G5: =VLOOKUP(A:A,INVENTÁRIO_05_2025!A:A,1,0) -> SPRDAPBWGRU02
A6: SPRDVMGRU01 | B6: poweredOn | C6: Linux | D6: Appliance Vmware | E6: Fisico | F6: ENCLOSURE1-HY381Y1 | G6: =VLOOKUP(A:A,INVENTÁRIO_05_2025!A:A,1,0) -> SPRDVMGRU01
A7: SPRDVMGRU02 | B7: poweredOn | C7: Linux | D7: Appliance Vmware | E7: Fisico | F7: ENCLOSURE1-HY381Y1 | G7: =VLOOKUP(A:A,INVENTÁRIO_05_2025!A:A,1,0) -> SPRDVMGRU02
A8: SPRDVMGRU05 | B8: poweredOn | C8: Linux | D8: Appliance Vmware | E8: Fisico | F8: ENCLOSURE1-HY381Y1 | G8: =VLOOKUP(A:A,INVENTÁRIO_05_2025!A:A,1,0) -> SPRDVMGRU05
A9: SPRDVMGRU03 | B9: poweredOn | C9: Linux | D9: Appliance Vmware | E9: Fisico | F9: ENCLOSURE2-BY381Y1 | G9: =VLOOKUP(A:A,INVENTÁRIO_05_2025!A:A,1,0) -> SPRDVMGRU03
A10: SPRDVMGRU04 | B10: poweredOn | C10: Linux | D10: Appliance Vmware | E10: Fisico | F10: ENCLOSURE2-BY381Y1 | G10: =VLOOKUP(A:A,INVENTÁRIO_05_2025!A:A,1,0) -> SPRDVMGRU04
A11: SPRDVMGRU06 | B11: poweredOn | C11: Linux | D11: Appliance Vmware | E11: Fisico | F11: ENCLOSURE2-BY381Y1 | G11: =VLOOKUP(A:A,INVENTÁRIO_05_2025!A:A,1,0) -> SPRDVMGRU06
A12: SPRDVMSAPGRU01 | B12: poweredOn | C12: Linux | D12: Appliance Vmware | E12: Fisico | F12: ENCLOSURE5-GQWPZ12 | G12: =VLOOKUP(A:A,INVENTÁRIO_05_2025!A:A,1,0) -> SPRDVMSAPGRU01
A13: SPRDVMSAPGRU02 | B13: poweredOn | C13: Linux | D13: Appliance Vmware | E13: Fisico | F13: ENCLOSURE5-GQWPZ12 | G13: =VLOOKUP(A:A,INVENTÁRIO_05_2025!A:A,1,0) -> SPRDVMSAPGRU02
... A488: Unknown 41 | B488: poweredOff | C488: Linux | D488: RedHat 7 | E488: Virtual | F488: TPS2 | G488: =VLOOKUP(A:A,INVENTÁRIO_05_2025!A:A,1,0) -> Unknown 41

Sheet DASHBOARD_05_2025
B2: Inventário Servidores Maio 2025
B4: Linux Virtual | E4: Linux Fisicos | H4: Windows Virtual | K4: Windows Fisicos
B5: Total Virtuais | C5: =COUNTIFS(INVENTÁRIO_05_2025!C:C,"Linux",INVENTÁRIO_05_2025!E:E,"Virtual") -> 106 | E5: Total Fisicos | F5: =COUNTIFS(INVENTÁRIO_05_2025!C:C,"Linux",INVENTÁRIO_05_2025!E:E,"Fisico") -> 50 | H5: Total Virtuais | I5: =COUNTIFS(INVENTÁRIO_05_2025!C:C,"Windows",INVENTÁRIO_05_2025!E:E,"Virtual") -> 283 | K5: Total Fisicos | L5: =COUNTIFS(INVENTÁRIO_05_2025!C:C,"Windows",INVENTÁRIO_05_2025!E:E,"Fisico") -> 49
B6: Desligadas | C6: =COUNTIFS(INVENTÁRIO_05_2025!B:B,"poweredOff",INVENTÁRIO_05_2025!C:C,"Linux",INVENTÁRIO_05_2025!E:E,"Virtual") -> 11 | E6: Desligadas | F6: =COUNTIFS(INVENTÁRIO_05_2025!B:B,"poweredOff",INVENTÁRIO_05_2025!C:C,"Linux",INVENTÁRIO_05_2025!E:E,"Fisico") -> 4 | H6: Desligadas | I6: =COUNTIFS(INVENTÁRIO_05_2025!B:B,"poweredOff",INVENTÁRIO_05_2025!C:C,"Windows",INVENTÁRIO_05_2025!E:E,"Virtual") -> 16 | K6: Desligadas | L6: =COUNTIFS(INVENTÁRIO_05_2025!B:B,"poweredOff",INVENTÁRIO_05_2025!C:C,"Windows",INVENTÁRIO_05_2025!E:E,"Fisico") -> 28
B7: Ligadas | C7: =COUNTIFS(INVENTÁRIO_05_2025!B:B,"poweredOn",INVENTÁRIO_05_2025!C:C,"Linux",INVENTÁRIO_05_2025!E:E,"Virtual") -> 95 | E7: Ligadas | F7: =COUNTIFS(INVENTÁRIO_05_2025!B:B,"poweredOn",INVENTÁRIO_05_2025!C:C,"Linux",INVENTÁRIO_05_2025!E:E,"Fisico") -> 46 | H7: Ligadas | I7: =COUNTIFS(INVENTÁRIO_05_2025!B:B,"poweredOn",INVENTÁRIO_05_2025!C:C,"Windows",INVENTÁRIO_05_2025!E:E,"Virtual") -> 267 | K7: Ligadas | L7: =COUNTIFS(INVENTÁRIO_05_2025!B:B,"poweredOn",INVENTÁRIO_05_2025!C:C,"Windows",INVENTÁRIO_05_2025!E:E,"Fisico") -> 21
B9: Total RedHat 9 | C9: =COUNTIFS(INVENTÁRIO_05_2025!C:C,"Linux",INVENTÁRIO_05_2025!D:D,"*RedHat 9*",INVENTÁRIO_05_2025!E:E,"Virtual") -> 16 | E9: Total RedHat 9 | F9: =COUNTIFS(INVENTÁRIO_05_2025!C:C,"Linux",INVENTÁRIO_05_2025!D:D,"*RedHat 9*",INVENTÁRIO_05_2025!E:E,"Fisico") -> 0 | H9: Windows 2022 | I9: =COUNTIFS(INVENTÁRIO_05_2025!C:C,"Windows",INVENTÁRIO_05_2025!D:D,"*2022*",INVENTÁRIO_05_2025!E:E,"Virtual") -> 29 | K9: Windows 2022 | L9: =COUNTIFS(INVENTÁRIO_05_2025!C:C,"Windows",INVENTÁRIO_05_2025!D:D,"*2022*",INVENTÁRIO_05_2025!E:E,"Fisico") -> 22
B10: Total RedHat 8 | C10: =COUNTIFS(INVENTÁRIO_05_2025!C:C,"Linux",INVENTÁRIO_05_2025!D:D,"*RedHat 8*",INVENTÁRIO_05_2025!E:E,"Virtual") -> 9 | E10: Total RedHat 8 | F10: =COUNTIFS(INVENTÁRIO_05_2025!C:C,"Linux",INVENTÁRIO_05_2025!D:D,"*RedHat 8*",INVENTÁRIO_05_2025!E:E,"Fisico") -> 2 | H10: Windows 2019 | I10: =COUNTIFS(INVENTÁRIO_05_2025!C:C,"Windows",INVENTÁRIO_05_2025!D:D,"*2019*",INVENTÁRIO_05_2025!E:E,"Virtual") -> 50 | K10: Windows 2019 | L10: =COUNTIFS(INVENTÁRIO_05_2025!C:C,"Windows",INVENTÁRIO_05_2025!D:D,"*2019*",INVENTÁRIO_05_2025!E:E,"Fisico") -> 14
B11: Total RedHat 7 | C11: =COUNTIFS(INVENTÁRIO_05_2025!C:C,"Linux",INVENTÁRIO_05_2025!D:D,"*RedHat 7*",INVENTÁRIO_05_2025!E:E,"Virtual") -> 10 | E11: Total RedHat 7 | F11: =COUNTIFS(INVENTÁRIO_05_2025!C:C,"Linux",INVENTÁRIO_05_2025!D:D,"*RedHat 7*",INVENTÁRIO_05_2025!E:E,"Fisico") -> 1 | H11: Windows 2016 | I11: =COUNTIFS(INVENTÁRIO_05_2025!C:C,"Windows",INVENTÁRIO_05_2025!D:D,"*2016*",INVENTÁRIO_05_2025!E:E,"Virtual") -> 76 | K11: Windows 2016 | L11: =COUNTIFS(INVENTÁRIO_05_2025!C:C,"Windows",INVENTÁRIO_05_2025!D:D,"*2016*",INVENTÁRIO_05_2025!E:E,"Fisico") -> 0
B12: Total RedHat 6 | C12: =COUNTIFS(INVENTÁRIO_05_2025!C:C,"Linux",INVENTÁRIO_05_2025!D:D,"*RedHat 6*",INVENTÁRIO_05_2025!E:E,"Virtual") -> 10 | E12: Total RedHat 6 | F12: =COUNTIFS(INVENTÁRIO_05_2025!C:C,"Linux",INVENTÁRIO_05_2025!D:D,"*RedHat 6*",INVENTÁRIO_05_2025!E:E,"Fisico") -> 23 | H12: Windows 2012 | I12: =COUNTIFS(INVENTÁRIO_05_2025!C:C,"Windows",INVENTÁRIO_05_2025!D:D,"*2012*",INVENTÁRIO_05_2025!E:E,"Virtual") -> 51 | K12: Windows 2012 | L12: =COUNTIFS(INVENTÁRIO_05_2025!C:C,"Windows",INVENTÁRIO_05_2025!D:D,"*2012*",INVENTÁRIO_05_2025!E:E,"Fisico") -> 7
B13: Total RedHat 5 | C13: =COUNTIFS(INVENTÁRIO_05_2025!C:C,"Linux",INVENTÁRIO_05_2025!D:D,"*RedHat 5*",INVENTÁRIO_05_2025!E:E,"Virtual") -> 0 | E13: Total RedHat 5 | F13: =COUNTIFS(INVENTÁRIO_05_2025!C:C,"Linux",INVENTÁRIO_05_2025!D:D,"*RedHat 5*",INVENTÁRIO_05_2025!E:E,"Fisico") -> 1 | H13: Windows 2008 | I13: =COUNTIFS(INVENTÁRIO_05_2025!C:C,"Windows",INVENTÁRIO_05_2025!D:D,"*2008*",INVENTÁRIO_05_2025!E:E,"Virtual") -> 69 | K13: Windows 2008 | L13: =COUNTIFS(INVENTÁRIO_05_2025!C:C,"Windows",INVENTÁRIO_05_2025!D:D,"*2008*",INVENTÁRIO_05_2025!E:E,"Fisico") -> 6
B14: Total Ubuntu | C14: =COUNTIFS(INVENTÁRIO_05_2025!C:C,"Linux",INVENTÁRIO_05_2025!D:D,"*Ubuntu*",INVENTÁRIO_05_2025!E:E,"Virtual") -> 30 | E14: Total Ubuntu | F14: =COUNTIFS(INVENTÁRIO_05_2025!C:C,"Linux",INVENTÁRIO_05_2025!D:D,"*Ubuntu*",INVENTÁRIO_05_2025!E:E,"Fisico") -> 1 | H14: Windows 10 | I14: =COUNTIFS(INVENTÁRIO_05_2025!C:C,"Windows",INVENTÁRIO_05_2025!D:D,"*10*",INVENTÁRIO_05_2025!E:E,"Virtual") -> 3 | K14: Windows 10 | L14: =COUNTIFS(INVENTÁRIO_05_2025!C:C,"Windows",INVENTÁRIO_05_2025!D:D,"*10*",INVENTÁRIO_05_2025!E:E,"Fisico") -> 0
B15: Total Centos | C15: =COUNTIFS(INVENTÁRIO_05_2025!C:C,"Linux",INVENTÁRIO_05_2025!D:D,"*Centos*",INVENTÁRIO_05_2025!E:E,"Virtual") -> 6 | E15: Total Centos | F15: =COUNTIFS(INVENTÁRIO_05_2025!C:C,"Linux",INVENTÁRIO_05_2025!D:D,"*Centos*",INVENTÁRIO_05_2025!E:E,"Fisico") -> 0 | H15: Windows 8 | I15: =COUNTIFS(INVENTÁRIO_05_2025!C:C,"Windows",INVENTÁRIO_05_2025!D:D,"*Windows 8*",INVENTÁRIO_05_2025!E:E,"Virtual") -> 1 | K15: Windows 8 | L15: =COUNTIFS(INVENTÁRIO_05_2025!C:C,"Windows",INVENTÁRIO_05_2025!D:D,"*Windows 8*",INVENTÁRIO_05_2025!E:E,"Fisico") -> 0
B16: Total Debian | C16: =COUNTIFS(INVENTÁRIO_05_2025!C:C,"Linux",INVENTÁRIO_05_2025!D:D,"*Debian*",INVENTÁRIO_05_2025!E:E,"Virtual") -> 6 | E16: Total Debian | F16: =COUNTIFS(INVENTÁRIO_05_2025!C:C,"Linux",INVENTÁRIO_05_2025!D:D,"*Debian*",INVENTÁRIO_05_2025!E:E,"Fisico") -> 0 | H16: Windows 7 | I16: =COUNTIFS(INVENTÁRIO_05_2025!C:C,"Windows",INVENTÁRIO_05_2025!D:D,"*7*",INVENTÁRIO_05_2025!E:E,"Virtual") -> 4 | K16: Windows 7 | L16: =COUNTIFS(INVENTÁRIO_05_2025!C:C,"Windows",INVENTÁRIO_05_2025!D:D,"*7*",INVENTÁRIO_05_2025!E:E,"Fisico") -> 0
B17: Total Suse | C17: =COUNTIFS(INVENTÁRIO_05_2025!C:C,"Linux",INVENTÁRIO_05_2025!D:D,"*Suse*",INVENTÁRIO_05_2025!E:E,"Virtual") -> 9 | E17: Total Suse | F17: =COUNTIFS(INVENTÁRIO_05_2025!C:C,"Linux",INVENTÁRIO_05_2025!D:D,"*Suse*",INVENTÁRIO_05_2025!E:E,"Fisico") -> 0
B18: Total SOs | C18: =SUM(C9:C17) -> 96 | E18: Total SOs | F18: =SUM(F9:F17) -> 28
B19: Outros SOs | C19: =C5-C18 -> 10 | E19: Outros SOs | F19: =F5-F18 -> 22
B22: TOP 10 SO | E22: Servidores Criados | H22: Servidores Excluidos | K22: Totais
B23: Windows 2022 | C23: =I9+L9 -> 51 | E23: SPRDSKDCGRU01_RESTORE | H23: SPRDAPPTCAGRU01_202.. | K23: Total Servidores | L23: =L25+L24 -> 488
B24: Windows 2019 | C24: =I10+L10 -> 64 | E24: SPRDSKDCGRU02_RESTORE | H24: SSERV1-GRU_13082024 | K24: Total Linux | L24: =C5+F5 -> 156
B25: Windows 2016 | C25: =I11 -> 76 | E25: SPRDSKPPCGRU10_RESTORE | H25: SHOMAPLGGRU01_REM.. | K25: Total Windows | L25: =L5+I5 -> 332
B26: Windows 2008 | C26: =I13+L13 -> 75 | E26: SPRDAPIHSGRU01_RESTORE | H26: SPRDAPCCGRU03_202.. | K26: Total Fisicos | L26: =F5+L5 -> 99
B27: Windows 2012 | C27: =I12+L12 -> 58 | E27: SHOMAPPOSTGRU01 | H27: SPRDAPCONVGRU02 | K27: Total Virtuais | L27: =C5+I5 -> 389
B28: RedHat | C28: =C9+C10+C11+C12+C13+F9+F10+F11+F12+F13 -> 72 | E28: SHOMAPCUPSGRU01_RESTORE | H28: SPRDAPSFTPGRU01 | K28: Total Ligadas | L28: =C7+F7+I7+L7 -> 429
B29: Ubuntu | C29: =C14+F14 -> 31 | E29: SPRDAPVPRGRU07 | H29: SPRDSQLGRU23 | K29: Total Desligadas | L29: =C6+F6+I6+L6 -> 59
B30: Centos | C30: =C15+F15 -> 6 | E30: SPRDSQLGRU23_REMOV... | H30: SPRDSQLGRU24 | K30: Total Criados | L30: 14
B31: Suse | C31: =C17+F17 -> 9 | E31: SPRDSQLGRU24_REMOV... | H31: SHOMAPLGGRU03_REM.. | K31: Total Excluidos | L31: 13
B32: Outros (Win7,8,Appliance,Debian) | C32: =C19+F19+I14+I15+I16+C16+F16 -> 46 | E32: SHOMADGRU001 | H32: SPRDAPZABGRU02_RESTORE
E33: SHOMADGRU002 | H33: SPRDSQLCBEGRU01_REMO..
E34: SHOMADGRU003 | H34: SPRDBDHSQLGRU14_CLONE
E35: SPRDAPSGPAGRU01 | H35: SSERV1-GRU_2024...
E36: SPRDBDHSQLGRU15

Sheet INVENTÁRIO_05_2025
A1: Servidor | B1: Status | C1: Tipo SO | D1: Versão SO no AD | E1: Fisico/Virtual | F1: Local | G1: Comparação mês Anterior | H1: Comparação mês posterior
A2: SPRDAPCSCOGRU02 | B2: poweredOff | C2: Linux | D2: CentOS 4/5 or later (32-bit) | E2: Virtual | F2: TPS2 | G2: =VLOOKUP(A:A,INVENTÁRIO_04_2025!A:A,1,0) -> SPRDAPCSCOGRU02 | H2: =VLOOKUP(A:A,INVENTÁRIO_06_2025!A:A,1,0) -> #N/A
A3: GRU-VMSLOT-AMS | B3: poweredOn | C3: Windows | D3: Microsoft Windows 7 (64-bit) | E3: Virtual | F3: TPS2 | G3: =VLOOKUP(A:A,INVENTÁRIO_04_2025!A:A,1,0) -> GRU-VMSLOT-AMS | H3: =VLOOKUP(A:A,INVENTÁRIO_06_2025!A:A,1,0) -> #N/A
A4: GRU-CCURE-01 | B4: poweredOff | C4: Windows | D4: Microsoft Windows 8 (64-bit) | E4: Virtual | F4: TPS2 | G4: =VLOOKUP(A:A,INVENTÁRIO_04_2025!A:A,1,0) -> GRU-CCURE-01 | H4: =VLOOKUP(A:A,INVENTÁRIO_06_2025!A:A,1,0) -> #N/A
A5: SPRDCCTVGRU19.gru.local | B5: poweredOff | C5: Windows | D5: Microsoft Windows Server 2008 R2 (64-bit) | E5: Virtual | F5: TPS2 | G5: =VLOOKUP(A:A,INVENTÁRIO_04_2025!A:A,1,0) -> SPRDCCTVGRU19.gru.local | H5: =VLOOKUP(A:A,INVENTÁRIO_06_2025!A:A,1,0) -> #N/A
A6: SPRDCCTVGRU22 | B6: poweredOff | C6: Windows | D6: Microsoft Windows Server 2008 R2 (64-bit) | E6: Virtual | F6: TPS2 | G6: =VLOOKUP(A:A,INVENTÁRIO_04_2025!A:A,1,0) -> SPRDCCTVGRU22 | H6: =VLOOKUP(A:A,INVENTÁRIO_06_2025!A:A,1,0) -> #N/A
A7: SPRDCCTVGRU23 | B7: poweredOff | C7: Windows | D7: Microsoft Windows Server 2008 R2 (64-bit) | E7: Virtual | F7: TPS2 | G7: =VLOOKUP(A:A,INVENTÁRIO_04_2025!A:A,1,0) -> SPRDCCTVGRU23 | H7: =VLOOKUP(A:A,INVENTÁRIO_06_2025!A:A,1,0) -> #N/A
A8: SPRDAPCSCOGRU01 | B8: poweredOff | C8: Linux | D8: Other 2.6.x Linux (32-bit) | E8: Virtual | F8: TPS2 | G8: =VLOOKUP(A:A,INVENTÁRIO_04_2025!A:A,1,0) -> SPRDAPCSCOGRU01 | H8: =VLOOKUP(A:A,INVENTÁRIO_06_2025!A:A,1,0) -> #N/A
A9: CLONE_SQASAPECCGRU01 | B9: poweredOff | C9: Linux | D9: RedHat 6 | E9: Virtual | F9: TPS2 | G9: =VLOOKUP(A:A,INVENTÁRIO_04_2025!A:A,1,0) -> CLONE_SQASAPECCGRU01 | H9: =VLOOKUP(A:A,INVENTÁRIO_06_2025!A:A,1,0) -> #N/A
A10: SATI-PF | B10: poweredOn | C10: Linux | D10: RedHat 6 | E10: Virtual | F10: TPS2 | G10: =VLOOKUP(A:A,INVENTÁRIO_04_2025!A:A,1,0) -> SATI-PF | H10: =VLOOKUP(A:A,INVENTÁRIO_06_2025!A:A,1,0) -> #N/A
A11: SDESAPNWGRU01 | B11: poweredOn | C11: Linux | D11: RedHat 6 | E11: Virtual | F11: TPS2 | G11: =VLOOKUP(A:A,INVENTÁRIO_04_2025!A:A,1,0) -> SDESAPNWGRU01 | H11: =VLOOKUP(A:A,INVENTÁRIO_06_2025!A:A,1,0) -> #N/A
A12: SPRDAPZABGRU02_2025060345004466_REMOVER_11_06 | B12: poweredOff | C12: Linux | D12: RedHat 7 | E12: Virtual | F12: TPS2 | G12: =VLOOKUP(A:A,INVENTÁRIO_04_2025!A:A,1,0) -> #N/A | H12: =VLOOKUP(A:A,INVENTÁRIO_06_2025!A:A,1,0) -> #N/A
A13: SPRDBDZABGRU02_2025060345004466_REMOVER_11_06 | B13: poweredOn | C13: Linux | D13: RedHat 7 | E13: Virtual | F13: TPS2 | G13: =VLOOKUP(A:A,INVENTÁRIO_04_2025!A:A,1,0) -> #N/A | H13: =VLOOKUP(A:A,INVENTÁRIO_06_2025!A:A,1,0) -> #N/A
... A489: CCTVGRU20 | B489: poweredOn | C489: Windows | D489: Windows Server 2008 R2 Enterprise | E489: Virtual | F489: HCI | G489: =VLOOKUP(A:A,INVENTÁRIO_04_2025!A:A,1,0) -> CCTVGRU20 | H489: =VLOOKUP(A:A,INVENTÁRIO_06_2025!A:A,1,0) -> CCTVGRU20

Sheet DASHBOARD_06_2025
B2: Inventário Servidores Junho 2025
B4: Linux Virtual | E4: Linux Fisicos | H4: Windows Virtual | K4: Windows Fisicos
B5: Total Virtuais | C5: =COUNTIFS(INVENTÁRIO_06_2025!C:C,"Linux",INVENTÁRIO_06_2025!E:E,"Virtual") -> 97 | E5: Total Fisicos | F5: =COUNTIFS(INVENTÁRIO_06_2025!C:C,"Linux",INVENTÁRIO_06_2025!E:E,"Fisico") -> 50 | H5: Total Virtuais | I5: =COUNTIFS(INVENTÁRIO_06_2025!C:C,"Windows",INVENTÁRIO_06_2025!E:E,"Virtual") -> 268 | K5: Total Fisicos | L5: =COUNTIFS(INVENTÁRIO_06_2025!C:C,"Windows",INVENTÁRIO_06_2025!E:E,"Fisico") -> 49
B6: Desligadas | C6: =COUNTIFS(INVENTÁRIO_06_2025!B:B,"poweredOff",INVENTÁRIO_06_2025!C:C,"Linux",INVENTÁRIO_06_2025!E:E,"Virtual") -> 4 | E6: Desligadas | F6: =COUNTIFS(INVENTÁRIO_06_2025!B:B,"poweredOff",INVENTÁRIO_06_2025!C:C,"Linux",INVENTÁRIO_06_2025!E:E,"Fisico") -> 5 | H6: Desligadas | I6: =COUNTIFS(INVENTÁRIO_06_2025!B:B,"poweredOff",INVENTÁRIO_06_2025!C:C,"Windows",INVENTÁRIO_06_2025!E:E,"Virtual") -> 14 | K6: Desligadas | L6: =COUNTIFS(INVENTÁRIO_06_2025!B:B,"poweredOff",INVENTÁRIO_06_2025!C:C,"Windows",INVENTÁRIO_06_2025!E:E,"Fisico") -> 28
B7: Ligadas | C7: =COUNTIFS(INVENTÁRIO_06_2025!B:B,"poweredOn",INVENTÁRIO_06_2025!C:C,"Linux",INVENTÁRIO_06_2025!E:E,"Virtual") -> 93 | E7: Ligadas | F7: =COUNTIFS(INVENTÁRIO_06_2025!B:B,"poweredOn",INVENTÁRIO_06_2025!C:C,"Linux",INVENTÁRIO_06_2025!E:E,"Fisico") -> 45 | H7: Ligadas | I7: =COUNTIFS(INVENTÁRIO_06_2025!B:B,"poweredOn",INVENTÁRIO_06_2025!C:C,"Windows",INVENTÁRIO_06_2025!E:E,"Virtual") -> 254 | K7: Ligadas | L7: =COUNTIFS(INVENTÁRIO_06_2025!B:B,"poweredOn",INVENTÁRIO_06_2025!C:C,"Windows",INVENTÁRIO_06_2025!E:E,"Fisico") -> 21
B9: Total RedHat 9 | C9: =COUNTIFS(INVENTÁRIO_06_2025!C:C,"Linux",INVENTÁRIO_06_2025!D:D,"*RedHat 9*",INVENTÁRIO_06_2025!E:E,"Virtual") -> 14 | E9: Total RedHat 9 | F9: =COUNTIFS(INVENTÁRIO_06_2025!C:C,"Linux",INVENTÁRIO_06_2025!D:D,"*RedHat 9*",INVENTÁRIO_06_2025!E:E,"Fisico") -> 0 | H9: Windows 2022 | I9: =COUNTIFS(INVENTÁRIO_06_2025!C:C,"Windows",INVENTÁRIO_06_2025!D:D,"*2022*",INVENTÁRIO_06_2025!E:E,"Virtual") -> 28 | K9: Windows 2022 | L9: =COUNTIFS(INVENTÁRIO_06_2025!C:C,"Windows",INVENTÁRIO_06_2025!D:D,"*2022*",INVENTÁRIO_06_2025!E:E,"Fisico") -> 22
B10: Total RedHat 8 | C10: =COUNTIFS(INVENTÁRIO_06_2025!C:C,"Linux",INVENTÁRIO_06_2025!D:D,"*RedHat 8*",INVENTÁRIO_06_2025!E:E,"Virtual") -> 9 | E10: Total RedHat 8 | F10: =COUNTIFS(INVENTÁRIO_06_2025!C:C,"Linux",INVENTÁRIO_06_2025!D:D,"*RedHat 8*",INVENTÁRIO_06_2025!E:E,"Fisico") -> 2 | H10: Windows 2019 | I10: =COUNTIFS(INVENTÁRIO_06_2025!C:C,"Windows",INVENTÁRIO_06_2025!D:D,"*2019*",INVENTÁRIO_06_2025!E:E,"Virtual") -> 48 | K10: Windows 2019 | L10: =COUNTIFS(INVENTÁRIO_06_2025!C:C,"Windows",INVENTÁRIO_06_2025!D:D,"*2019*",INVENTÁRIO_06_2025!E:E,"Fisico") -> 14
B11: Total RedHat 7 | C11: =COUNTIFS(INVENTÁRIO_06_2025!C:C,"Linux",INVENTÁRIO_06_2025!D:D,"*RedHat 7*",INVENTÁRIO_06_2025!E:E,"Virtual") -> 7 | E11: Total RedHat 7 | F11: =COUNTIFS(INVENTÁRIO_06_2025!C:C,"Linux",INVENTÁRIO_06_2025!D:D,"*RedHat 7*",INVENTÁRIO_06_2025!E:E,"Fisico") -> 1 | H11: Windows 2016 | I11: =COUNTIFS(INVENTÁRIO_06_2025!C:C,"Windows",INVENTÁRIO_06_2025!D:D,"*2016*",INVENTÁRIO_06_2025!E:E,"Virtual") -> 76 | K11: Windows 2016 | L11: =COUNTIFS(INVENTÁRIO_06_2025!C:C,"Windows",INVENTÁRIO_06_2025!D:D,"*2016*",INVENTÁRIO_06_2025!E:E,"Fisico") -> 0
B12: Total RedHat 6 | C12: =COUNTIFS(INVENTÁRIO_06_2025!C:C,"Linux",INVENTÁRIO_06_2025!D:D,"*RedHat 6*",INVENTÁRIO_06_2025!E:E,"Virtual") -> 8 | E12: Total RedHat 6 | F12: =COUNTIFS(INVENTÁRIO_06_2025!C:C,"Linux",INVENTÁRIO_06_2025!D:D,"*RedHat 6*",INVENTÁRIO_06_2025!E:E,"Fisico") -> 23 | H12: Windows 2012 | I12: =COUNTIFS(INVENTÁRIO_06_2025!C:C,"Windows",INVENTÁRIO_06_2025!D:D,"*2012*",INVENTÁRIO_06_2025!E:E,"Virtual") -> 53 | K12: Windows 2012 | L12: =COUNTIFS(INVENTÁRIO_06_2025!C:C,"Windows",INVENTÁRIO_06_2025!D:D,"*2012*",INVENTÁRIO_06_2025!E:E,"Fisico") -> 7
B13: Total RedHat 5 | C13: =COUNTIFS(INVENTÁRIO_06_2025!C:C,"Linux",INVENTÁRIO_06_2025!D:D,"*RedHat 5*",INVENTÁRIO_06_2025!E:E,"Virtual") -> 0 | E13: Total RedHat 5 | F13: =COUNTIFS(INVENTÁRIO_06_2025!C:C,"Linux",INVENTÁRIO_06_2025!D:D,"*RedHat 5*",INVENTÁRIO_06_2025!E:E,"Fisico") -> 1 | H13: Windows 2008 | I13: =COUNTIFS(INVENTÁRIO_06_2025!C:C,"Windows",INVENTÁRIO_06_2025!D:D,"*2008*",INVENTÁRIO_06_2025!E:E,"Virtual") -> 57 | K13: Windows 2008 | L13: =COUNTIFS(INVENTÁRIO_06_2025!C:C,"Windows",INVENTÁRIO_06_2025!D:D,"*2008*",INVENTÁRIO_06_2025!E:E,"Fisico") -> 6
B14: Total Ubuntu | C14: =COUNTIFS(INVENTÁRIO_06_2025!C:C,"Linux",INVENTÁRIO_06_2025!D:D,"*Ubuntu*",INVENTÁRIO_06_2025!E:E,"Virtual") -> 28 | E14: Total Ubuntu | F14: =COUNTIFS(INVENTÁRIO_06_2025!C:C,"Linux",INVENTÁRIO_06_2025!D:D,"*Ubuntu*",INVENTÁRIO_06_2025!E:E,"Fisico") -> 1 | H14: Windows 10 | I14: =COUNTIFS(INVENTÁRIO_06_2025!C:C,"Windows",INVENTÁRIO_06_2025!D:D,"*10*",INVENTÁRIO_06_2025!E:E,"Virtual") -> 3 | K14: Windows 10 | L14: =COUNTIFS(INVENTÁRIO_06_2025!C:C,"Windows",INVENTÁRIO_06_2025!D:D,"*10*",INVENTÁRIO_06_2025!E:E,"Fisico") -> 0
B15: Total Centos | C15: =COUNTIFS(INVENTÁRIO_06_2025!C:C,"Linux",INVENTÁRIO_06_2025!D:D,"*Centos*",INVENTÁRIO_06_2025!E:E,"Virtual") -> 6 | E15: Total Centos | F15: =COUNTIFS(INVENTÁRIO_06_2025!C:C,"Linux",INVENTÁRIO_06_2025!D:D,"*Centos*",INVENTÁRIO_06_2025!E:E,"Fisico") -> 0 | H15: Windows 8 | I15: =COUNTIFS(INVENTÁRIO_06_2025!C:C,"Windows",INVENTÁRIO_06_2025!D:D,"*Windows 8*",INVENTÁRIO_06_2025!E:E,"Virtual") -> 0 | K15: Windows 8 | L15: =COUNTIFS(INVENTÁRIO_06_2025!C:C,"Windows",INVENTÁRIO_06_2025!D:D,"*Windows 8*",INVENTÁRIO_06_2025!E:E,"Fisico") -> 0
B16: Total Debian | C16: =COUNTIFS(INVENTÁRIO_06_2025!C:C,"Linux",INVENTÁRIO_06_2025!D:D,"*Debian*",INVENTÁRIO_06_2025!E:E,"Virtual") -> 6 | E16: Total Debian | F16: =COUNTIFS(INVENTÁRIO_06_2025!C:C,"Linux",INVENTÁRIO_06_2025!D:D,"*Debian*",INVENTÁRIO_06_2025!E:E,"Fisico") -> 0 | H16: Windows 7 | I16: =COUNTIFS(INVENTÁRIO_06_2025!C:C,"Windows",INVENTÁRIO_06_2025!D:D,"*7*",INVENTÁRIO_06_2025!E:E,"Virtual") -> 3 | K16: Windows 7 | L16: =COUNTIFS(INVENTÁRIO_06_2025!C:C,"Windows",INVENTÁRIO_06_2025!D:D,"*7*",INVENTÁRIO_06_2025!E:E,"Fisico") -> 0
B17: Total Suse | C17: =COUNTIFS(INVENTÁRIO_06_2025!C:C,"Linux",INVENTÁRIO_06_2025!D:D,"*Suse*",INVENTÁRIO_06_2025!E:E,"Virtual") -> 9 | E17: Total Suse | F17: =COUNTIFS(INVENTÁRIO_06_2025!C:C,"Linux",INVENTÁRIO_06_2025!D:D,"*Suse*",INVENTÁRIO_06_2025!E:E,"Fisico") -> 0
B18: Total SOs | C18: =SUM(C9:C17) -> 87 | E18: Total SOs | F18: =SUM(F9:F17) -> 28
B19: Outros SOs | C19: =C5-C18 -> 10 | E19: Outros SOs | F19: =F5-F18 -> 22
B22: TOP 10 SO | E22: Servidores Criados | H22: Servidores Excluidos | K22: Totais
B23: Windows 2022 | C23: =I9+L9 -> 50 | E23: SHOMSAPNWGRU01 | H23: CLONE_SQASAPECCGRU01 | K23: Total Servidores | L23: =L25+L24 -> 464
B24: Windows 2019 | C24: =I10+L10 -> 62 | E24: SPRDAPAGPMGRU01_2025060445004428 | F24: . | H24: GRU-CCURE-01 | I24: . | K24: Total Linux | L24: =C5+F5 -> 147
B25: Windows 2016 | C25: =I11 -> 76 | E25: SPRDAPDSMGRU01_2025060445004428 | F25: . | H25: GRU-VMSLOT-AMS | I25: . | K25: Total Windows | L25: =L5+I5 -> 317
B26: Windows 2008 | C26: =I13+L13 -> 63 | E26: SPRDAPESBGRU08_2025062545007583_VERIFICAR PARA REMOVER EM_07_07_25 | F26: . | H26: SAPL2-GRU | I26: . | K26: Total Fisicos | L26: =F5+L5 -> 99
B27: Windows 2012 | C27: =I12+L12 -> 60 | E27: SPRDAPGFNGRU02_RESTORE | F27: . | H27: SATI-PF | I27: . | K27: Total Virtuais | L27: =C5+I5 -> 365
B28: RedHat | C28: =C9+C10+C11+C12+C13+F9+F10+F11+F12+F13 -> 65 | E28: SPRDAPNLBGRU01_RESTORE | F28: . | H28: SDESAPNWGRU01 | I28: . | K28: Total Ligadas | L28: =C7+F7+I7+L7 -> 413
B29: Ubuntu | C29: =C14+F14 -> 29 | E29: SPRDAPSSP0200 | F29: . | H29: SHOMAPCUPSGRU01 | I29: . | K29: Total Desligadas | L29: =C6+F6+I6+L6 -> 51
B30: Centos | C30: =C15+F15 -> 6 | E30: SPRDSHPINTGRU04_RESTORE | F30: . | H30: SHOMINTELI1-GRU | I30: . | K30: Total Criados | L30: 10
B31: Suse | C31: =C17+F17 -> 9 | E31: SPRDSKDCGRU01_RESTORE1 | F31: . | H31: SINTELI1-GRU | I31: . | K31: Total Excluidos | L31: 34
B32: Outros (Win7,8,Appliance,Debian) | C32: =C19+F19+I14+I15+I16+C16+F16 -> 44 | E32: SPRDWSUSGRU01 | H32: SPRDAPAOGRU03 | I32: .
H33: SPRDAPAOGRU04 | I33: .
H34: SPRDAPCSCOGRU01 | I34: .
H35: SPRDAPCSCOGRU02 | I35: .
H36: SPRDAPDOCGRU01 | I36: .
H37: SPRDAPESBGRU08 | I37: .
H38: SPRDAPETESGRU01 | I38: .
H39: SPRDAPSCOGRU01 | I39: .
H40: SPRDAPSCOGRU02 | I40: .
H41: SPRDAPZABGRU02_2025060... | I41: .
H42: SPRDAPZBPXGRU01_2025060345004466_REMOVER_11_06 | I42: .
H43: SPRDAPZBPXGRU02_2025060345004466_REMOVER_11_06 | I43: .
H44: SPRDBDSNAGRU01 | I44: .
... H54: TP_UBUNTU_24 | I54: .
...

Sheet INVENTÁRIO_06_2025
A1: Servidor | B1: Status | C1: Tipo SO | D1: Versão SO no AD | E1: Fisico/Virtual | F1: Local | G1: Comparação
A2: SLOT-01 | B2: poweredOff | C2: Linux | D2: - | E2: Fisico | F2: ENCLOSURE3-JR6LBY1 | G2: =VLOOKUP(A:A,INVENTÁRIO_05_2025!A:A,1,0) -> SLOT-01
A3: SPRDAPTRGRU01 | B3: poweredOff | C3: Linux | D3: - | E3: Fisico | F3: ENCLOSURE5-GQWPZ12 | G3: =VLOOKUP(A:A,INVENTÁRIO_05_2025!A:A,1,0) -> SPRDAPTRGRU01
A4: SPRDAPBWGRU01 | B4: poweredOff | C4: Linux | D4: - | E4: Fisico | F4: ENCLOSURE5-GQWPZ12 | G4: =VLOOKUP(A:A,INVENTÁRIO_05_2025!A:A,1,0) -> SPRDAPBWGRU01
A5: SPRDAPBWGRU02 | B5: poweredOff | C5: Linux | D5: - | E5: Fisico | F5: ENCLOSURE6-DM8QZ12 | G5: =VLOOKUP(A:A,INVENTÁRIO_05_2025!A:A,1,0) -> SPRDAPBWGRU02
A6: SPRDVMGRU01 | B6: poweredOn | C6: Linux | D6: Appliance Vmware | E6: Fisico | F6: ENCLOSURE1-HY381Y1 | G6: =VLOOKUP(A:A,INVENTÁRIO_05_2025!A:A,1,0) -> SPRDVMGRU01
A7: SPRDVMGRU02 | B7: poweredOn | C7: Linux | D7: Appliance Vmware | E7: Fisico | F7: ENCLOSURE1-HY381Y1 | G7: =VLOOKUP(A:A,INVENTÁRIO_05_2025!A:A,1,0) -> SPRDVMGRU02
A8: SPRDVMGRU05 | B8: poweredOn | C8: Linux | D8: Appliance Vmware | E8: Fisico | F8: ENCLOSURE1-HY381Y1 | G8: =VLOOKUP(A:A,INVENTÁRIO_05_2025!A:A,1,0) -> SPRDVMGRU05
A9: SPRDVMGRU03 | B9: poweredOn | C9: Linux | D9: Appliance Vmware | E9: Fisico | F9: ENCLOSURE2-BY381Y1 | G9: =VLOOKUP(A:A,INVENTÁRIO_05_2025!A:A,1,0) -> SPRDVMGRU03
A10: SPRDVMGRU04 | B10: poweredOn | C10: Linux | D10: Appliance Vmware | E10: Fisico | F10: ENCLOSURE2-BY381Y1 | G10: =VLOOKUP(A:A,INVENTÁRIO_05_2025!A:A,1,0) -> SPRDVMGRU04
A11: SPRDVMGRU06 | B11: poweredOn | C11: Linux | D11: Appliance Vmware | E11: Fisico | F11: ENCLOSURE2-BY381Y1 | G11: =VLOOKUP(A:A,INVENTÁRIO_05_2025!A:A,1,0) -> SPRDVMGRU06
A12: SPRDVMSAPGRU01 | B12: poweredOn | C12: Linux | D12: Appliance Vmware | E12: Fisico | F12: ENCLOSURE5-GQWPZ12 | G12: =VLOOKUP(A:A,INVENTÁRIO_05_2025!A:A,1,0) -> SPRDVMSAPGRU01
A13: SPRDVMSAPGRU02 | B13: poweredOn | C13: Linux | D13: Appliance Vmware | E13: Fisico | F13: ENCLOSURE5-GQWPZ12 | G13: =VLOOKUP(A:A,INVENTÁRIO_05_2025!A:A,1,0) -> SPRDVMSAPGRU02
... A109: SPRDAPIHSGRU01_RESTORE | B109: poweredOff | C109: Linux | D109: RedHat 7 | E109: Virtual | F109: HCI | G109: =VLOOKUP(A:A,INVENTÁRIO_05_2025!A:A,1,0) -> SPRDAPIHSGRU01_RESTORE
A110: SPRDAPJPGRUXX | B110: poweredOff | C110: Windows | D110: Microsoft Windows Server 2016 or later (64-bit) | E110: Virtual | F110: HCI
A111: SPRDAPNLBGRU01_RESTORE | B111: poweredOff | C111: Linux | D111: Oracle Solaris 10 (64-bit) | E111: Virtual | F111: HCI | G111: =VLOOKUP(A:A,INVENTÁRIO_05_2025!A:A,1,0) -> #N/A
A112: SPRDSHPINTGRU04_RESTORE | B112: poweredOff | C112: Windows | D112: Windows Server 2012 R2 Datacenter | E112: Virtual | F112: HCI | G112: =VLOOKUP(A:A,INVENTÁRIO_05_2025!A:A,1,0) -> #N/A
A113: SPRDSKDCGRU01_RESTORE | B113: poweredOff | C113: Windows | D113: Microsoft Windows Server 2016 (64-bit) | E113: Virtual | F113: HCI | G113: =VLOOKUP(A:A,INVENTÁRIO_05_2025!A:A,1,0) -> SPRDSKDCGRU01_RESTORE
A114: SPRDSKDCGRU01_RESTORE1 | B114: poweredOff | C114: Windows | D114: Microsoft Windows Server 2016 (64-bit) | E114: Virtual | F114: HCI | G114: =VLOOKUP(A:A,INVENTÁRIO_05_2025!A:A,1,0) -> #N/A
A115: SPRDSKDCGRU02_RESTORE | B115: poweredOff | C115: Windows | D115: Microsoft Windows Server 2016 (64-bit) | E115: Virtual | F115: HCI | G115: =VLOOKUP(A:A,INVENTÁRIO_05_2025!A:A,1,0) -> SPRDSKDCGRU02_RESTORE
A116: SPRDSKPPCGRU10_RESTORE | B116: poweredOff | C116: Windows | D116: Microsoft Windows Server 2016 (64-bit) | E116: Virtual | F116: HCI | G116: =VLOOKUP(A:A,INVENTÁRIO_05_2025!A:A,1,0) -> SPRDSKPPCGRU10_RESTORE
A117: SPRDVCSQLGRU06 | B117: poweredOff | C117: Windows | D117: Microsoft Windows Server 2019 (64-bit) | E117: Virtual | F117: HCI | G117: =VLOOKUP(A:A,INVENTÁRIO_05_2025!A:A,1,0) -> SPRDVCSQLGRU06
A118: SPRDVCWEBGRU02 | B118: poweredOff | C118: Windows | D118: Windows Server 2019 Datacenter | E118: Virtual | F118: HCI | G118: =VLOOKUP(A:A,INVENTÁRIO_05_2025!A:A,1,0) -> SPRDVCWEBGRU02
A119: SDESAPMNTGRU01 | B119: poweredOn | C119: Windows | D119: Windows Server 2008 R2 Enterprise | E119: Virtual | F119: TPS2 | G119: =VLOOKUP(A:A,INVENTÁRIO_05_2025!A:A,1,0) -> SDESAPMNTGRU01
A120: SDEVAPECGRU01 | B120: poweredOn | C120: Linux | D120: RedHat 6 | E120: Virtual | F120: TPS2 | G120: =VLOOKUP(A:A,INVENTÁRIO_05_2025!A:A,1,0) -> SDEVAPECGRU01
A121: SDQBDORAGRU01 | B121: poweredOn | C121: Linux | D121: RedHat 6 | E121: Virtual | F121: TPS2 | G121: =VLOOKUP(A:A,INVENTÁRIO_05_2025!A:A,1,0) -> SDQBDORAGRU01
A122: SDQBDORAGRU02 | B122: poweredOn | C122: Linux | D122: RedHat 6 | E122: Virtual | F122: TPS2 | G122: =VLOOKUP(A:A,INVENTÁRIO_05_2025!A:A,1,0) -> SDQBDORAGRU02
... A465: SSERV1-GRU | B465: poweredOn | C465: Windows | D465: Windows Server 2008 R2 Standard | E465: Virtual | F465: HCI | G465: =VLOOKUP(A:A,INVENTÁRIO_05_2025!A:A,1,0) -> SSERV1-GRU

Sheet DASHBOARD_07_2025
B2: Inventário Servidores Julho 2025
B4: Linux Virtual | E4: Linux Fisicos | H4: Windows Virtual | K4: Windows Fisicos
B5: Total Virtuais | C5: =COUNTIFS(INVENTÁRIO_07_2025!C:C,"Linux",INVENTÁRIO_07_2025!E:E,"Virtual") -> 97 | E5: Total Fisicos | F5: =COUNTIFS(INVENTÁRIO_07_2025!C:C,"Linux",INVENTÁRIO_07_2025!E:E,"Fisico") -> 50 | H5: Total Virtuais | I5: =COUNTIFS(INVENTÁRIO_07_2025!C:C,"Windows",INVENTÁRIO_07_2025!E:E,"Virtual") -> 251 | K5: Total Fisicos | L5: =COUNTIFS(INVENTÁRIO_07_2025!C:C,"Windows",INVENTÁRIO_07_2025!E:E,"Fisico") -> 49
B6: Desligadas | C6: =COUNTIFS(INVENTÁRIO_07_2025!B:B,"poweredOff",INVENTÁRIO_07_2025!C:C,"Linux",INVENTÁRIO_07_2025!E:E,"Virtual") -> 0 | E6: Desligadas | F6: =COUNTIFS(INVENTÁRIO_07_2025!B:B,"poweredOff",INVENTÁRIO_07_2025!C:C,"Linux",INVENTÁRIO_07_2025!E:E,"Fisico") -> 5 | H6: Desligadas | I6: =COUNTIFS(INVENTÁRIO_07_2025!B:B,"poweredOff",INVENTÁRIO_07_2025!C:C,"Windows",INVENTÁRIO_07_2025!E:E,"Virtual") -> 9 | K6: Desligadas | L6: =COUNTIFS(INVENTÁRIO_07_2025!B:B,"poweredOff",INVENTÁRIO_07_2025!C:C,"Windows",INVENTÁRIO_07_2025!E:E,"Fisico") -> 28
B7: Ligadas | C7: =COUNTIFS(INVENTÁRIO_07_2025!B:B,"poweredOn",INVENTÁRIO_07_2025!C:C,"Linux",INVENTÁRIO_07_2025!E:E,"Virtual") -> 97 | E7: Ligadas | F7: =COUNTIFS(INVENTÁRIO_07_2025!B:B,"poweredOn",INVENTÁRIO_07_2025!C:C,"Linux",INVENTÁRIO_07_2025!E:E,"Fisico") -> 45 | H7: Ligadas | I7: =COUNTIFS(INVENTÁRIO_07_2025!B:B,"poweredOn",INVENTÁRIO_07_2025!C:C,"Windows",INVENTÁRIO_07_2025!E:E,"Virtual") -> 242 | K7: Ligadas | L7: =COUNTIFS(INVENTÁRIO_07_2025!B:B,"poweredOn",INVENTÁRIO_07_2025!C:C,"Windows",INVENTÁRIO_07_2025!E:E,"Fisico") -> 21
B9: Total RedHat 9 | C9: =COUNTIFS(INVENTÁRIO_07_2025!C:C,"Linux",INVENTÁRIO_07_2025!D:D,"*RedHat 9*",INVENTÁRIO_07_2025!E:E,"Virtual") -> 17 | E9: Total RedHat 9 | F9: =COUNTIFS(INVENTÁRIO_07_2025!C:C,"Linux",INVENTÁRIO_07_2025!D:D,"*RedHat 9*",INVENTÁRIO_07_2025!E:E,"Fisico") -> 0 | H9: Windows 2022 | I9: =COUNTIFS(INVENTÁRIO_07_2025!C:C,"Windows",INVENTÁRIO_07_2025!D:D,"*2022*",INVENTÁRIO_07_2025!E:E,"Virtual") -> 29 | K9: Windows 2022 | L9: =COUNTIFS(INVENTÁRIO_07_2025!C:C,"Windows",INVENTÁRIO_07_2025!D:D,"*2022*",INVENTÁRIO_07_2025!E:E,"Fisico") -> 22
B10: Total RedHat 8 | C10: =COUNTIFS(INVENTÁRIO_07_2025!C:C,"Linux",INVENTÁRIO_07_2025!D:D,"*RedHat 8*",INVENTÁRIO_07_2025!E:E,"Virtual") -> 9 | E10: Total RedHat 8 | F10: =COUNTIFS(INVENTÁRIO_07_2025!C:C,"Linux",INVENTÁRIO_07_2025!D:D,"*RedHat 8*",INVENTÁRIO_07_2025!E:E,"Fisico") -> 2 | H10: Windows 2019 | I10: =COUNTIFS(INVENTÁRIO_07_2025!C:C,"Windows",INVENTÁRIO_07_2025!D:D,"*2019*",INVENTÁRIO_07_2025!E:E,"Virtual") -> 46 | K10: Windows 2019 | L10: =COUNTIFS(INVENTÁRIO_07_2025!C:C,"Windows",INVENTÁRIO_07_2025!D:D,"*2019*",INVENTÁRIO_07_2025!E:E,"Fisico") -> 14
B11: Total RedHat 7 | C11: =COUNTIFS(INVENTÁRIO_07_2025!C:C,"Linux",INVENTÁRIO_07_2025!D:D,"*RedHat 7*",INVENTÁRIO_07_2025!E:E,"Virtual") -> 6 | E11: Total RedHat 7 | F11: =COUNTIFS(INVENTÁRIO_07_2025!C:C,"Linux",INVENTÁRIO_07_2025!D:D,"*RedHat 7*",INVENTÁRIO_07_2025!E:E,"Fisico") -> 1 | H11: Windows 2016 | I11: =COUNTIFS(INVENTÁRIO_07_2025!C:C,"Windows",INVENTÁRIO_07_2025!D:D,"*2016*",INVENTÁRIO_07_2025!E:E,"Virtual") -> 69 | K11: Windows 2016 | L11: =COUNTIFS(INVENTÁRIO_07_2025!C:C,"Windows",INVENTÁRIO_07_2025!D:D,"*2016*",INVENTÁRIO_07_2025!E:E,"Fisico") -> 0
B12: Total RedHat 6 | C12: =COUNTIFS(INVENTÁRIO_07_2025!C:C,"Linux",INVENTÁRIO_07_2025!D:D,"*RedHat 6*",INVENTÁRIO_07_2025!E:E,"Virtual") -> 9 | E12: Total RedHat 6 | F12: =COUNTIFS(INVENTÁRIO_07_2025!C:C,"Linux",INVENTÁRIO_07_2025!D:D,"*RedHat 6*",INVENTÁRIO_07_2025!E:E,"Fisico") -> 23 | H12: Windows 2012 | I12: =COUNTIFS(INVENTÁRIO_07_2025!C:C,"Windows",INVENTÁRIO_07_2025!D:D,"*2012*",INVENTÁRIO_07_2025!E:E,"Virtual") -> 49 | K12: Windows 2012 | L12: =COUNTIFS(INVENTÁRIO_07_2025!C:C,"Windows",INVENTÁRIO_07_2025!D:D,"*2012*",INVENTÁRIO_07_2025!E:E,"Fisico") -> 7
B13: Total RedHat 5 | C13: =COUNTIFS(INVENTÁRIO_07_2025!C:C,"Linux",INVENTÁRIO_07_2025!D:D,"*RedHat 5*",INVENTÁRIO_07_2025!E:E,"Virtual") -> 0 | E13: Total RedHat 5 | F13: =COUNTIFS(INVENTÁRIO_07_2025!C:C,"Linux",INVENTÁRIO_07_2025!D:D,"*RedHat 5*",INVENTÁRIO_07_2025!E:E,"Fisico") -> 1 | H13: Windows 2008 | I13: =COUNTIFS(INVENTÁRIO_07_2025!C:C,"Windows",INVENTÁRIO_07_2025!D:D,"*2008*",INVENTÁRIO_07_2025!E:E,"Virtual") -> 54 | K13: Windows 2008 | L13: =COUNTIFS(INVENTÁRIO_07_2025!C:C,"Windows",INVENTÁRIO_07_2025!D:D,"*2008*",INVENTÁRIO_07_2025!E:E,"Fisico") -> 6
B14: Total Ubuntu | C14: =COUNTIFS(INVENTÁRIO_07_2025!C:C,"Linux",INVENTÁRIO_07_2025!D:D,"*Ubuntu*",INVENTÁRIO_07_2025!E:E,"Virtual") -> 28 | E14: Total Ubuntu | F14: =COUNTIFS(INVENTÁRIO_07_2025!C:C,"Linux",INVENTÁRIO_07_2025!D:D,"*Ubuntu*",INVENTÁRIO_07_2025!E:E,"Fisico") -> 1 | H14: Windows 10 | I14: =COUNTIFS(INVENTÁRIO_07_2025!C:C,"Windows",INVENTÁRIO_07_2025!D:D,"*10*",INVENTÁRIO_07_2025!E:E,"Virtual") -> 2 | K14: Windows 10 | L14: =COUNTIFS(INVENTÁRIO_07_2025!C:C,"Windows",INVENTÁRIO_07_2025!D:D,"*10*",INVENTÁRIO_07_2025!E:E,"Fisico") -> 0
B15: Total Centos | C15: =COUNTIFS(INVENTÁRIO_07_2025!C:C,"Linux",INVENTÁRIO_07_2025!D:D,"*Centos*",INVENTÁRIO_07_2025!E:E,"Virtual") -> 4 | E15: Total Centos | F15: =COUNTIFS(INVENTÁRIO_07_2025!C:C,"Linux",INVENTÁRIO_07_2025!D:D,"*Centos*",INVENTÁRIO_07_2025!E:E,"Fisico") -> 0 | H15: Windows 8 | I15: =COUNTIFS(INVENTÁRIO_07_2025!C:C,"Windows",INVENTÁRIO_07_2025!D:D,"*Windows 8*",INVENTÁRIO_07_2025!E:E,"Virtual") -> 0 | K15: Windows 8 | L15: =COUNTIFS(INVENTÁRIO_07_2025!C:C,"Windows",INVENTÁRIO_07_2025!D:D,"*Windows 8*",INVENTÁRIO_07_2025!E:E,"Fisico") -> 0
B16: Total Debian | C16: =COUNTIFS(INVENTÁRIO_07_2025!C:C,"Linux",INVENTÁRIO_07_2025!D:D,"*Debian*",INVENTÁRIO_07_2025!E:E,"Virtual") -> 6 | E16: Total Debian | F16: =COUNTIFS(INVENTÁRIO_07_2025!C:C,"Linux",INVENTÁRIO_07_2025!D:D,"*Debian*",INVENTÁRIO_07_2025!E:E,"Fisico") -> 0 | H16: Windows 7 | I16: =COUNTIFS(INVENTÁRIO_07_2025!C:C,"Windows",INVENTÁRIO_07_2025!D:D,"*7*",INVENTÁRIO_07_2025!E:E,"Virtual") -> 2 | K16: Windows 7 | L16: =COUNTIFS(INVENTÁRIO_07_2025!C:C,"Windows",INVENTÁRIO_07_2025!D:D,"*7*",INVENTÁRIO_07_2025!E:E,"Fisico") -> 0
