Workbook

Sheet SOC CHeck
A1: Servidores de Produção | B1: Qualys | C1: Sentinel | D1: Elastic | E1: Observação
A2: SPRDAPIHSGRU01 | B2: =VLOOKUP(A:A,Qualys!A:A,1,0) -> SPRDAPIHSGRU01 | C2: =VLOOKUP(A:A,Sentinel!A:A,1,0) -> SPRDAPIHSGRU01 | D2: =VLOOKUP(A:A,Elastic!A:A,1,0) -> SPRDAPIHSGRU01 | E2: ok
A3: SPRDAPIHSGRU02 | B3: =VLOOKUP(A:A,Qualys!A:A,1,0) -> SPRDAPIHSGRU02 | C3: =VLOOKUP(A:A,Sentinel!A:A,1,0) -> SPRDAPIHSGRU02 | D3: =VLOOKUP(A:A,Elastic!A:A,1,0) -> SPRDAPIHSGRU02 | E3: ok
A4: SPRDAPBIGRU01 | B4: =VLOOKUP(A:A,Qualys!A:A,1,0) -> SPRDAPBIGRU01 | C4: =VLOOKUP(A:A,Sentinel!A:A,1,0) -> SPRDAPBIGRU01 | D4: =VLOOKUP(A:A,Elastic!A:A,1,0) -> #N/A | E4: RedHat 6 Não Suporta Elastic
A5: SPRDAPBIGRU02 | B5: =VLOOKUP(A:A,Qualys!A:A,1,0) -> SPRDAPBIGRU02 | C5: =VLOOKUP(A:A,Sentinel!A:A,1,0) -> SPRDAPBIGRU02 | D5: =VLOOKUP(A:A,Elastic!A:A,1,0) -> #N/A | E5: RedHat 6 Não Suporta Elastic
A6: SPRDAPLOGSGRU01 | B6: =VLOOKUP(A:A,Qualys!A:A,1,0) -> SPRDAPLOGSGRU01 | C6: =VLOOKUP(A:A,Sentinel!A:A,1,0) -> SPRDAPLOGSGRU01 | D6: =VLOOKUP(A:A,Elastic!A:A,1,0) -> SPRDAPLOGSGRU01 | E6: ok
A7: SPRDAPSSP0200 | B7: =VLOOKUP(A:A,Qualys!A:A,1,0) -> #N/A | C7: =VLOOKUP(A:A,Sentinel!A:A,1,0) -> #N/A | D7: =VLOOKUP(A:A,Elastic!A:A,1,0) -> #N/A | E7: Sem Acesso, Policia Federal
A8: SPRDAPCMSGRU02 | B8: =VLOOKUP(A:A,Qualys!A:A,1,0) -> SPRDAPCMSGRU02 | C8: =VLOOKUP(A:A,Sentinel!A:A,1,0) -> SPRDAPCMSGRU02 | D8: =VLOOKUP(A:A,Elastic!A:A,1,0) -> #N/A | E8: RedHat 6 Não Suporta Elastic
A9: SPRDAPCMSGRU04 | B9: =VLOOKUP(A:A,Qualys!A:A,1,0) -> SPRDAPCMSGRU04 | C9: =VLOOKUP(A:A,Sentinel!A:A,1,0) -> SPRDAPCMSGRU04 | D9: =VLOOKUP(A:A,Elastic!A:A,1,0) -> #N/A | E9: RedHat 6 Não Suporta Elastic
A10: SPRDAPCMSGRU05 | B10: =VLOOKUP(A:A,Qualys!A:A,1,0) -> SPRDAPCMSGRU05 | C10: =VLOOKUP(A:A,Sentinel!A:A,1,0) -> SPRDAPCMSGRU05 | D10: =VLOOKUP(A:A,Elastic!A:A,1,0) -> #N/A | E10: RedHat 6 Não Suporta Elastic
A11: SPRDBDORAGRU12 | B11: =VLOOKUP(A:A,Qualys!A:A,1,0) -> SPRDBDORAGRU12 | C11: =VLOOKUP(A:A,Sentinel!A:A,1,0) -> SPRDBDORAGRU12 | D11: =VLOOKUP(A:A,Elastic!A:A,1,0) -> SPRDBDORAGRU12 | E11: ok
A12: SPRDAPCMSGRU07 | B12: =VLOOKUP(A:A,Qualys!A:A,1,0) -> SPRDAPCMSGRU07 | C12: =VLOOKUP(A:A,Sentinel!A:A,1,0) -> SPRDAPCMSGRU07 | D12: =VLOOKUP(A:A,Elastic!A:A,1,0) -> SPRDAPCMSGRU07 | E12: ok
A13: PRDRMADS02 | B13: =VLOOKUP(A:A,Qualys!A:A,1,0) -> PRDRMADS02 | C13: =VLOOKUP(A:A,Sentinel!A:A,1,0) -> PRDRMADS02 | D13: =VLOOKUP(A:A,Elastic!A:A,1,0) -> PRDRMADS02 | E13: ok
... A36: SPRDAPIHSGRU03 | B36: =VLOOKUP(A:A,Qualys!A:A,1,0) -> SPRDAPIHSGRU03 | C36: =VLOOKUP(A:A,Sentinel!A:A,1,0) -> SPRDAPIHSGRU03 | D36: =VLOOKUP(A:A,Elastic!A:A,1,0) -> SPRDAPIHSGRU03 | E36: ok
A37: SPRDAPIPAMGRU01 | B37: SPRDAPIPAMGRU01 | C37: SPRDAPIPAMGRU01 | D37: =VLOOKUP(A:A,Elastic!A:A,1,0) -> SPRDAPIPAMGRU01 | E37: Hostname alterado
A38: SPRDAPITSMGRU01 | B38: SPRDAPITSMGRU01 | C38: SPRDAPITSMGRU01 | D38: =VLOOKUP(A:A,Elastic!A:A,1,0) -> SPRDAPITSMGRU01 | E38: Hostname alterado
A39: SPRDAPCCPRGRU02 | B39: =VLOOKUP(A:A,Qualys!A:A,1,0) -> SPRDAPCCPRGRU02 | C39: =VLOOKUP(A:A,Sentinel!A:A,1,0) -> SPRDAPCCPRGRU02 | D39: =VLOOKUP(A:A,Elastic!A:A,1,0) -> SPRDAPCCPRGRU02 | E39: ok
A40: SPRDAPMISP01 | B40: =VLOOKUP(A:A,Qualys!A:A,1,0) -> SPRDAPMISP01 | C40: =VLOOKUP(A:A,Sentinel!A:A,1,0) -> SPRDAPMISP01 | D40: =VLOOKUP(A:A,Elastic!A:A,1,0) -> SPRDAPMISP01 | E40: ok
A41: SPRDAPNBKGRU01 | B41: =VLOOKUP(A:A,Qualys!A:A,1,0) -> SPRDAPNBKGRU01 | C41: =VLOOKUP(A:A,Sentinel!A:A,1,0) -> SPRDAPNBKGRU01 | D41: =VLOOKUP(A:A,Elastic!A:A,1,0) -> #N/A | E41: RedHat 6 Não Suporta Elastic
A42: SPRDAPNFSGRU01 | B42: =VLOOKUP(A:A,Qualys!A:A,1,0) -> SPRDAPNFSGRU01 | C42: =VLOOKUP(A:A,Sentinel!A:A,1,0) -> SPRDAPNFSGRU01 | D42: =VLOOKUP(A:A,Elastic!A:A,1,0) -> SPRDAPNFSGRU01 | E42: ok
A43: SPRDAPCMSGRU08 | B43: =VLOOKUP(A:A,Qualys!A:A,1,0) -> SPRDAPCMSGRU08 | C43: =VLOOKUP(A:A,Sentinel!A:A,1,0) -> SPRDAPCMSGRU08 | D43: =VLOOKUP(A:A,Elastic!A:A,1,0) -> SPRDAPCMSGRU08 | E43: ok
A44: SPRDAPOCSGRU01 | B44: =VLOOKUP(A:A,Qualys!A:A,1,0) -> SPRDAPOCSGRU01 | C44: =VLOOKUP(A:A,Sentinel!A:A,1,0) -> SPRDAPOCSGRU01 | D44: =VLOOKUP(A:A,Elastic!A:A,1,0) -> SPRDAPOCSGRU01 | E44: ok
A45: SPRDAPPIGRU01 | B45: =VLOOKUP(A:A,Qualys!A:A,1,0) -> SPRDAPPIGRU01 | C45: =VLOOKUP(A:A,Sentinel!A:A,1,0) -> SPRDAPPIGRU01 | D45: =VLOOKUP(A:A,Elastic!A:A,1,0) -> #N/A | E45: RedHat 6 Não Suporta Elastic
A46: SPRDAPPIGRU02 | B46: =VLOOKUP(A:A,Qualys!A:A,1,0) -> SPRDAPPIGRU02 | C46: =VLOOKUP(A:A,Sentinel!A:A,1,0) -> SPRDAPPIGRU02 | D46: =VLOOKUP(A:A,Elastic!A:A,1,0) -> #N/A | E46: RedHat 6 Não Suporta Elastic
A47: SPRDAPNMCGRU01 | B47: =VLOOKUP(A:A,Qualys!A:A,1,0) -> SPRDAPNMCGRU01 | C47: =VLOOKUP(A:A,Sentinel!A:A,1,0) -> SPRDAPNMCGRU01 | D47: =VLOOKUP(A:A,Elastic!A:A,1,0) -> SPRDAPNMCGRU01 | E47: ok
A48: SPRDAPPRMGRU01 | B48: =VLOOKUP(A:A,Qualys!A:A,1,0) -> SPRDAPPRMGRU01 | C48: =VLOOKUP(A:A,Sentinel!A:A,1,0) -> SPRDAPPRMGRU01 | D48: =VLOOKUP(A:A,Elastic!A:A,1,0) -> SPRDAPPRMGRU01 | E48: ok
A49: SPRDAPRMAGRU01 | B49: =VLOOKUP(A:A,Qualys!A:A,1,0) -> #N/A | C49: =VLOOKUP(A:A,Sentinel!A:A,1,0) -> #N/A | D49: =VLOOKUP(A:A,Elastic!A:A,1,0) -> #N/A | E49: Servidor excluido/desativado
A50: SPRDAPRMAGRU02 | B50: =VLOOKUP(A:A,Qualys!A:A,1,0) -> #N/A | C50: =VLOOKUP(A:A,Sentinel!A:A,1,0) -> #N/A | D50: =VLOOKUP(A:A,Elastic!A:A,1,0) -> #N/A | E50: Servidor excluido/desativado
... A76: SPRDAPVPRGRU07 | B76: =VLOOKUP(A:A,Qualys!A:A,1,0) -> #N/A | C76: =VLOOKUP(A:A,Sentinel!A:A,1,0) -> #N/A | D76: =VLOOKUP(A:A,Elastic!A:A,1,0) -> #N/A | E76: Sem acesso, pendente verificação
A77: SPRDBDDACGRU01 | B77: =VLOOKUP(A:A,Qualys!A:A,1,0) -> SPRDBDDACGRU01 | C77: SPRDBDDACGRU01 | D77: =VLOOKUP(A:A,Elastic!A:A,1,0) -> #N/A | E77: ok
A78: SPRDBDITSMGRU01 | B78: SPRDBDITSMGRU01 | C78: SPRDBDITSMGRU01 | D78: =VLOOKUP(A:A,Elastic!A:A,1,0) -> SPRDBDITSMGRU01 | E78: Hostname alterado
A79: SPRDBDORAGRU03 | B79: =VLOOKUP(A:A,Qualys!A:A,1,0) -> #N/A | C79: =VLOOKUP(A:A,Sentinel!A:A,1,0) -> #N/A | D79: =VLOOKUP(A:A,Elastic!A:A,1,0) -> #N/A | E79: Impossivel proteger, RedHat 5
A80: SPRDBDORAGRU04 | B80: =VLOOKUP(A:A,Qualys!A:A,1,0) -> SPRDBDORAGRU04 | C80: =VLOOKUP(A:A,Sentinel!A:A,1,0) -> SPRDBDORAGRU04 | D80: =VLOOKUP(A:A,Elastic!A:A,1,0) -> #N/A | E80: RedHat 6 Não Suporta Elastic
A81: SPRDBDORAGRU05 | B81: =VLOOKUP(A:A,Qualys!A:A,1,0) -> SPRDBDORAGRU05 | C81: =VLOOKUP(A:A,Sentinel!A:A,1,0) -> SPRDBDORAGRU05 | D81: =VLOOKUP(A:A,Elastic!A:A,1,0) -> #N/A | E81: RedHat 6 Não Suporta Elastic
A82: SPBDORAGRU09 | B82: =VLOOKUP(A:A,Qualys!A:A,1,0) -> SPBDORAGRU09 | C82: =VLOOKUP(A:A,Sentinel!A:A,1,0) -> SPBDORAGRU09 | D82: =VLOOKUP(A:A,Elastic!A:A,1,0) -> #N/A | E82: RedHat 6 Não Suporta Elastic
A83: SPBDORAGRU11 | B83: =VLOOKUP(A:A,Qualys!A:A,1,0) -> SPBDORAGRU11 | C83: =VLOOKUP(A:A,Sentinel!A:A,1,0) -> SPBDORAGRU11 | D83: =VLOOKUP(A:A,Elastic!A:A,1,0) -> #N/A | E83: RedHat 6 Não Suporta Elastic
A84: SPRDAPRPGRU15 | B84: =VLOOKUP(A:A,Qualys!A:A,1,0) -> SPRDAPRPGRU15 | C84: =VLOOKUP(A:A,Sentinel!A:A,1,0) -> SPRDAPRPGRU15 | D84: =VLOOKUP(A:A,Elastic!A:A,1,0) -> #N/A | E84: Elastic instalado
A85: SPRDBDORAGRU13 | B85: =VLOOKUP(A:A,Qualys!A:A,1,0) -> SPRDBDORAGRU13 | C85: =VLOOKUP(A:A,Sentinel!A:A,1,0) -> SPRDBDORAGRU13 | D85: =VLOOKUP(A:A,Elastic!A:A,1,0) -> SPRDBDORAGRU13 | E85: ok
A86: SPRDBDOTRSGRU01 | B86: SPRDBDOTRSGRU01 | C86: =VLOOKUP(A:A,Sentinel!A:A,1,0) -> SPRDBDOTRSGRU01 | D86: SPRDBDOTRSGRU01 | E86: ok, servidor renomeado
A87: SPRDBDSPGGRU01 | B87: =VLOOKUP(A:A,Qualys!A:A,1,0) -> SPRDBDSPGGRU01 | C87: =VLOOKUP(A:A,Sentinel!A:A,1,0) -> SPRDBDSPGGRU01 | D87: =VLOOKUP(A:A,Elastic!A:A,1,0) -> SPRDBDSPGGRU01 | E87: ok
...

Sheet Qualys
A1: NAME
A2: SPRDAPLOGSGRU01
A3: SDQBDORAGRU02
A4: SPRDAPRPGRU15
A5: SPRDSIEM02
A6: SPRDAPBIGRU01
A7: SUATBDORAGRU01
A8: SPRDBDORAGRU13
A9: SPRDMYSQLGRU02
A10: SPRDAPLOGSGRU01
A11: SDQBDORAGRU01
A12: SPRDAPGRFGRU01
... A92: SPRDBDORAGRU12

Sheet Sentinel
A1: SPRDPRXEGTGRU02
A2: SPRDPRXEGTGRU01
A3: SPRDBDORAGRU13
A4: SPRDAPECCGRU07
A5: SPRDZBGRU03
A6: SPRDAPSSHGRU01
A7: SPRDAPMISP01
A8: SPRDBDSPGGRU01
A9: SPRDAPSPGGRU01
A10: SPRDAPSQBGRU01
A11: SPRDAPGFNGRU02
A12: SHOMAPPOSTGRU01
... A130: SPRDAPCCPRGRU02

Sheet Elastic
A1: PRDRMADS02
A2: SHOMAPCMSGRU01
A3: SHOMAPCMSGRU03
A4: SHOMAPCMSGRU11
A5: SHOMAPCUPSGRU01
A6: SHOMAPGPROGRU01
A7: SHOMAPIHSGRU02
A8: SHOMAPMOOGRU01
A9: SHOMAPPOSTGRU01
A10: SHOMAPREPGRU01
A11: SHOMBDMOOGRU01
A12: SHOMBDOTRSGRU01
... A85: SPRDZBGRU05
