Workbook

Sheet SOC CHeck
A1: Servidores de Produção | B1: IP | C1: Qualys | D1: Sentinel | E1: Elastic
A2: SPRDZBGRU01 | B2: 172.16.253.68 | C2: =VLOOKUP(A:A,Qualys!B:B,1,0) -> SPRDZBGRU01 | D2: =VLOOKUP(A:A,Sentinel!A:A,1,0) -> SPRDZBGRU01 | E2: =VLOOKUP(A:A,Elastic!A:A,1,0) -> sprdzbgru01
A3: SPRDZBGRU02 | B3: 172.16.253.69 | C3: =VLOOKUP(A:A,Qualys!B:B,1,0) -> SPRDZBGRU02 | D3: =VLOOKUP(A:A,Sentinel!A:A,1,0) -> SPRDZBGRU02 | E3: =VLOOKUP(A:A,Elastic!A:A,1,0) -> sprdzbgru02
A4: SPRDZBGRU03 | B4: 172.16.253.70 | C4: =VLOOKUP(A:A,Qualys!B:B,1,0) -> SPRDZBGRU03 | D4: =VLOOKUP(A:A,Sentinel!A:A,1,0) -> SPRDZBGRU03 | E4: =VLOOKUP(A:A,Elastic!A:A,1,0) -> sprdzbgru03
A5: SPRDZBGRU04 | B5: 172.16.253.71 | C5: =VLOOKUP(A:A,Qualys!B:B,1,0) -> SPRDZBGRU04 | D5: =VLOOKUP(A:A,Sentinel!A:A,1,0) -> SPRDZBGRU04 | E5: =VLOOKUP(A:A,Elastic!A:A,1,0) -> sprdzbgru04
A6: SPRDZBGRU05 | B6: 172.16.253.72 | C6: =VLOOKUP(A:A,Qualys!B:B,1,0) -> SPRDZBGRU05 | D6: =VLOOKUP(A:A,Sentinel!A:A,1,0) -> SPRDZBGRU05 | E6: =VLOOKUP(A:A,Elastic!A:A,1,0) -> sprdzbgru05
A7: SPRDAPGFNGRU02 | B7: 172.16.253.82 | C7: =VLOOKUP(A:A,Qualys!B:B,1,0) -> sprdapgfngru02 | D7: =VLOOKUP(A:A,Sentinel!A:A,1,0) -> sprdapgfngru02 | E7: =VLOOKUP(A:A,Elastic!A:A,1,0) -> #N/A
A8: SPRDAPZBPXGRU01 | B8: 172.16.253.84 | C8: =VLOOKUP(A:A,Qualys!B:B,1,0) -> sprdapzbpxgru01 | D8: =VLOOKUP(A:A,Sentinel!A:A,1,0) -> sprdapzbpxgru01 | E8: =VLOOKUP(A:A,Elastic!A:A,1,0) -> sprdapzbpxgru01
A9: SPRDAPZABGRU02 | B9: 172.16.253.88 | C9: =VLOOKUP(A:A,Qualys!B:B,1,0) -> sprdapzabgru02 | D9: =VLOOKUP(A:A,Sentinel!A:A,1,0) -> sprdapzabgru02 | E9: =VLOOKUP(A:A,Elastic!A:A,1,0) -> #N/A
A10: SPRDAPOCSGRU01 | B10: 172.16.253.89 | C10: =VLOOKUP(A:A,Qualys!B:B,1,0) -> SPRDAPOCSGRU01 | D10: =VLOOKUP(A:A,Sentinel!A:A,1,0) -> SPRDAPOCSGRU01 | E10: =VLOOKUP(A:A,Elastic!A:A,1,0) -> SPRDAPOCSGRU01
A11: SPRDMYSQLGRU02 | B11: 172.16.253.90 | C11: =VLOOKUP(A:A,Qualys!B:B,1,0) -> SPRDMYSQLGRU02 | D11: =VLOOKUP(A:A,Sentinel!A:A,1,0) -> SPRDMYSQLGRU02 | E11: =VLOOKUP(A:A,Elastic!A:A,1,0) -> SPRDMYSQLGRU02
A12: SPRDAPZBPXGRU02 | B12: 172.16.253.91 | C12: =VLOOKUP(A:A,Qualys!B:B,1,0) -> sprdapzbpxgru02 | D12: =VLOOKUP(A:A,Sentinel!A:A,1,0) -> sprdapzbpxgru02 | E12: =VLOOKUP(A:A,Elastic!A:A,1,0) -> #N/A
A13: SPRDNTDGRU03 | B13: 172.16.253.92 | C13: =VLOOKUP(A:A,Qualys!B:B,1,0) -> SPRDNTDGRU03 | D13: =VLOOKUP(A:A,Sentinel!A:A,1,0) -> SPRDNTDGRU03 | E13: =VLOOKUP(A:A,Elastic!A:A,1,0) -> SPRDNTDGRU03
... A21: SPRDAPSMGRU02 | B21: 172.31.49.147 | C21: =VLOOKUP(A:A,Qualys!B:B,1,0) -> sprdapsmgru02 | D21: =VLOOKUP(A:A,Sentinel!A:A,1,0) -> sprdapsmgru02 | E21: =VLOOKUP(A:A,Elastic!A:A,1,0) -> sprdapsmgru02
A22: SPRDBDORAGRU09 | B22: 172.31.49.150 | C22: spbdoragru09 | D22: spbdoragru09 | E22: spbdoragru09
A23: SPRDAPECGRU01 | B23: 172.31.49.152 | C23: =VLOOKUP(A:A,Qualys!B:B,1,0) -> sprdapecgru01 | D23: =VLOOKUP(A:A,Sentinel!A:A,1,0) -> sprdapecgru01 | E23: =VLOOKUP(A:A,Elastic!A:A,1,0) -> sprdapecgru01
A24: SPRDAPECGRU02 | B24: 172.31.49.153 | C24: =VLOOKUP(A:A,Qualys!B:B,1,0) -> sprdapecgru02 | D24: =VLOOKUP(A:A,Sentinel!A:A,1,0) -> sprdapecgru02 | E24: =VLOOKUP(A:A,Elastic!A:A,1,0) -> sprdapecgru02
A25: SPRDAPECGRU03 | B25: 172.31.49.154 | C25: =VLOOKUP(A:A,Qualys!B:B,1,0) -> sprdapecgru03 | D25: =VLOOKUP(A:A,Sentinel!A:A,1,0) -> sprdapecgru03 | E25: =VLOOKUP(A:A,Elastic!A:A,1,0) -> sprdapecgru03
A26: SPRDAPPIGRU01 | B26: 172.31.49.155 | C26: =VLOOKUP(A:A,Qualys!B:B,1,0) -> sprdappigru01 | D26: =VLOOKUP(A:A,Sentinel!A:A,1,0) -> sprdappigru01 | E26: =VLOOKUP(A:A,Elastic!A:A,1,0) -> sprdappigru01
A27: SPRDAPBIGRU01 | B27: 172.31.49.156 | C27: =VLOOKUP(A:A,Qualys!B:B,1,0) -> sprdapbigru01 | D27: =VLOOKUP(A:A,Sentinel!A:A,1,0) -> sprdapbigru01 | E27: =VLOOKUP(A:A,Elastic!A:A,1,0) -> sprdapbigru01
A28: SPRDBDOTRSGRU01 | B28: 172.31.49.16 | C28: =VLOOKUP(A:A,Qualys!B:B,1,0) -> SPRDBDOTRSGRU01 | D28: =VLOOKUP(A:A,Sentinel!A:A,1,0) -> SPRDBDOTRSGRU01 | E28: =VLOOKUP(A:A,Elastic!A:A,1,0) -> SPRDBDOTRSGRU01
A29: SPRDBDORAGRU11 | B29: 172.31.49.163 | C29: spbdoragru11 | D29: spbdoragru11 | E29: spbdoragru11
A30: SPRDAPECGRU04 | B30: 172.31.49.165 | C30: =VLOOKUP(A:A,Qualys!B:B,1,0) -> sprdapecgru04 | D30: =VLOOKUP(A:A,Sentinel!A:A,1,0) -> sprdapecgru04 | E30: =VLOOKUP(A:A,Elastic!A:A,1,0) -> sprdapecgru04
A31: SPRDAPECGRU05 | B31: 172.31.49.166 | C31: =VLOOKUP(A:A,Qualys!B:B,1,0) -> sprdapecgru05 | D31: =VLOOKUP(A:A,Sentinel!A:A,1,0) -> sprdapecgru05 | E31: =VLOOKUP(A:A,Elastic!A:A,1,0) -> sprdapecgru05
A32: SPRDAPECGRU06 | B32: 172.31.49.167 | C32: =VLOOKUP(A:A,Qualys!B:B,1,0) -> sprdapecgru06 | D32: =VLOOKUP(A:A,Sentinel!A:A,1,0) -> sprdapecgru06 | E32: =VLOOKUP(A:A,Elastic!A:A,1,0) -> sprdapecgru06
A33: SPRDAPPIGRU02 | B33: 172.31.49.168 | C33: =VLOOKUP(A:A,Qualys!B:B,1,0) -> sprdappigru02 | D33: =VLOOKUP(A:A,Sentinel!A:A,1,0) -> sprdappigru02 | E33: =VLOOKUP(A:A,Elastic!A:A,1,0) -> sprdappigru02
A34: SPRDAPBIGRU02 | B34: 172.31.49.169 | C34: =VLOOKUP(A:A,Qualys!B:B,1,0) -> sprdapbigru02 | D34: =VLOOKUP(A:A,Sentinel!A:A,1,0) -> sprdapbigru02 | E34: =VLOOKUP(A:A,Elastic!A:A,1,0) -> #N/A
A35: SPRDAPSSHGRU01 | B35: 172.31.49.176 | C35: =VLOOKUP(A:A,Qualys!B:B,1,0) -> SPRDAPSSHGRU01 | D35: =VLOOKUP(A:A,Sentinel!A:A,1,0) -> SPRDAPSSHGRU01 | E35: =VLOOKUP(A:A,Elastic!A:A,1,0) -> SPRDAPSSHGRU01
A36: SPRDAPCMSGRU08 | B36: 172.31.49.199 | C36: =VLOOKUP(A:A,Qualys!B:B,1,0) -> SPRDAPCMSGRU08 | D36: =VLOOKUP(A:A,Sentinel!A:A,1,0) -> SPRDAPCMSGRU08 | E36: =VLOOKUP(A:A,Elastic!A:A,1,0) -> SPRDAPCMSGRU08
A37: SPRDSAPNASGRU01 | B37: 172.31.49.202 | C37: =VLOOKUP(A:A,Qualys!B:B,1,0) -> sprdsapnasgru01 | D37: =VLOOKUP(A:A,Sentinel!A:A,1,0) -> sprdsapnasgru01 | E37: =VLOOKUP(A:A,Elastic!A:A,1,0) -> sprdsapnasgru01
A38: SPRDAPCUPSGRU03 | B38: 172.31.49.208 | C38: =VLOOKUP(A:A,Qualys!B:B,1,0) -> SPRDAPCUPSGRU03 | D38: =VLOOKUP(A:A,Sentinel!A:A,1,0) -> SPRDAPCUPSGRU03 | E38: =VLOOKUP(A:A,Elastic!A:A,1,0) -> SPRDAPCUPSGRU03
A39: SPRDAPCUPSGRU04 | B39: 172.31.49.209 | C39: =VLOOKUP(A:A,Qualys!B:B,1,0) -> SPRDAPCUPSGRU04 | D39: =VLOOKUP(A:A,Sentinel!A:A,1,0) -> SPRDAPCUPSGRU04 | E39: =VLOOKUP(A:A,Elastic!A:A,1,0) -> SPRDAPCUPSGRU04
A40: SPRDAPNBKGRU01 | B40: 172.31.49.210 | C40: =VLOOKUP(A:A,Qualys!B:B,1,0) -> sprdapnbkgru01 | D40: =VLOOKUP(A:A,Sentinel!A:A,1,0) -> sprdapnbkgru01 | E40: =VLOOKUP(A:A,Elastic!A:A,1,0) -> sprdapnbkgru01
A41: SPRDAPLOGSGRU01 | B41: 172.31.49.221 | C41: =VLOOKUP(A:A,Qualys!B:B,1,0) -> SPRDAPLOGSGRU01 | D41: =VLOOKUP(A:A,Sentinel!A:A,1,0) -> SPRDAPLOGSGRU01 | E41: =VLOOKUP(A:A,Elastic!A:A,1,0) -> SPRDAPLOGSGRU01
... A82: SPRDAPRPGRU12 | B82: 192.168.0.60 | C82: =VLOOKUP(A:A,Qualys!B:B,1,0) -> SPRDAPRPGRU12 | D82: =VLOOKUP(A:A,Sentinel!A:A,1,0) -> SPRDAPRPGRU12 | E82: =VLOOKUP(A:A,Elastic!A:A,1,0) -> SPRDAPRPGRU12
A83: SPRDBDDACGRU01 | B83: 192.168.40.134 | C83: =VLOOKUP(A:A,Qualys!B:B,1,0) -> SPRDBDDACGRU01 | D83: dacdb-gru | E83: =VLOOKUP(A:A,Elastic!A:A,1,0) -> #N/A
A84: SPRDAPDIPGRU01 | B84: 192.168.40.136 | C84: =VLOOKUP(A:A,Qualys!B:B,1,0) -> SPRDAPDIPGRU01 | D84: =VLOOKUP(A:A,Sentinel!A:A,1,0) -> SPRDAPDIPGRU01 | E84: =VLOOKUP(A:A,Elastic!A:A,1,0) -> #N/A
A86: Nome Diferente
A87: Corrigido
A88: Impossivel Corrigir

Sheet Qualys
A1: Asset Id | B1: Asset Name | C1: Host Id | D1: Netbios Name | E1: Mac Address | F1: IPV4 Addresses | G1: IPV6 Addresses | H1: Operating System Category | I1: OS | J1: Operating System Version | K1: Operating System Lifecycle Stage | L1: Hardware Category | M1: Hardware Name | N1: Hardware Lifecycle Stage | O1: CPU Count | P1: CPU Speed (mhz) | Q1: CPU Description | R1: Total Memory (mb) | S1: Bios Description | T1: Bios Serial Number | U1: Bios Asset Tag | V1: Time Zone | W1: Last System Boot | X1: Last Logged-In User | Y1: Inventory Source | Z1: Agent Id | AA1: Inventory Last Updated On | AB1: Architecture | AC1: Modules | AD1: Sources | AE1: Criticality Score | AF1: TruRisk Score | AG1: Hardware Uuid | AH1: Activity | AI1: Tags
A2: 85888236 | B2: SPRDZBGRU03 | C2: 21733190 | D2: '- | E2: 00:50:56:92:97:71,00:50:56:92:97:71 | F2: 172.16.253.70 | G2: fe80:0:0:0:250:56ff:fe92:9771 | H2: Linux / Unidentified | I2: Canonical Ubuntu Noble Numbat 24.04 LTS 24.04.1 LTS | J2: 24.04 LTS | K2: GA | L2: Virtualized / Virtual Machine | M2: VMware VMware Virtual Platform VMware Virtual Platform | N2: Unknown | O2: 10 | P2: 2600 | Q2: Intel(R) Xeon(R) Gold 6348 CPU @ 2.60GHz | R2: 34017 | S2: VMware, Inc. VMW201.00V.20829224.B64.2211211842 11/21/2022 | T2: VMware-42 12 a2 9f 50 59 37 c0-47 f9 0d 08 bd 0e f1 f9 | U2: No Asset Tag | V2: '-03:00 | W2: Aug 9, 2024 | X2: root | Y2: QAGENT | Z2: 4707d078-f2d3-4855-96cd-2db94e8ffc2f | AA2: Jan 31, 2025 | AB2: x86_64 | AC2: VM,SCA,PM | AD2: Cloud Agent | AE2: 4 | AF2: 475 | AG2: 9fa21242-5950-c037-47f9-0d08bd0ef1f9 | AH2: Jan 31, 2025 | AI2: Cloud Agent,GRU_ACN_4-Perigoso,GRU-GERAL,GRU_CAT_ACN-INFRACRITICA
A3: 21366253 | B3: SPRDAPRMAGRU04 | C3: 7550466 | D3: '- | E3: 00:50:56:92:ec:09,00:50:56:92:ec:09 | F3: 192.168.0.36 | G3: fe80:0:0:0:250:56ff:fe92:ec09 | H3: Linux / Unidentified | I3: Canonical Ubuntu Focal Fossa 20.04 LTS 20.04.1 LTS | J3: 20.04 LTS | K3: GA | L3: Virtualized / Virtual Machine | M3: VMware VMware Virtual Platform VMware Virtual Platform | N3: Unknown | O3: 2 | P3: 2600 | Q3: Intel(R) Xeon(R) Gold 6348 CPU @ 2.60GHz | R3: 3888 | S3: Phoenix Technologies LTD 6.00 11/12/2020 | T3: VMware-42 12 b7 1c b1 6d 7f e9-03 7b 03 22 1c 68 18 d1 | U3: No Asset Tag | V3: '-03:00 | W3: Jul 2, 2024 | X3: root | Y3: QAGENT | Z3: b6661280-51e6-48fb-9998-34e9cf460fa9 | AA3: Jan 31, 2025 | AB3: x86_64 | AC3: VM,SCA,PM | AD3: Cloud Agent | AE3: 3 | AF3: 366 | AG3: 1cb71242-6db1-e97f-037b-03221c6818d1 | AH3: Jan 31, 2025 | AI3: Cloud Agent,GRU_ACN_3-Maior,GRU-GERAL,GRU_CAT_ACN-AMS
A4: 95867240 | B4: sprdapecgru02 | C4: 24677781 | D4: '- | E4: 54:9f:35:73:0b:88,54:9f:35:73:0b:88 | F4: 172.31.49.153 | G4: fe80:0:0:0:569f:35ff:fe73:b88 | H4: Linux / Server | I4: Red Hat Enterprise Linux Server 6 6.6 | J4: 6.6 | K4: EOL/EOS | L4: Computers / Server | M4: Dell PowerEdge M620 | N4: EOS | O4: 24 | P4: 2100 | Q4: Intel(R) Xeon(R) CPU E5-2620 v2 @ 2.10GHz | R4: 32062 | S4: Dell Inc. 2.4.3 07/02/2014 | T4: FM22012 | U4: '- | V4: '-03:00 | W4: Jan 22, 2025 | X4: root | Y4: QAGENT | Z4: d46e9433-918b-4166-8027-117c777b2d9d | AA4: Jan 31, 2025 | AB4: x86_64 | AC4: VM,SCA,PM | AD4: Cloud Agent | AE4: 5 | AF4: 880 | AG4: 44454c4c-4d00-1032-8032-c6c04f303132 | AH4: Jan 31, 2025 | AI4: Cloud Agent,GRU_ACN_5-Catastrofico,GRU-GERAL,GRU_CAT_ACN-SAP
A5: 56154521 | B5: SHOMWBCMSGRU01 | C5: 13487063 | D5: '- | E5: 00:50:56:b6:da:65,52:54:00:00:5c:5b,00:50:56:b6:da:65 | F5: 172.31.52.32,192.168.122.1 | G5: fe80:0:0:0:250:56ff:feb6:da65 | H5: Linux / Server | I5: Red Hat Enterprise Linux 8 8.10 | J5: 8.10 | K5: GA | L5: Virtualized / Virtual Machine | M5: VMware VMware Virtual Platform VMware Virtual Platform | N5: Unknown | O5: 4 | P5: 2400 | Q5: Intel(R) Xeon(R) CPU E5-4640 0 @ 2.40GHz | R5: 17745 | S5: Phoenix Technologies LTD 6.00 12/12/2018 | T5: VMware-42 36 44 d9 d8 f4 73 25-da 4f 54 90 4c 38 e6 e9 | U5: No Asset Tag | V5: '-03:00 | W5: Oct 3, 2024 | X5: root | Y5: QAGENT | Z5: b66f361f-2c13-4eaa-b093-75e09e3a4cb7 | AA5: Jan 31, 2025 | AB5: x86_64 | AC5: VM,SCA,PM | AD5: Cloud Agent | AE5: 1 | AF5: 169 | AG5: d9443642-f4d8-2573-da4f-54904c38e6e9 | AH5: Jan 31, 2025 | AI5: Cloud Agent,GRU-GERAL,GRU-CAT-Servidores
A6: 24112996 | B6: sprdapcmsgru02 | C6: 7852074 | D6: '- | E6: b8:ca:3a:33:8e:c2 | F6: 172.31.49.87 | H6: Linux / Server | I6: Red Hat Enterprise Linux Server 6 6.10 | J6: 6.10 | K6: EOL/EOS | L6: Computers / Server | M6: Dell PowerEdge M820 | N6: EOS | O6: 32 | P6: 2400 | Q6: Intel(R) Xeon(R) CPU E5-4640 0 @ 2.40GHz | R6: 129006 | S6: Dell Inc. 2.3.3 01/27/2016 | T6: 8LPNKZ1 | U6: '- | V6: '-03:00 | W6: Aug 11, 2023 | X6: root | Y6: QAGENT | Z6: 67b92f6a-e0b4-4212-b284-8fc3eac50bb9 | AA6: Jan 31, 2025 | AB6: x86_64 | AC6: VM,SCA,PM | AD6: Cloud Agent | AE6: 1 | AF6: 173 | AG6: 44454c4c-4c00-1050-804e-b8c04f4b5a31 | AH6: Jan 31, 2025 | AI6: Cloud Agent,GRU-GERAL,GRU-CAT-Servidores
A7: 24268668 | B7: SDESAPNWGRU01 | C7: 7880078 | D7: '- | E7: 00:50:56:9d:65:56,00:50:56:9d:65:56 | F7: 172.31.52.122 | G7: fe80:0:0:0:250:56ff:fe9d:6556 | H7: Linux / Server | I7: Red Hat Enterprise Linux Server 6 6.5 | J7: 6.5 | K7: EOL/EOS | L7: Virtualized / Virtual Machine | M7: VMware VMware Virtual Platform VMware Virtual Platform | N7: Unknown | O7: 4 | P7: 2400 | Q7: Intel(R) Xeon(R) CPU E5-4640 0 @ 2.40GHz | R7: 32097 | S7: Phoenix Technologies LTD 6.00 12/12/2018 | T7: VMware-42 1d 68 2c 2b 6e 05 ce-13 5c 41 ac 6a 94 ca de | U7: No Asset Tag | V7: '-03:00 | W7: Aug 29, 2024 | X7: root | Y7: QAGENT | Z7: e93b2bbc-e6a4-4210-aa29-90156171e746 | AA7: Jan 31, 2025 | AB7: x86_64 | AC7: VM,SCA,PM | AD7: Cloud Agent | AE7: 1 | AF7: 174 | AG7: 421d682c-2b6e-05ce-135c-41ac6a94cade | AH7: Jan 31, 2025 | AI7: Cloud Agent,GRU-GERAL,GRU-CAT-Servidores
A8: 105340447 | B8: SHOMRMAGRU01 | C8: 27089989 | D8: '- | E8: 00:50:56:8a:d4:0b,00:50:56:8a:d4:0b | F8: 10.36.52.18 | G8: fe80:0:0:0:250:56ff:fe8a:d40b | H8: Linux / Unidentified | I8: Canonical Ubuntu Jammy Jellyfish 22.04 LTS 22.04.5 LTS | J8: 22.04 LTS | K8: GA | L8: Virtualized / Virtual Machine | M8: VMware VMware Virtual Platform VMware Virtual Platform | N8: Unknown | O8: 4 | P8: 2100 | Q8: Intel(R) Xeon(R) CPU E5-2620 v2 @ 2.10GHz | R8: 7901 | S8: Phoenix Technologies LTD 6.00 09/19/2018 | T8: VMware-42 0a 2f 8e a1 25 f8 33-8e cd a6 e6 8b ba 82 bb | U8: No Asset Tag | V8: '-03:00 | W8: Jul 31, 2024 | X8: root | Y8: QAGENT | Z8: 5e7f6cba-a327-4801-aa9e-e565a988ad05 | AA8: Jan 31, 2025 | AB8: x86_64 | AC8: VM,SCA,PM | AD8: Cloud Agent | AE8: 1 | AF8: 124 | AG8: 8e2f0a42-25a1-33f8-8ecd-a6e68bba82bb | AH8: Jan 31, 2025 | AI8: Cloud Agent,GRU-GERAL,GRU-CAT-Servidores
A9: 112853995 | B9: spbdoragru11 | C9: 29078941 | D9: '- | E9: 54:9f:35:71:da:ac,54:9f:35:71:da:ac,54:9f:35:71:d9:2e,54:9f:35:71:d9:2e,54:9f:35:71:d9:2e,54:9f:35:71:d9:2e,54:9f:35:71:da:ac | F9: 10.1.1.58,169.254.223.104,172.31.49.163,172.31.49.190,172.31.49.191 | G9: fe80:0:0:0:569f:35ff:fe71:d92e,fe80:0:0:0:569f:35ff:fe71:daac | H9: Linux / Server | I9: Red Hat Enterprise Linux Server 6 6.6 | J9: 6.6 | K9: EOL/EOS | L9: Computers / Server | M9: Dell PowerEdge M620 | N9: EOS | O9: 40 | P9: 2200 | Q9: Intel(R) Xeon(R) CPU E5-2660 v2 @ 2.20GHz | R9: 258302 | S9: Dell Inc. 2.4.3 07/02/2014 | T9: HM27012 | U9: '- | V9: '-03:00 | W9: Sep 1, 2024 | X9: root | Y9: QAGENT | Z9: 27204092-1690-4ae1-a2b3-9c5c20794307 | AA9: Jan 31, 2025 | AB9: x86_64 | AC9: VM,SCA,PM | AD9: Cloud Agent | AE9: 4 | AF9: 703 | AG9: 44454c4c-4d00-1032-8037-c8c04f303132 | AH9: Jan 31, 2025 | AI9: Cloud Agent,GRU_ACN_4-Perigoso,GRU-GERAL,GRU_CAT_ACN-SAP
A10: 109170828 | B10: SPRDAPAUDGRU01 | C10: 28063260 | D10: SPRDAPAUDGRU01 | E10: 00:50:56:A3:6F:36 | F10: 172.31.57.69 | H10: Windows / Server | I10: Microsoft Windows Server 2019 Datacenter 1809 Build 17763.6293 64-Bit | J10: 1809 | K10: EOL | L10: Virtualized / Virtual Machine | M10: VMware VMware Virtual Platform VMware Virtual Platform | N10: Unknown | O10: 8 | P10: 2594 | Q10: Intel(R) Xeon(R) Gold 6348 CPU @ 2.60GHz | R10: 20479 | S10: Phoenix Technologies LTD 6.00 | T10: VMware-42 23 1e 3c d8 9f 8c 7d-b5 49 3f db 4d e2 cb a2 | U10: NoAssetTag | V10: '-03:00 | W10: Jan 17, 2025 | X10: alpha | Y10: QAGENT | Z10: 621d7ba9-09cf-4584-99ea-a5a0143a7c6f | AA10: Jan 31, 2025 | AB10: 64-bit | AC10: VM,SCA,PM | AD10: Cloud Agent | AE10: 1 | AF10: 172 | AG10: 3C1E2342-9FD8-7D8C-B549-3FDB4DE2CBA2 | AH10: Jan 31, 2025 | AI10: Cloud Agent,GRU-GERAL,GRU-CAT-Servidores
A11: 96989672 | B11: SPRDAPCUPSGRU03 | C11: 24900872 | D11: '- | E11: 00:50:56:a3:5a:db | F11: 172.31.49.208 | H11: Linux / Server | I11: Red Hat Enterprise Linux 9 9.5 | J11: 9.5 | K11: GA | L11: Virtualized / Virtual Machine | M11: VMware VMware Virtual Platform VMware Virtual Platform | N11: Unknown | O11: 4 | P11: 2600 | Q11: Intel(R) Xeon(R) Gold 6348 CPU @ 2.60GHz | R11: 5635 | S11: VMware, Inc. VMW201.00V.20829224.B64.2211211842 11/21/2022 | T11: VMware-42 23 b3 55 a2 22 50 fc-6d 17 07 a2 56 63 a6 f4 | U11: No Asset Tag | V11: '-03:00 | W11: Dec 25, 2024 | X11: sysgru | Y11: QAGENT | Z11: 2f5380fa-6e49-48c6-8741-8ee016e20073 | AA11: Jan 31, 2025 | AB11: x86_64 | AC11: VM,SCA,PM | AD11: Cloud Agent | AE11: 5 | AF11: 34 | AG11: 55b32342-22a2-fc50-6d17-07a25663a6f4 | AH11: Jan 31, 2025 | AI11: Cloud Agent,GRU_ACN_5-Catastrofico,GRU-GERAL,GRU_CAT_ACN-CMS
A12: 114356548 | B12: SPRDAPOCSGRU01 | C12: 29394703 | D12: '- | E12: 00:50:56:9d:1a:13,00:50:56:9d:1a:13 | F12: 172.16.253.89 | G12: fe80:0:0:0:250:56ff:fe9d:1a13 | H12: Linux / Server | I12: Debian Project Debian Buster 10.13 | J12: 10.13 | K12: EOL/EOS | L12: Virtualized / Virtual Machine | M12: VMware VMware Virtual Platform VMware Virtual Platform | N12: Unknown | O12: 4 | P12: 2400 | Q12: Intel(R) Xeon(R) CPU E5-4640 0 @ 2.40GHz | R12: 7978 | S12: Phoenix Technologies LTD 6.00 12/12/2018 | T12: VMware-42 1d 42 cd c3 6d 55 4f-90 63 2f 10 9a ad c3 8a | U12: No Asset Tag | V12: '-03:00 | W12: Nov 13, 2024 | X12: sysgru | Y12: QAGENT | Z12: 0c0abaf4-80a6-4299-82de-332bd46f9992 | AA12: Jan 31, 2025 | AB12: x86_64 | AC12: VM,SCA,PM | AD12: Cloud Agent | AE12: 1 | AF12: 71 | AG12: cd421d42-6dc3-4f55-9063-2f109aadc38a | AH12: Jan 31, 2025 | AI12: Cloud Agent,GRU-GERAL,GRU-CAT-Servidores
A13: 20891478 | B13: sprdbdoragru04 | C13: 7478080 | D13: '- | E13: b8:ca:3a:33:8e:a8,b8:ca:3a:33:8e:a8,b8:ca:3a:33:8e:a8,b8:ca:3a:33:8e:a8,b8:ca:3a:33:8e:a8,b8:ca:3a:33:8e:a8 | F13: 10.1.1.17,169.254.249.133,172.31.49.91,172.31.49.141,172.31.49.145 | G13: fe80:0:0:0:baca:3aff:fe33:8ea8 | H13: Linux / Server | I13: Red Hat Enterprise Linux Server 6 6.10 | J13: 6.10 | K13: EOL/EOS | L13: Computers / Server | M13: Dell PowerEdge M820 | N13: EOS | O13: 32 | P13: 2400 | Q13: Intel(R) Xeon(R) CPU E5-4640 0 @ 2.40GHz | R13: 258423 | S13: Dell Inc. 2.2.2 07/02/2014 | T13: JHSR9X1 | U13: '- | V13: '-03:00 | W13: Dec 6, 2024 | X13: root | Y13: QAGENT | Z13: b5e5b4ac-2f9e-4336-b1cf-95477d2c27f4 | AA13: Jan 31, 2025 | AB13: x86_64 | AC13: VM,SCA,PM | AD13: Cloud Agent | AE13: 5 | AF13: 858 | AG13: 44454c4c-4800-1053-8052-cac04f395831 | AH13: Jan 31, 2025 | AI13: Cloud Agent,GRU_ACN_5-Catastrofico,GRU-GERAL,GRU_CAT_ACN-CMS
A14: 20890762 | B14: SPRDAPCCPRGRU02 | C14: 7477756 | D14: '- | E14: 00:50:56:92:3e:7f,52:54:00:9c:ff:62,00:50:56:92:3e:7f | F14: 172.31.49.139,192.168.122.1 | G14: fe80:0:0:0:250:56ff:fe92:3e7f | H14: Linux / Server | I14: Red Hat Enterprise Linux 8 8.8 | J14: 8.8 | K14: EOL | L14: Virtualized / Virtual Machine | M14: VMware VMware Virtual Platform VMware Virtual Platform | N14: Unknown | O14: 2 | P14: 2600 | Q14: Intel(R) Xeon(R) Gold 6348 CPU @ 2.60GHz | R14: 3634 | S14: Phoenix Technologies LTD 6.00 11/12/2020 | T14: VMware-42 12 8b b6 e3 6a 87 49-14 d7 d0 10 b3 c9 8a ca | U14: No Asset Tag | V14: '-03:00 | W14: Aug 9, 2024 | X14: root | Y14: QAGENT | Z14: f10fd344-5d8e-4a00-a536-1da519704e40 | AA14: Jan 31, 2025 | AB14: x86_64 | AC14: VM,SCA,PM | AD14: Cloud Agent | AE14: 5 | AF14: 848 | AG14: b68b1242-6ae3-4987-14d7-d010b3c98aca | AH14: Jan 31, 2025 | AI14: Cloud Agent,GRU_ACN_5-Catastrofico,GRU-GERAL,GRU_CAT_ACN-TARIFAGRU
A15: 118300643 | B15: sprdapzbpxgru02 | C15: 32350692 | D15: '- | E15: 00:50:56:b6:8e:0a,00:50:56:b6:4a:e2 | F15: 172.16.1.99,172.16.253.91 | H15: Linux / Unidentified | I15: Canonical Ubuntu Focal Fossa 20.04 LTS 20.04.6 LTS | J15: 20.04 LTS | K15: GA | L15: Virtualized / Virtual Machine | M15: VMware VMware Virtual Platform VMware Virtual Platform | N15: Unknown | O15: 2 | P15: 2400 | Q15: Intel(R) Xeon(R) CPU E5-4640 0 @ 2.40GHz | R15: 3889 | S15: Phoenix Technologies LTD 6.00 12/12/2018 | T15: VMware-42 36 b4 8e b6 59 b1 dc-9c d7 e4 c9 80 d6 96 6b | U15: No Asset Tag | V15: '-03:00 | W15: Aug 23, 2023 | X15: sysgru | Y15: QAGENT | Z15: faf60259-a9dd-475f-a140-ebdd2171d3fe | AA15: Jan 31, 2025 | AB15: x86_64 | AC15: VM,SCA,PM | AD15: Cloud Agent | AE15: 1 | AF15: 121 | AG15: 8eb43642-59b6-dcb1-9cd7-e4c980d6966b | AH15: Jan 31, 2025 | AI15: Cloud Agent,GRU-GERAL,GRU-CAT-Servidores
A16: 20192421 | B16: SAD2-GRU | C16: 7377597 | D16: SAD2-GRU | E16: 9A:B2:5B:E1:9F:35,9A:B2:5B:E1:9F:35 | F16: 172.31.50.21 | G16: fe80:0:0:0:df9:ac18:e17c:6e7d | H16: Windows / Server | I16: Microsoft Windows Server 2008 R2 Standard 6.1 SP1 Build 7601.24559 | J16: 6.1 | K16: EOL/EOS | L16: Virtualized / Virtual Machine | M16: VMware VMware Virtual Platform VMware Virtual Platform | N16: Unknown | O16: 4 | P16: 2593 | Q16: Intel(R) Xeon(R) Gold 6348 CPU @ 2.60GHz | R16: 10239 | S16: Phoenix Technologies LTD 6.00 | T16: VMware-42 23 84 96 0a c8 5f 48-e8 17 87 a6 b4 b3 1b a5 | U16: NoAssetTag | V16: '-03:00 | W16: Dec 20, 2024 | X16: GRU\sistemas.gru | Y16: QAGENT | Z16: 227465a7-c1fd-4eb8-a30b-f53b35c13485 | AA16: Jan 31, 2025 | AB16: 64-bit | AC16: VM,SCA,PM | AD16: Cloud Agent | AE16: 5 | AF16: 875 | AG16: 96842342-C80A-485F-E817-87A6B4B31BA5 | AH16: Jan 31, 2025 | AI16: Cloud Agent,GRU_ACN_5-Catastrofico,GRU-GERAL,GRU_CAT_ACN-INFRACRITICA
A17: 20893218 | B17: sprdbdoragru05 | C17: 7478657 | D17: '- | E17: b8:ca:3a:35:19:e8,b8:ca:3a:35:19:e8,b8:ca:3a:35:19:e8,b8:ca:3a:35:19:e8,b8:ca:3a:35:19:e8,b8:ca:3a:35:19:e8,b8:ca:3a:35:19:e8 | F17: 10.1.1.18,169.254.196.231,172.31.49.92,172.31.49.142,172.31.49.143,172.31.49.144 | G17: fe80:0:0:0:baca:3aff:fe35:19e8 | H17: Linux / Server | I17: Red Hat Enterprise Linux Server 6 6.10 | J17: 6.10 | K17: EOL/EOS | L17: Computers / Server | M17: Dell PowerEdge M820 | N17: EOS | O17: 32 | P17: 2400 | Q17: Intel(R) Xeon(R) CPU E5-4640 0 @ 2.40GHz | R17: 258278 | S17: Dell Inc. 2.0.24 01/21/2014 | T17: 267GY12 | U17: '- | V17: '-03:00 | W17: Nov 17, 2023 | X17: oracle | Y17: QAGENT | Z17: f42786ee-6db5-49a4-bfac-ece221d27a0b | AA17: Jan 31, 2025 | AB17: x86_64 | AC17: VM,SCA,PM | AD17: Cloud Agent | AE17: 5 | AF17: 861 | AG17: 44454c4c-3600-1037-8047-b2c04f593132 | AH17: Jan 31, 2025 | AI17: Cloud Agent,GRU_ACN_5-Catastrofico,GRU-GERAL,GRU_CAT_ACN-CMS
A18: 36002054 | B18: SPRDAPRPGRU08 | C18: 9898114 | D18: SPRDAPRPGRU08 | E18: 00:50:56:92:24:F1,00:50:56:92:24:F1 | F18: 192.168.1.87 | G18: fe80:0:0:0:d8d:81a6:f1e0:4b56 | H18: Windows / Server | I18: Microsoft Windows Server 2012 R2 Datacenter 6.3 Build 9600.19356 64-Bit | J18: 6.3 | K18: EOL/EOS | L18: Virtualized / Virtual Machine | M18: VMware VMware Virtual Platform VMware Virtual Platform | N18: Unknown | O18: 4 | P18: 2594 | Q18: Intel(R) Xeon(R) Gold 6348 CPU @ 2.60GHz | R18: 16383 | S18: Phoenix Technologies LTD 6.00 | T18: VMware-42 12 09 67 fe 2c 32 18-91 3f 27 60 53 4c 6a f8 | U18: NoAssetTag | V18: '-03:00 | W18: Jan 3, 2025 | X18: svc-rp | Y18: QAGENT | Z18: 0063da12-0910-43aa-a9de-5bf1394392e2 | AA18: Jan 31, 2025 | AB18: 64-bit | AC18: VM,SCA,PM | AD18: Cloud Agent | AE18: 3 | AF18: 524 | AG18: 67091242-2CFE-1832-913F-2760534C6AF8 | AH18: Jan 31, 2025 | AI18: Cloud Agent,GRU_ACN_3-Maior,GRU-GERAL,GRU_CAT_ACN-INFRACRITICA
A19: 25379848 | B19: SPRDAPCMSGRU08 | C19: 8140546 | D19: '- | E19: 54:9f:35:71:d9:da,54:9f:35:71:d9:d7,52:54:00:db:b5:83 | F19: 172.31.49.127,172.31.49.199,192.168.122.1 | H19: Linux / Server | I19: Red Hat Enterprise Linux 8 8.7 | J19: 8.7 | K19: EOL/EOS | L19: Computers / Server | M19: Dell PowerEdge M620 | N19: EOS | O19: 24 | P19: 2200 | Q19: Intel(R) Xeon(R) CPU E5-2660 v2 @ 2.20GHz | R19: 64092 | S19: Dell Inc. 2.9.0 01/08/2020 | T19: 7M24012 | U19: '- | V19: '-03:00 | W19: Apr 6, 2023 | X19: root | Y19: QAGENT | Z19: 8ca613b0-92c1-41be-a3d3-65a34f2f0054 | AA19: Jan 31, 2025 | AB19: x86_64 | AC19: VM,SCA,PM | AD19: Cloud Agent | AE19: 4 | AF19: 688 | AG19: 4c4c4544-004d-3210-8034-b7c04f303132 | AH19: Jan 31, 2025 | AI19: Cloud Agent,GRU_ACN_4-Perigoso,GRU-GERAL,GRU_CAT_ACN-CMS
A20: 57563324 | B20: sprdapprmgru01 | C20: 13633900 | D20: '- | E20: 00:50:56:b6:13:3d,00:50:56:b6:13:3d | F20: 172.31.50.167 | G20: fe80:0:0:0:250:56ff:feb6:133d | H20: Linux / Unidentified | I20: Canonical Ubuntu Jammy Jellyfish 22.04 LTS 22.04.4 LTS | J20: 22.04 LTS | K20: GA | L20: Virtualized / Virtual Machine | M20: VMware VMware Virtual Platform VMware Virtual Platform | N20: Unknown | O20: 2 | P20: 2400 | Q20: Intel(R) Xeon(R) CPU E5-4640 0 @ 2.40GHz | R20: 3876 | S20: Phoenix Technologies LTD 6.00 12/12/2018 | T20: VMware-42 36 91 4b 7a 2f ef 6d-58 45 0a ec 60 64 b1 85 | U20: No Asset Tag | V20: '-03:00 | W20: Mar 8, 2024 | X20: root | Y20: QAGENT | Z20: 9d300e92-9025-4d5c-bb45-692ba38b1201 | AA20: Jan 31, 2025 | AB20: x86_64 | AC20: VM,SCA,PM | AD20: Cloud Agent | AE20: 1 | AF20: 126 | AG20: 4b913642-2f7a-6def-5845-0aec6064b185 | AH20: Jan 31, 2025 | AI20: Cloud Agent,GRU-GERAL,GRU-CAT-Servidores
A21: 109876158 | B21: SENHASEGURA_ARBRITO | C21: 28361853 | D21: '- | E21: 02:42:07:84:4b:40,00:50:56:92:1d:56,00:50:56:92:1d:56 | F21: 172.17.0.1,172.31.46.24 | G21: fe80:0:0:0:e724:c925:2674:9f4f | H21: Linux / Server | I21: The CentOS Project CentOS 7 7.9 2009 | J21: 7.9 | K21: EOL/EOS | L21: Virtualized / Virtual Machine | M21: VMware VMware Virtual Platform VMware Virtual Platform | N21: Unknown | O21: 2 | P21: 2600 | Q21: Intel(R) Xeon(R) Gold 6348 CPU @ 2.60GHz | R21: 7802 | S21: Phoenix Technologies LTD 6.00 11/12/2020 | T21: VMware-42 12 a3 6a 45 fd a8 2d-84 47 c8 09 f8 9a 94 8a | U21: No Asset Tag | V21: '-03:00 | W21: Aug 13, 2024 | X21: root | Y21: QAGENT | Z21: 41d690ac-bd73-4ec3-94f0-4d362c362a0d | AA21: Jan 31, 2025 | AB21: x86_64 | AC21: VM,SCA,PM | AD21: Cloud Agent | AE21: 4 | AF21: 294 | AG21: 6aa31242-fd45-2da8-8447-c809f89a948a | AH21: Jan 31, 2025 | AI21: Cloud Agent,GRU_ACN_4-Perigoso,GRU-GERAL,GRU_CAT_ACN-INFRACRITICA
A22: 109197702 | B22: sprdapzbpxgru01 | C22: 28073442 | D22: '- | E22: 00:50:56:b6:1a:82,00:50:56:b6:1a:82 | F22: 172.16.253.84 | G22: fe80:0:0:0:250:56ff:feb6:1a82 | H22: Linux / Unidentified | I22: Canonical Ubuntu Focal Fossa 20.04 LTS 20.04.6 LTS | J22: 20.04 LTS | K22: GA | L22: Virtualized / Virtual Machine | M22: VMware VMware Virtual Platform VMware Virtual Platform | N22: Unknown | O22: 8 | P22: 2400 | Q22: Intel(R) Xeon(R) CPU E5-4640 0 @ 2.40GHz | R22: 9918 | S22: Phoenix Technologies LTD 6.00 12/12/2018 | T22: VMware-42 36 14 85 5a d8 23 a6-a8 ae a2 48 0c f2 49 f9 | U22: No Asset Tag | V22: '-03:00 | W22: Aug 21, 2024 | X22: root | Y22: QAGENT | Z22: 5d9a1324-8185-41d5-8c7a-a7027b98e681 | AA22: Jan 31, 2025 | AB22: x86_64 | AC22: VM,SCA,PM | AD22: Cloud Agent | AE22: 1 | AF22: 24 | AG22: 85143642-d85a-a623-a8ae-a2480cf249f9 | AH22: Jan 31, 2025 | AI22: Cloud Agent,GRU-GERAL,GRU-CAT-Servidores
A23: 109828633 | B23: SPRDAPVPRGRU04 | C23: 28345336 | D23: '- | E23: 00:50:56:b6:d3:0a,00:50:56:b6:d3:0a | F23: 172.31.62.196 | G23: fe80:0:0:0:250:56ff:feb6:d30a | H23: Linux / Server | I23: SUSE Linux Enterprise Server 12 12 SP5 | J23: 12 | K23: EOL | L23: Virtualized / Virtual Machine | M23: VMware VMware Virtual Platform VMware Virtual Platform | N23: Unknown | O23: 4 | P23: 2400 | Q23: Intel(R) Xeon(R) CPU E5-4640 0 @ 2.40GHz | R23: 7858 | S23: Phoenix Technologies LTD 6.00 12/12/2018 | T23: VMware-42 36 0b ef 2a 0a 87 1a-a4 6d 61 b4 5f 12 4f eb | U23: No Asset Tag | V23: '-03:00 | W23: Jul 30, 2024 | X23: admin | Y23: QAGENT | Z23: 4c27d44b-73eb-407d-a68c-5c7b369f1085 | AA23: Jan 31, 2025 | AB23: x86_64 | AC23: VM,SCA,PM | AD23: Cloud Agent | AE23: 1 | AF23: 168 | AG23: 42360BEF-2A0A-871A-A46D-61B45F124FEB | AH23: Jan 31, 2025 | AI23: Cloud Agent,GRU-GERAL,GRU-CAT-Servidores
A24: 24383683 | B24: SPRDAPFSCCGRU01 | C24: 7904476 | D24: SPRDAPFSCCGRU01 | E24: 00:50:56:9D:7E:EF,00:50:56:9D:7E:EF | F24: 172.31.49.237 | G24: fe80:0:0:0:5486:4109:1eee:d243 | H24: Windows / Server | I24: Microsoft Windows Server 2008 R2 Enterprise 6.1 SP1 Build 7601.24533 | J24: 6.1 | K24: EOL/EOS | L24: Virtualized / Virtual Machine | M24: VMware VMware Virtual Platform VMware Virtual Platform | N24: Unknown | O24: 8 | P24: 2400 | Q24: Intel(R) Xeon(R) CPU E5-4640 0 @ 2.40GHz | R24: 8191 | S24: Phoenix Technologies LTD 6.00 | T24: VMware-56 4d e2 6d 8a 3d 8e c3-e4 20 d7 cf f1 11 f8 fb | U24: NoAssetTag | V24: '-03:00 | W24: Oct 18, 2023 | X24: gru.local\sistemas.gru | Y24: QAGENT | Z24: 352be47d-695f-4e2e-a837-a2211937686f | AA24: Jan 31, 2025 | AB24: 64-bit | AC24: VM,SCA,PM | AD24: Cloud Agent | AE24: 1 | AF24: 173 | AG24: 6de24d56-3d8a-c38e-e420-d7cff111f8fb | AH24: Jan 31, 2025 | AI24: Cloud Agent,GRU-GERAL,GRU-CAT-Servidores
A25: 131535799 | B25: SHOMAPIHSGRU02 | C25: 34405932 | D25: '- | E25: 00:50:56:b6:ef:7c,00:50:56:b6:ef:7c | F25: 172.31.52.53 | G25: fe80:0:0:0:250:56ff:feb6:ef7c | H25: Linux / Server | I25: Red Hat Enterprise Linux 9 9.5 | J25: 9.5 | K25: GA | L25: Virtualized / Virtual Machine | M25: VMware VMware Virtual Platform VMware Virtual Platform | N25: Unknown | O25: 1 | P25: 2400 | Q25: Intel(R) Xeon(R) CPU E5-4640 0 @ 2.40GHz | R25: 3625 | S25: VMware, Inc. VMW71.00V.0.B64.1903020819 03/02/2019 | T25: VMware-42 36 c2 e7 67 3b cb 48-11 14 59 d2 30 cc f7 4e | U25: No Asset Tag | V25: '-03:00 | W25: Jan 21, 2025 | X25: sysgru | Y25: QAGENT | Z25: 59d637ef-ba1b-4b93-8720-6a7df4b0b561 | AA25: Jan 31, 2025 | AB25: x86_64 | AC25: VM,SCA,PM | AD25: Cloud Agent | AE25: 1 | AF25: 67 | AG25: e7c23642-3b67-48cb-1114-59d230ccf74e | AH25: Jan 31, 2025 | AI25: Cloud Agent,GRU-GERAL,GRU-CAT-Servidores
A26: 20890737 | B26: SPRDAPCMSGRU05 | C26: 7477605 | D26: '- | E26: b8:ca:3a:35:1a:6a,b8:ca:3a:35:1a:6a | F26: 172.31.49.90 | G26: fe80:0:0:0:baca:3aff:fe35:1a6a | H26: Linux / Server | I26: Red Hat Enterprise Linux Server 6 6.10 | J26: 6.10 | K26: EOL/EOS | L26: Computers / Server | M26: Dell PowerEdge M620 | N26: EOS | O26: 24 | P26: 2500 | Q26: Intel(R) Xeon(R) CPU E5-2640 0 @ 2.50GHz | R26: 129022 | S26: Dell Inc. 2.5.2 02/03/2015 | T26: FZ3PKZ1 | U26: '- | V26: '-03:00 | W26: Jul 26, 2023 | X26: root | Y26: QAGENT | Z26: 95fadd06-dba1-4317-be72-33b093948bed | AA26: Jan 31, 2025 | AB26: x86_64 | AC26: VM,SCA,PM | AD26: Cloud Agent | AE26: 5 | AF26: 867 | AG26: 44454c4c-5a00-1033-8050-c6c04f4b5a31 | AH26: Jan 31, 2025 | AI26: Cloud Agent,GRU_ACN_5-Catastrofico,GRU-GERAL,GRU_CAT_ACN-CMS
A27: 131557546 | B27: SPRDAPIHSGRU03 | C27: 34405934 | D27: '- | E27: 00:50:56:a3:79:bb,00:50:56:a3:79:bb | F27: 192.168.0.55 | G27: fe80:0:0:0:250:56ff:fea3:79bb | H27: Linux / Server | I27: Red Hat Enterprise Linux 9 9.5 | J27: 9.5 | K27: GA | L27: Virtualized / Virtual Machine | M27: VMware VMware Virtual Platform VMware Virtual Platform | N27: Unknown | O27: 2 | P27: 2600 | Q27: Intel(R) Xeon(R) Gold 6348 CPU @ 2.60GHz | R27: 7907 | S27: VMware, Inc. VMW201.00V.20829224.B64.2211211842 11/21/2022 | T27: VMware-42 23 19 81 13 ee f7 2a-04 42 66 6d a8 45 82 0c | U27: No Asset Tag | V27: '-03:00 | W27: Jan 29, 2025 | X27: sysgru | Y27: QAGENT | Z27: f7fb72cc-3e93-4596-939c-35ef98655c6a | AA27: Jan 31, 2025 | AB27: x86_64 | AC27: VM,SCA,PM | AD27: Cloud Agent | AE27: 1 | AF27: 67 | AG27: 81192342-ee13-2af7-0442-666da845820c | AH27: Jan 31, 2025 | AI27: Cloud Agent,GRU-GERAL,GRU-CAT-Servidores
A28: 27895381 | B28: sprdbdotrsgru02 | C28: 8497827 | D28: '- | E28: 00:50:56:b6:10:c2,00:50:56:b6:10:c2 | F28: 172.31.49.229 | G28: fe80:0:0:0:250:56ff:feb6:10c2 | H28: Linux / Unidentified | I28: Canonical Ubuntu Focal Fossa 20.04 LTS 20.04.5 LTS | J28: 20.04 LTS | K28: GA | L28: Virtualized / Virtual Machine | M28: VMware VMware Virtual Platform VMware Virtual Platform | N28: Unknown | O28: 8 | P28: 2400 | Q28: Intel(R) Xeon(R) CPU E5-4640 0 @ 2.40GHz | R28: 11934 | S28: Phoenix Technologies LTD 6.00 12/12/2018 | T28: VMware-42 36 50 7c aa 08 48 71-f9 71 86 92 5c c8 08 d8 | U28: No Asset Tag | V28: UTC | W28: Nov 16, 2023 | X28: root | Y28: QAGENT | Z28: c585a953-7db0-475e-a042-c75ae42fea5b | AA28: Jan 31, 2025 | AB28: x86_64 | AC28: VM,SCA,PM | AD28: Cloud Agent | AE28: 1 | AF28: 167 | AG28: 7c503642-08aa-7148-f971-86925cc808d8 | AH28: Jan 31, 2025 | AI28: Cloud Agent,GRU-GERAL,GRU-CAT-Servidores
A29: 20293585 | B29: SPRDAPHSEGRU01 | C29: 7395725 | D29: SPRDAPHSEGRU01 | E29: 00:50:56:92:5D:D0,00:50:56:92:5D:D0 | F29: 172.31.49.22 | G29: fe80:0:0:0:48de:5679:801e:a65e | H29: Windows / Server | I29: Microsoft Windows Server 2016 Datacenter 1607 Build 14393.6452 64-Bit | J29: 1607 | K29: EOL | L29: Virtualized / Virtual Machine | M29: VMware VMware Virtual Platform VMware Virtual Platform | N29: Unknown | O29: 16 | P29: 2594 | Q29: Intel(R) Xeon(R) Gold 6348 CPU @ 2.60GHz | R29: 12287 | S29: Phoenix Technologies LTD 6.00 | T29: VMware-42 12 7d aa 63 ef db 8e-9c 01 8e a8 0c 98 83 6d | U29: NoAssetTag | V29: '-03:00 | W29: Aug 9, 2024 | X29: GRU\sistemas.gru | Y29: QAGENT | Z29: 040738ab-cd44-4a08-af7a-99f7d0ba2e71 | AA29: Jan 31, 2025 | AB29: 64-bit | AC29: VM,SCA,PM | AD29: Cloud Agent | AE29: 3 | AF29: 513 | AG29: AA7D1242-EF63-8EDB-9C01-8EA80C98836D | AH29: Jan 31, 2025 | AI29: Cloud Agent,GRU_ACN_3-Maior,GRU-GERAL,GRU_CAT_ACN-GPA
A30: 134035420 | B30: SPRDAPRPGRU15 | C30: 35038549 | D30: '- | E30: 00:50:56:a3:e2:dc,00:50:56:a3:e2:dc | F30: 192.168.0.25 | G30: fe80:0:0:0:250:56ff:fea3:e2dc | H30: Linux / Server | I30: Red Hat Enterprise Linux 9 9.5 | J30: 9.5 | K30: GA | L30: Virtualized / Virtual Machine | M30: VMware VMware Virtual Platform VMware Virtual Platform | N30: Unknown | O30: 4 | P30: 2600 | Q30: Intel(R) Xeon(R) Gold 6348 CPU @ 2.60GHz | R30: 7651 | S30: VMware, Inc. VMW201.00V.20829224.B64.2211211842 11/21/2022 | T30: VMware-42 23 ea 03 be 5e 0f 1a-54 c5 dd 43 7f 7c 58 d0 | U30: No Asset Tag | V30: '-03:00 | W30: Dec 5, 2024 | X30: sysgru | Y30: QAGENT | Z30: 50f26332-a8b5-4300-b67a-58878d0f8c31 | AA30: Jan 31, 2025 | AB30: x86_64 | AC30: VM,SCA,PM | AD30: Cloud Agent | AE30: 1 | AF30: 7 | AG30: 03ea2342-5ebe-1a0f-54c5-dd437f7c58d0 | AH30: Jan 31, 2025 | AI30: Cloud Agent,GRU-GERAL,GRU-CAT-Servidores
A31: 27700453 | B31: sprdsapnasgru01 | C31: 8468939 | D31: '- | E31: 00:50:56:92:07:4e,00:50:56:92:07:4e | F31: 172.31.49.202 | G31: fe80:0:0:0:250:56ff:fe92:74e | H31: Linux / Server | I31: Red Hat Enterprise Linux Server 6 6.6 | J31: 6.6 | K31: EOL/EOS | L31: Virtualized / Virtual Machine | M31: VMware VMware Virtual Platform VMware Virtual Platform | N31: Unknown | O31: 2 | P31: 2100 | Q31: Intel(R) Xeon(R) Platinum 8176 CPU @ 2.10GHz | R31: 7858 | S31: Phoenix Technologies LTD 6.00 11/12/2020 | T31: VMware-42 12 30 53 89 af db 36-00 63 47 9c 72 57 83 ae | U31: No Asset Tag | V31: '-03:00 | W31: Jun 19, 2024 | X31: sysgru | Y31: QAGENT | Z31: 3dbd0f01-7bc4-457d-bc23-4b8caaa759a2 | AA31: Jan 31, 2025 | AB31: x86_64 | AC31: VM,SCA,PM | AD31: Cloud Agent | AE31: 4 | AF31: 698 | AG31: 42123053-89af-db36-0063-479c725783ae | AH31: Jan 31, 2025 | AI31: Cloud Agent,GRU_ACN_4-Perigoso,GRU-GERAL,GRU_CAT_ACN-SAP
A32: 107146571 | B32: PRDRMADS02 | C32: 27527349 | D32: '- | E32: 00:50:56:a3:3f:23,52:54:00:cd:3e:82,00:50:56:a3:3f:23 | F32: 172.31.49.50,192.168.122.1 | G32: fe80:0:0:0:250:56ff:fea3:3f23 | H32: Linux / Server | I32: Red Hat Enterprise Linux 8 8.10 | J32: 8.10 | K32: GA | L32: Virtualized / Virtual Machine | M32: VMware VMware Virtual Platform VMware Virtual Platform | N32: Unknown | O32: 4 | P32: 2600 | Q32: Intel(R) Xeon(R) Gold 6348 CPU @ 2.60GHz | R32: 7665 | S32: Phoenix Technologies LTD 6.00 11/12/2020 | T32: VMware-42 23 f5 74 84 fd 5b a9-f7 8c db 67 cf cd bd a1 | U32: No Asset Tag | V32: '-03:00 | W32: Sep 4, 2024 | X32: root | Y32: QAGENT | Z32: b01f8d7b-9b12-497d-b7b4-7d8305d9a982 | AA32: Jan 31, 2025 | AB32: x86_64 | AC32: VM,SCA,PM | AD32: Cloud Agent | AE32: 1 | AF32: 171 | AG32: 74f52342-fd84-a95b-f78c-db67cfcdbda1 | AH32: Jan 31, 2025 | AI32: Cloud Agent,GRU-GERAL,GRU-CAT-Servidores
A33: 97308191 | B33: SPRDAPSSHGRU01 | C33: 24995962 | D33: '- | E33: 54:9f:35:73:0b:61 | F33: 172.31.49.176 | H33: Linux / Unidentified | I33: Canonical Ubuntu Noble Numbat 24.04 LTS 24.04.1 LTS | J33: 24.04 LTS | K33: GA | L33: Computers / Server | M33: Dell PowerEdge M620 | N33: EOS | O33: 40 | P33: 2200 | Q33: Intel(R) Xeon(R) CPU E5-2660 v2 @ 2.20GHz | R33: 64338 | S33: Dell Inc. 2.4.3 07/02/2014 | T33: HM22012 | U33: '- | V33: '-03:00 | W33: Nov 26, 2024 | X33: sysgru | Y33: QAGENT | Z33: 2528af6c-2461-4ad5-ac05-70de78f179ab | AA33: Jan 31, 2025 | AB33: x86_64 | AC33: VM,SCA,PM | AD33: Cloud Agent | AE33: 1 | AF33: 27 | AG33: 4c4c4544-004d-3210-8032-c8c04f303132 | AH33: Jan 31, 2025 | AI33: Cloud Agent,GRU-GERAL,GRU-CAT-Servidores
A34: 107596735 | B34: DESKTOP-5IFR8I7 | C34: 27727654 | D34: GRU-VIG-BGBCSV1 | E34: 5C:F9:DD:ED:87:79,5C:F9:DD:ED:87:79 | F34: 10.11.13.140 | G34: fe80:0:0:0:cf04:d97a:5635:a49c | H34: Windows / Client | I34: Microsoft Windows 10 Pro 22H2 Build 19045.4894 64-Bit | J34: 22H2 | K34: GA | L34: Computers / Desktop | M34: Dell OptiPlex 3010 | N34: EOS | O34: 4 | P34: 3201 | Q34: Intel(R) Core(TM) i5-3470 CPU @ 3.20GHz | R34: 8162 | S34: Dell Inc. A22 | T34: BGBCSV1 | U34: '- | V34: '-03:00 | W34: Dec 20, 2024 | X34: VIGIAGRO | Y34: QAGENT | Z34: 808f514e-c6da-4f5b-8f3b-892e8ae094b1 | AA34: Jan 31, 2025 | AB34: 64 bits | AC34: VM,SCA,PM | AD34: Cloud Agent | AE34: 1 | AF34: 177 | AG34: 4C4C4544-0047-4210-8043-C2C04F535631 | AH34: Jan 31, 2025 | AI34: Cloud Agent,GRU-GERAL,GRU-CAT-Workstation
A35: 96870252 | B35: sprdappigru01 | C35: 24873330 | D35: '- | E35: 54:9f:35:73:10:7f,54:9f:35:73:0b:af,54:9f:35:73:0b:af,54:9f:35:73:10:7f | F35: 10.1.1.89,172.31.49.155 | G35: fe80:0:0:0:569f:35ff:fe73:baf,fe80:0:0:0:569f:35ff:fe73:107f | H35: Linux / Server | I35: Red Hat Enterprise Linux Server 6 6.6 | J35: 6.6 | K35: EOL/EOS | L35: Computers / Server | M35: Dell PowerEdge M620 | N35: EOS | O35: 12 | P35: 2600 | Q35: Intel(R) Xeon(R) CPU E5-2630 v2 @ 2.60GHz | R35: 64387 | S35: Dell Inc. 2.4.3 07/02/2014 | T35: 31MNF22 | U35: '- | V35: '-03:00 | W35: Oct 11, 2024 | X35: sysgru | Y35: QAGENT | Z35: a8e43ba7-8db5-4115-81c0-d73b6ee9af5c | AA35: Jan 31, 2025 | AB35: x86_64 | AC35: VM,SCA,PM | AD35: Cloud Agent | AE35: 1 | AF35: 175 | AG35: 44454c4c-3100-104d-804e-b3c04f463232 | AH35: Jan 31, 2025 | AI35: Cloud Agent,GRU_ACN_1-Insignificante,GRU-GERAL,GRU_CAT_ACN-SAP
A36: 142172320 | B36: SPRDMYSQLGRU02 | C36: 38417552 | D36: '- | E36: 00:50:56:9d:4f:75 | F36: 172.16.253.90 | H36: Linux / Server | I36: Red Hat Enterprise Linux Server 7 7.9 | J36: 7.9 | K36: EOL/EOS | L36: Virtualized / Virtual Machine | M36: VMware VMware Virtual Platform VMware Virtual Platform | N36: Unknown | O36: 4 | P36: 2400 | Q36: Intel(R) Xeon(R) CPU E5-4640 0 @ 2.40GHz | R36: 7821 | S36: Phoenix Technologies LTD 6.00 12/12/2018 | T36: VMware-56 4d 42 27 e7 67 e6 f1-0f 0a f3 61 cc dd 0d 6f | U36: No Asset Tag | V36: '-03:00 | W36: Nov 18, 2024 | X36: sysgru | Y36: QAGENT | Z36: fcad08a7-cf35-4635-9756-4916b9df6094 | AA36: Jan 31, 2025 | AB36: x86_64 | AC36: VM,PM | AD36: Cloud Agent | AE36: 1 | AF36: 170 | AG36: 564d4227-e767-e6f1-0f0a-f361ccdd0d6f | AH36: Jan 31, 2025 | AI36: Cloud Agent,GRU-GERAL,GRU-CAT-Servidores
A37: 118288358 | B37: shombdoragru01 | C37: 32350690 | D37: '- | E37: b8:ca:3a:33:8f:3a,b8:ca:3a:33:8f:3a,b8:ca:3a:33:8f:37,b8:ca:3a:33:8f:37,b8:ca:3a:33:8f:37,b8:ca:3a:33:8f:37,b8:ca:3a:33:8f:37,b8:ca:3a:33:8f:3a | F37: 10.1.1.9,169.254.27.150,172.31.52.60,172.31.52.63,172.31.52.66,172.31.52.67 | G37: fe80:0:0:0:baca:3aff:fe33:8f37,fe80:0:0:0:baca:3aff:fe33:8f3a | H37: Linux / Server | I37: Red Hat Enterprise Linux Server 6 6.5 | J37: 6.5 | K37: EOL/EOS | L37: Computers / Server | M37: Dell PowerEdge M620 | N37: EOS | O37: 32 | P37: 2700 | Q37: Intel(R) Xeon(R) CPU E5-2680 0 @ 2.70GHz | R37: 64377 | S37: Dell Inc. 2.5.4 01/27/2016 | T37: 7H4PKZ1 | U37: '- | V37: '-02:00 | W37: Feb 21, 2024 | X37: sysgru | Y37: QAGENT | Z37: ffb71dfc-e08c-4773-9d6d-2e9dc80dcfc2 | AA37: Jan 31, 2025 | AB37: x86_64 | AC37: VM,SCA,PM | AD37: Cloud Agent | AE37: 1 | AF37: 174 | AG37: 44454c4c-4800-1034-8050-b7c04f4b5a31 | AH37: Jan 31, 2025 | AI37: Cloud Agent,GRU-GERAL,GRU-CAT-Servidores
A38: 118300234 | B38: shombdoragru02 | C38: 30629851 | D38: '- | E38: b8:ca:3a:35:1a:7a,b8:ca:3a:35:1a:7a,b8:ca:3a:35:1a:77,b8:ca:3a:35:1a:77,b8:ca:3a:35:1a:77,b8:ca:3a:35:1a:77,b8:ca:3a:35:1a:7a | F38: 10.1.1.10,169.254.64.50,172.31.52.61,172.31.52.64,172.31.52.65 | G38: fe80:0:0:0:baca:3aff:fe35:1a77,fe80:0:0:0:baca:3aff:fe35:1a7a | H38: Linux / Server | I38: Red Hat Enterprise Linux Server 6 6.10 | J38: 6.10 | K38: EOL/EOS | L38: Computers / Server | M38: Dell PowerEdge M620 | N38: EOS | O38: 32 | P38: 2700 | Q38: Intel(R) Xeon(R) CPU E5-2680 0 @ 2.70GHz | R38: 64377 | S38: Dell Inc. 2.5.4 01/27/2016 | T38: 802PKZ1 | U38: '- | V38: '-03:00 | W38: Nov 9, 2024 | X38: sysgru | Y38: QAGENT | Z38: 669bb8ac-1b2c-41b4-8f0e-b35c1719fd97 | AA38: Jan 31, 2025 | AB38: x86_64 | AC38: VM,SCA,PM | AD38: Cloud Agent | AE38: 1 | AF38: 173 | AG38: 44454c4c-3000-1032-8050-b8c04f4b5a31 | AH38: Jan 31, 2025 | AI38: Cloud Agent,GRU-GERAL,GRU-CAT-Servidores
A39: 25346862 | B39: sprdotrsgru01 | C39: 8133588 | D39: '- | E39: 00:50:56:a3:52:0c,00:50:56:a3:52:0c | F39: 172.31.49.49 | G39: fe80:0:0:0:250:56ff:fea3:520c | H39: Linux / Unidentified | I39: Canonical Ubuntu Focal Fossa 20.04 LTS 20.04.6 LTS | J39: 20.04 LTS | K39: GA | L39: Virtualized / Virtual Machine | M39: VMware VMware Virtual Platform VMware Virtual Platform | N39: Unknown | O39: 8 | P39: 2600 | Q39: Intel(R) Xeon(R) Gold 6348 CPU @ 2.60GHz | R39: 24006 | S39: Phoenix Technologies LTD 6.00 11/12/2020 | T39: VMware-42 23 39 53 a4 68 79 0e-c4 9a 87 fc f6 57 dd 90 | U39: No Asset Tag | V39: '-03:00 | W39: Dec 1, 2024 | X39: root | Y39: QAGENT | Z39: 73c7a656-2a2f-4bbc-ac3d-0a65b38ae4e3 | AA39: Jan 31, 2025 | AB39: x86_64 | AC39: VM,SCA,PM | AD39: Cloud Agent | AE39: 3 | AF39: 73 | AG39: 42233953-a468-790e-c49a-87fcf657dd90 | AH39: Jan 31, 2025 | AI39: Cloud Agent,GRU_ACN_3-Maior,GRU-GERAL,GRU_CAT_ACN-INFRACRITICA
A40: 19242329 | B40: SPRDCCTVGRU20 | C40: 7159514 | D40: SPRDCCTVGRU20 | E40: 00:0A:F7:2F:70:E4,00:0A:F7:2F:70:E4,00:0A:F7:2F:70:E4,00:0A:F7:2F:70:E4,00:0A:F7:2F:70:E7,F0:1F:AF:E1:4F:FB | F40: 10.36.57.100,10.36.57.110,10.36.57.111,10.36.57.112,10.36.60.100,10.36.61.100 | H40: Windows / Server | I40: Microsoft Windows Server 2019 Datacenter 1809 Build 17763.4252 64-Bit | J40: 1809 | K40: EOL | L40: Computers / Server | M40: '- | N40: Not Applicable | O40: 12 | P40: 2200 | Q40: Intel(R) Xeon(R) CPU E5-2430 0 @ 2.20GHz | R40: 32723 | S40: 2.9.0 | T40: 4LM1DZ1 | U40: '- | V40: '-03:00 | W40: Nov 15, 2024 | X40: GRU\svc-sql-cluster | Y40: QAGENT | Z40: 05d1d5cb-9e12-40b9-8d9c-9839f1cf66b9 | AA40: Jan 31, 2025 | AB40: 64-bit | AC40: VM,SCA,PM | AD40: Cloud Agent | AE40: 4 | AF40: 683 | AG40: 4c4c4544-004c-4d10-8031-b4c04f445a31 | AH40: Jan 31, 2025 | AI40: Cloud Agent,GRU_ACN_4-Perigoso,GRU-GERAL,GRU_CAT_ACN-CFTV
...

Sheet Sentinel
A1: Endpoint Name | B1: Site | C1: Last Logged In User | D1: OS Username | E1: Group | F1: Tags | G1: Domain | H1: Account | I1: Console Visible IP | J1: Agent Version | K1: Serial Number | L1: Subscribed On | M1: Device Type | N1: Model Name | O1: OS | P1: OS Version | Q1: Architecture | R1: Memory | S1: CPU Count | T1: CPU Type | U1: Core Count | V1: Management Connectivity | W1: Network Status | X1: Update Status | Y1: Scan Status | Z1: Last Reported IP | AA1: Pending Uninstall | AB1: Disk Encryption | AC1: Agent UUID | AD1: Agent ID | AE1: Customer Identifier | AF1: Console Migration Status | AG1: Operational State | AH1: Operational State Expiration | AI1: Last Reboot Date | AJ1: Installer Type | AK1: Reboot Required due to Threat | AL1: User Action Required | AM1: Remote Profiling State | AN1: Remote Profiling Expiration | AO1: Storage Type | AP1: Storage Name | AQ1: Cloud Account | AR1: Cloud Location | AS1: Cloud Network | AT1: Cloud Image | AU1: Cloud Tags | AV1: Cloud Instance Size | AW1: Cloud Instance ID | AX1: Cloud Security Group | AY1: Cluster Name | AZ1: K8s Type | BA1: K8s Version | BB1: Agent Namespace | BC1: Agent Pod Name | BD1: K8s Node Name | BE1: K8s Node Labels | BF1: ECS Type | BG1: ECS Version | BH1: ECS Cluster Name | BI1: ECS Task Arn | BJ1: ECS Task Availability Zone | BK1: ECS Service Name | BL1: ECS Service Arn | BM1: ECS Task Definition Family | BN1: ECS Task Definition Revision | BO1: ECS Task Definition Arn | BP1: Is Uninstalled | BQ1: Decommissioned at | BR1: Missing Permissions
A2: SPRDAPRPGRU15 | B2: Default site | C2: N/A | D2: root | E2: SERVIDORES LINUX | F2: None | G2: unknown | H2: GRUPO INVEPAR | I2: 177130117155 | J2: 24.1.1.16 | K2: N/A | L2: Oct 22, 2024 08:47:10 PM | M2: server | N2: VMware, Inc. VMware20,1 | O2: Linux | P2: Linux,Red Hat Enterprise release 9.5 (Plow) 5.14.0-503.15.1.el9_5.x86_64 | Q2: 64 bit | R2: 7 GB | S2: 2 | T2: Intel(R) Xeon(R) Gold 6348 CPU @ 2.60GHz | U2: 4 | V2: Online | W2: Connected | X2: Up to date | Y2: Completed( Oct 22, 2024 09:04:41 PM ) | Z2: 192.168.0.25 | AA2: No | AB2: Off | AC2: 003a05bc-bdd3-7fdd-6547-cbbef80bce72 | AD2: 2.0669633e+18 | AE2: N/A | AF2: N/A | AG2: Not disabled | AH2: N/A | AI2: Dec 05, 2024 03:22:50 PM | AJ2: RPM | AK2: No | AL2: No | AM2: disabled | AN2: N/A | AO2: N/A | AP2: N/A | AQ2: N/A | AR2: N/A | AS2: N/A | AT2: N/A | AU2: N/A | AV2: N/A | AW2: N/A | AX2: N/A | AY2: N/A | AZ2: N/A | BA2: N/A | BB2: N/A | BC2: N/A | BD2: N/A | BE2: N/A | BF2: N/A | BG2: N/A | BH2: N/A | BI2: N/A | BJ2: N/A | BK2: N/A | BL2: N/A | BM2: N/A | BN2: N/A | BO2: N/A | BP2: No | BQ2: N/A | BR2: N/A
A3: SPRDAPRPGRU14 | B3: Default site | C3: N/A | D3: root | E3: SERVIDORES LINUX | F3: None | G3: unknown | H3: GRUPO INVEPAR | I3: 200.174.72.155 | J3: 24.1.1.16 | K3: N/A | L3: Oct 22, 2024 08:46:31 PM | M3: server | N3: VMware, Inc. VMware20,1 | O3: Linux | P3: Linux,Red Hat Enterprise release 9.5 (Plow) 5.14.0-503.15.1.el9_5.x86_64 | Q3: 64 bit | R3: 7 GB | S3: 2 | T3: Intel(R) Xeon(R) Gold 6348 CPU @ 2.60GHz | U3: 4 | V3: Online | W3: Connected | X3: Up to date | Y3: Completed( Oct 22, 2024 09:00:27 PM ) | Z3: 192.168.0.26 | AA3: No | AB3: Off | AC3: 0044e9ca-ad5f-dc6c-33a5-96c1a5d218f0 | AD3: 2.066963e+18 | AE3: N/A | AF3: N/A | AG3: Not disabled | AH3: N/A | AI3: Dec 05, 2024 01:26:09 PM | AJ3: RPM | AK3: No | AL3: No | AM3: disabled | AN3: N/A | AO3: N/A | AP3: N/A | AQ3: N/A | AR3: N/A | AS3: N/A | AT3: N/A | AU3: N/A | AV3: N/A | AW3: N/A | AX3: N/A | AY3: N/A | AZ3: N/A | BA3: N/A | BB3: N/A | BC3: N/A | BD3: N/A | BE3: N/A | BF3: N/A | BG3: N/A | BH3: N/A | BI3: N/A | BJ3: N/A | BK3: N/A | BL3: N/A | BM3: N/A | BN3: N/A | BO3: N/A | BP3: No | BQ3: N/A | BR3: N/A
A4: SPRDAPRPGRU14 | B4: Default site | C4: N/A | D4: root | E4: SERVIDORES LINUX | F4: None | G4: unknown | H4: GRUPO INVEPAR | I4: 177130117155 | J4: 24.1.1.16 | K4: N/A | L4: Oct 17, 2024 02:11:37 PM | M4: server | N4: VMware, Inc. VMware20,1 | O4: Linux | P4: Linux,Red Hat Enterprise release 9.4 (Plow) 5.14.0-427.40.1.el9_4.x86_64 | Q4: 64 bit | R4: 7 GB | S4: 2 | T4: Intel(R) Xeon(R) Gold 6348 CPU @ 2.60GHz | U4: 4 | V4: Offline | W4: Connected | X4: Up to date | Y4: Aborted( Oct 17, 2024 02:17:30 PM ) | Z4: 192.168.0.61 | AA4: No | AB4: Off | AC4: ffd19249-fae8-4a30-34e3-b30cac120a7f | AD4: 2.0631404e+18 | AE4: N/A | AF4: N/A | AG4: Not disabled | AH4: N/A | AI4: Oct 22, 2024 07:52:47 PM | AJ4: RPM | AK4: No | AL4: No | AM4: disabled | AN4: N/A | AO4: N/A | AP4: N/A | AQ4: N/A | AR4: N/A | AS4: N/A | AT4: N/A | AU4: N/A | AV4: N/A | AW4: N/A | AX4: N/A | AY4: N/A | AZ4: N/A | BA4: N/A | BB4: N/A | BC4: N/A | BD4: N/A | BE4: N/A | BF4: N/A | BG4: N/A | BH4: N/A | BI4: N/A | BJ4: N/A | BK4: N/A | BL4: N/A | BM4: N/A | BN4: N/A | BO4: N/A | BP4: No | BQ4: N/A | BR4: N/A
A5: SPRDAPIHSGRU03 | B5: Default site | C5: N/A | D5: root | E5: SERVIDORES LINUX | F5: None | G5: gru.local | H5: GRUPO INVEPAR | I5: 200.174.72.155 | J5: 24.1.1.16 | K5: N/A | L5: Oct 16, 2024 07:27:21 PM | M5: server | N5: VMware, Inc. VMware20,1 | O5: Linux | P5: Linux,Red Hat Enterprise release 9.5 (Plow) 5.14.0-503.22.1.el9_5.x86_64 | Q5: 64 bit | R5: 8 GB | S5: 2 | T5: Intel(R) Xeon(R) Gold 6348 CPU @ 2.60GHz | U5: 2 | V5: Online | W5: Connected | X5: Up to date | Y5: Completed( Oct 16, 2024 07:41:09 PM ) | Z5: 192.168.0.55 | AA5: No | AB5: Off | AC5: ff77b23f-3f2d-f1f4-a6f2-999d8ae3d98d | AD5: 2.0625745e+18 | AE5: N/A | AF5: N/A | AG5: Not disabled | AH5: N/A | AI5: Jan 29, 2025 02:08:11 PM | AJ5: RPM | AK5: No | AL5: No | AM5: disabled | AN5: N/A | AO5: N/A | AP5: N/A | AQ5: N/A | AR5: N/A | AS5: N/A | AT5: N/A | AU5: N/A | AV5: N/A | AW5: N/A | AX5: N/A | AY5: N/A | AZ5: N/A | BA5: N/A | BB5: N/A | BC5: N/A | BD5: N/A | BE5: N/A | BF5: N/A | BG5: N/A | BH5: N/A | BI5: N/A | BJ5: N/A | BK5: N/A | BL5: N/A | BM5: N/A | BN5: N/A | BO5: N/A | BP5: No | BQ5: N/A | BR5: N/A
A6: SHOMAPIHSGRU02 | B6: Default site | C6: N/A | D6: root | E6: SERVIDORES LINUX | F6: None | G6: gru.local | H6: GRUPO INVEPAR | I6: 177130117155 | J6: 24.1.1.16 | K6: N/A | L6: Oct 16, 2024 07:07:01 PM | M6: server | N6: VMware, Inc. VMware7,1 | O6: Linux | P6: Linux,Red Hat Enterprise release 9.5 (Plow) 5.14.0-503.21.1.el9_5.x86_64 | Q6: 64 bit | R6: 4 GB | S6: 1 | T6: Intel(R) Xeon(R) CPU E5-4640 0 @ 2.40GHz | U6: 1 | V6: Online | W6: Connected | X6: Up to date | Y6: Completed( Oct 16, 2024 07:52:40 PM ) | Z6: 172.31.52.53 | AA6: No | AB6: Off | AC6: ff581c26-cdb7-6b02-d886-e4dc39c324b7 | AD6: 2.0625643e+18 | AE6: N/A | AF6: N/A | AG6: Not disabled | AH6: N/A | AI6: Jan 21, 2025 03:20:56 AM | AJ6: RPM | AK6: No | AL6: No | AM6: disabled | AN6: N/A | AO6: N/A | AP6: N/A | AQ6: N/A | AR6: N/A | AS6: N/A | AT6: N/A | AU6: N/A | AV6: N/A | AW6: N/A | AX6: N/A | AY6: N/A | AZ6: N/A | BA6: N/A | BB6: N/A | BC6: N/A | BD6: N/A | BE6: N/A | BF6: N/A | BG6: N/A | BH6: N/A | BI6: N/A | BJ6: N/A | BK6: N/A | BL6: N/A | BM6: N/A | BN6: N/A | BO6: N/A | BP6: No | BQ6: N/A | BR6: N/A
A7: SPRDAPGLPIGRU02 | B7: Default site | C7: N/A | D7: root | E7: SERVIDORES LINUX | F7: None | G7: unknown | H7: GRUPO INVEPAR | I7: 177130117155 | J7: 23.4.2.14 | K7: N/A | L7: Oct 09, 2024 06:30:48 PM | M7: server | N7: VMware, Inc. VMware Virtual Platform | O7: Linux | P7: Linux,Ubuntu 22.04.4 LTS 5.15.0-107-generic | Q7: 64 bit | R7: 16 GB | S7: 8 | T7: Intel(R) Xeon(R) CPU E5-4620 v2 @ 2.60GHz | U7: 8 | V7: Online | W7: Connected | X7: Up to date | Y7: Completed( Oct 09, 2024 07:38:38 PM ) | Z7: 172.31.50.82 | AA7: No | AB7: Off | AC7: e879e58d-403d-81e3-5546-d2196d2b34ff | AD7: 2.0574726e+18 | AE7: N/A | AF7: N/A | AG7: Not disabled | AH7: N/A | AI7: May 17, 2024 11:29:37 PM | AJ7: DEB | AK7: No | AL7: No | AM7: disabled | AN7: N/A | AO7: N/A | AP7: N/A | AQ7: N/A | AR7: N/A | AS7: N/A | AT7: N/A | AU7: N/A | AV7: N/A | AW7: N/A | AX7: N/A | AY7: N/A | AZ7: N/A | BA7: N/A | BB7: N/A | BC7: N/A | BD7: N/A | BE7: N/A | BF7: N/A | BG7: N/A | BH7: N/A | BI7: N/A | BJ7: N/A | BK7: N/A | BL7: N/A | BM7: N/A | BN7: N/A | BO7: N/A | BP7: No | BQ7: N/A | BR7: N/A
A8: sprdbdzabgru02 | B8: Default site | C8: N/A | D8: root | E8: SERVIDORES LINUX | F8: ACN : INFRA CRITICA, Impacto : D-Menor | G8: unknown | H8: GRUPO INVEPAR | I8: 177130117155 | J8: 23.1.1.7 | K8: N/A | L8: Oct 09, 2024 06:20:20 PM | M8: server | N8: VMware, Inc. VMware Virtual Platform | O8: Linux | P8: Linux,Red Hat Enterprise release 8.10 (Ootpa) 4.18.0-305.12.1.el8_4.x86_64 | Q8: 64 bit | R8: 31 GB | S8: 4 | T8: Intel(R) Xeon(R) CPU E5-4640 0 @ 2.40GHz | U8: 8 | V8: Online | W8: Connected | X8: Up to date | Y8: Completed( Oct 09, 2024 08:03:31 PM ) | Z8: 172.16.253.93 | AA8: No | AB8: Off | AC8: 98f98b22-d935-0b95-73e4-e3c58410de1d | AD8: 2.0574673e+18 | AE8: N/A | AF8: N/A | AG8: Not disabled | AH8: N/A | AI8: Feb 03, 2024 10:06:54 PM | AJ8: RPM | AK8: No | AL8: No | AM8: disabled | AN8: N/A | AO8: N/A | AP8: N/A | AQ8: N/A | AR8: N/A | AS8: N/A | AT8: N/A | AU8: N/A | AV8: N/A | AW8: N/A | AX8: N/A | AY8: N/A | AZ8: N/A | BA8: N/A | BB8: N/A | BC8: N/A | BD8: N/A | BE8: N/A | BF8: N/A | BG8: N/A | BH8: N/A | BI8: N/A | BJ8: N/A | BK8: N/A | BL8: N/A | BM8: N/A | BN8: N/A | BO8: N/A | BP8: No | BQ8: N/A | BR8: N/A
A9: SPRDBDOTRSGRU01 | B9: Default site | C9: N/A | D9: root | E9: SERVIDORES BANCO DE DADOS | F9: None | G9: unknown | H9: GRUPO INVEPAR | I9: 177130117155 | J9: 23.2.2.4 | K9: N/A | L9: Sep 27, 2024 03:12:06 PM | M9: server | N9: VMware, Inc. VMware Virtual Platform | O9: Linux | P9: Linux,Ubuntu 20.04.6 LTS 5.4.0-196-generic | Q9: 64 bit | R9: 27 GB | S9: 2 | T9: Intel(R) Xeon(R) CPU E5-4640 0 @ 2.40GHz | U9: 8 | V9: Online | W9: Connected | X9: Up to date | Y9: Aborted( Sep 27, 2024 03:53:53 PM ) | Z9: 172.31.52.16 | AA9: No | AB9: Off | AC9: f97fa568-85ae-2e0e-aa2a-6a40bf775767 | AD9: 2.0486753e+18 | AE9: N/A | AF9: N/A | AG9: Not disabled | AH9: N/A | AI9: Sep 30, 2024 01:45:07 PM | AJ9: DEB | AK9: No | AL9: No | AM9: disabled | AN9: N/A | AO9: N/A | AP9: N/A | AQ9: N/A | AR9: N/A | AS9: N/A | AT9: N/A | AU9: N/A | AV9: N/A | AW9: N/A | AX9: N/A | AY9: N/A | AZ9: N/A | BA9: N/A | BB9: N/A | BC9: N/A | BD9: N/A | BE9: N/A | BF9: N/A | BG9: N/A | BH9: N/A | BI9: N/A | BJ9: N/A | BK9: N/A | BL9: N/A | BM9: N/A | BN9: N/A | BO9: N/A | BP9: No | BQ9: N/A | BR9: N/A
A10: SPRDBDOTRSGRU01 | B10: Default site | C10: N/A | D10: root | E10: SERVIDORES BANCO DE DADOS | F10: None | G10: unknown | H10: GRUPO INVEPAR | I10: 177130117155 | J10: 23.2.2.4 | K10: N/A | L10: Sep 27, 2024 03:11:24 PM | M10: server | N10: VMware, Inc. VMware Virtual Platform | O10: Linux | P10: Linux,Ubuntu 20.04.6 LTS 5.4.0-200-generic | Q10: 64 bit | R10: 27 GB | S10: 2 | T10: Intel(R) Xeon(R) Gold 6348 CPU @ 2.60GHz | U10: 8 | V10: Online | W10: Connected | X10: Up to date | Y10: Completed( Sep 27, 2024 04:22:44 PM ) | Z10: 172.31.49.16 | AA10: No | AB10: Off | AC10: f9776b74-5667-65d6-0743-60cc7e8e3ebe | AD10: 2.0486749e+18 | AE10: N/A | AF10: N/A | AG10: Not disabled | AH10: N/A | AI10: Dec 01, 2024 02:47:59 AM | AJ10: DEB | AK10: No | AL10: No | AM10: disabled | AN10: N/A | AO10: N/A | AP10: N/A | AQ10: N/A | AR10: N/A | AS10: N/A | AT10: N/A | AU10: N/A | AV10: N/A | AW10: N/A | AX10: N/A | AY10: N/A | AZ10: N/A | BA10: N/A | BB10: N/A | BC10: N/A | BD10: N/A | BE10: N/A | BF10: N/A | BG10: N/A | BH10: N/A | BI10: N/A | BJ10: N/A | BK10: N/A | BL10: N/A | BM10: N/A | BN10: N/A | BO10: N/A | BP10: No | BQ10: N/A | BR10: N/A
A11: sprdotrsgru01 | B11: Default site | C11: N/A | D11: root | E11: SERVIDORES LINUX | F11: ACN : INFRA CRITICA, Impacto : C-Maior | G11: unknown | H11: GRUPO INVEPAR | I11: 200.174.72.155 | J11: 23.2.2.4 | K11: N/A | L11: Sep 27, 2024 02:13:28 PM | M11: server | N11: VMware, Inc. VMware Virtual Platform | O11: Linux | P11: Linux,Ubuntu 20.04.6 LTS 5.4.0-196-generic | Q11: 64 bit | R11: 23 GB | S11: 2 | T11: Intel(R) Xeon(R) CPU E5-4640 0 @ 2.40GHz | U11: 8 | V11: Online | W11: Connected | X11: Up to date | Y11: Aborted( Sep 27, 2024 02:17:52 PM ) | Z11: 172.31.52.49 | AA11: No | AB11: Off | AC11: f955d934-4f7d-ed62-aa46-654db3e2819a | AD11: 2.0486458e+18 | AE11: N/A | AF11: N/A | AG11: Not disabled | AH11: N/A | AI11: Sep 27, 2024 06:50:34 PM | AJ11: DEB | AK11: No | AL11: No | AM11: disabled | AN11: N/A | AO11: N/A | AP11: N/A | AQ11: N/A | AR11: N/A | AS11: N/A | AT11: N/A | AU11: N/A | AV11: N/A | AW11: N/A | AX11: N/A | AY11: N/A | AZ11: N/A | BA11: N/A | BB11: N/A | BC11: N/A | BD11: N/A | BE11: N/A | BF11: N/A | BG11: N/A | BH11: N/A | BI11: N/A | BJ11: N/A | BK11: N/A | BL11: N/A | BM11: N/A | BN11: N/A | BO11: N/A | BP11: No | BQ11: N/A | BR11: N/A
A12: sprdotrsgru01 | B12: Default site | C12: N/A | D12: root | E12: SERVIDORES LINUX | F12: ACN : INFRA CRITICA, Impacto : C-Maior | G12: gru.local | H12: GRUPO INVEPAR | I12: 177130117155 | J12: 23.2.2.4 | K12: N/A | L12: Sep 27, 2024 02:13:17 PM | M12: server | N12: VMware, Inc. VMware Virtual Platform | O12: Linux | P12: Linux,Ubuntu 20.04.6 LTS 5.4.0-200-generic | Q12: 64 bit | R12: 23 GB | S12: 2 | T12: Intel(R) Xeon(R) Gold 6348 CPU @ 2.60GHz | U12: 8 | V12: Online | W12: Connected | X12: Up to date | Y12: Aborted( Sep 27, 2024 02:18:03 PM ) | Z12: 172.31.49.49 | AA12: No | AB12: Off | AC12: f95008de-e3e8-0c1b-20fc-a3057f82b15a | AD12: 2.0486457e+18 | AE12: N/A | AF12: N/A | AG12: Not disabled | AH12: N/A | AI12: Dec 01, 2024 03:04:20 AM | AJ12: DEB | AK12: No | AL12: No | AM12: disabled | AN12: N/A | AO12: N/A | AP12: N/A | AQ12: N/A | AR12: N/A | AS12: N/A | AT12: N/A | AU12: N/A | AV12: N/A | AW12: N/A | AX12: N/A | AY12: N/A | AZ12: N/A | BA12: N/A | BB12: N/A | BC12: N/A | BD12: N/A | BE12: N/A | BF12: N/A | BG12: N/A | BH12: N/A | BI12: N/A | BJ12: N/A | BK12: N/A | BL12: N/A | BM12: N/A | BN12: N/A | BO12: N/A | BP12: No | BQ12: N/A | BR12: N/A
A13: shomapprmgru01 | B13: Default site | C13: N/A | D13: root | E13: SERVIDORES LINUX | F13: None | G13: unknown | H13: GRUPO INVEPAR | I13: 200.174.72.155 | J13: 23.4.2.14 | K13: N/A | L13: Sep 05, 2024 01:39:21 PM | M13: server | N13: VMware, Inc. VMware Virtual Platform | O13: Linux | P13: Linux,Ubuntu 22.04.2 LTS 5.15.0-79-generic | Q13: 64 bit | R13: 4 GB | S13: 2 | T13: Intel(R) Xeon(R) CPU E5-2620 v2 @ 2.10GHz | U13: 2 | V13: Online | W13: Connected | X13: Out of date | Y13: Completed( Sep 05, 2024 03:05:18 PM ) | Z13: 10.36.52.134 | AA13: No | AB13: Off | AC13: 9172529f-6524-9da4-aebd-f9a5b568177f | AD13: 2.0326836e+18 | AE13: N/A | AF13: N/A | AG13: Not disabled | AH13: N/A | AI13: Jan 03, 2024 07:35:13 PM | AJ13: DEB | AK13: No | AL13: No | AM13: disabled | AN13: N/A | AO13: N/A | AP13: N/A | AQ13: N/A | AR13: N/A | AS13: N/A | AT13: N/A | AU13: N/A | AV13: N/A | AW13: N/A | AX13: N/A | AY13: N/A | AZ13: N/A | BA13: N/A | BB13: N/A | BC13: N/A | BD13: N/A | BE13: N/A | BF13: N/A | BG13: N/A | BH13: N/A | BI13: N/A | BJ13: N/A | BK13: N/A | BL13: N/A | BM13: N/A | BN13: N/A | BO13: N/A | BP13: No | BQ13: N/A | BR13: N/A
A14: shomapgrfgru01 | B14: Default site | C14: N/A | D14: root | E14: SERVIDORES LINUX | F14: None | G14: unknown | H14: GRUPO INVEPAR | I14: 200.174.72.155 | J14: 23.4.2.14 | K14: N/A | L14: Aug 30, 2024 02:14:03 PM | M14: server | N14: VMware, Inc. VMware Virtual Platform | O14: Linux | P14: Linux,Ubuntu 22.04.4 LTS 5.15.0-76-generic | Q14: 64 bit | R14: 4 GB | S14: 10 | T14: Intel(R) Xeon(R) CPU E5-2620 v2 @ 2.10GHz | U14: 10 | V14: Online | W14: Connected | X14: Out of date | Y14: Completed( Aug 30, 2024 03:53:49 PM ) | Z14: 10.36.52.135 | AA14: No | AB14: Off | AC14: f05e56fd-7495-1ab2-4159-e10eff45ab1f | AD14: 2.0283524e+18 | AE14: N/A | AF14: N/A | AG14: Not disabled | AH14: N/A | AI14: Jan 03, 2024 07:41:52 PM | AJ14: DEB | AK14: No | AL14: No | AM14: disabled | AN14: N/A | AO14: N/A | AP14: N/A | AQ14: N/A | AR14: N/A | AS14: N/A | AT14: N/A | AU14: N/A | AV14: N/A | AW14: N/A | AX14: N/A | AY14: N/A | AZ14: N/A | BA14: N/A | BB14: N/A | BC14: N/A | BD14: N/A | BE14: N/A | BF14: N/A | BG14: N/A | BH14: N/A | BI14: N/A | BJ14: N/A | BK14: N/A | BL14: N/A | BM14: N/A | BN14: N/A | BO14: N/A | BP14: No | BQ14: N/A | BR14: N/A
A15: shomapgrfgru01 | B15: Default site | C15: N/A | D15: root | E15: SERVIDORES LINUX | F15: None | G15: unknown | H15: GRUPO INVEPAR | I15: 177130117155 | J15: 23.2.2.4 | K15: N/A | L15: Aug 30, 2024 02:12:31 PM | M15: server | N15: VMware, Inc. VMware Virtual Platform | O15: Linux | P15: Linux,Ubuntu 22.04.4 LTS 5.15.0-79-generic | Q15: 64 bit | R15: 4 GB | S15: 10 | T15: Intel(R) Xeon(R) CPU E5-2620 v2 @ 2.10GHz | U15: 10 | V15: Offline | W15: Connected | X15: Up to date | Y15: Aborted( Aug 30, 2024 02:17:51 PM ) | Z15: 10.36.52.137 | AA15: No | AB15: Off | AC15: 918d0ec7-4549-4645-0553-72f085fa77d6 | AD15: 2.0283516e+18 | AE15: N/A | AF15: N/A | AG15: Not disabled | AH15: N/A | AI15: Jan 03, 2024 07:32:13 PM | AJ15: DEB | AK15: No | AL15: No | AM15: disabled | AN15: N/A | AO15: N/A | AP15: N/A | AQ15: N/A | AR15: N/A | AS15: N/A | AT15: N/A | AU15: N/A | AV15: N/A | AW15: N/A | AX15: N/A | AY15: N/A | AZ15: N/A | BA15: N/A | BB15: N/A | BC15: N/A | BD15: N/A | BE15: N/A | BF15: N/A | BG15: N/A | BH15: N/A | BI15: N/A | BJ15: N/A | BK15: N/A | BL15: N/A | BM15: N/A | BN15: N/A | BO15: N/A | BP15: No | BQ15: N/A | BR15: N/A
